Workbook
Name ckpj8hfcjasd9vhm: 'DIRTY ESG DATA'!$A$1:$I$6045

Sheet FINAL - WITH MOMENTUM
A1: TICKER | B1: Year | C1: ESGCombinedScore | D1: EnvironmentPillarScore | E1: GovernancePillarScore | F1: SocialPillarScore | G1: ESG Momentum | H1: ESG Mom-Env | I1: ESG Mom - Gov | J1: ESG Mom - Social
A2: AAV CN EQUITY | B2: 2021 | C2: 0.32801626 | D2: 0.27423839 | E2: 0.51237323 | F2: 0.26886706 | G2: =IF(A2<>A1,C2-0,C2-C1) -> 0.32801626 | H2: =IF(A2<>A1,D2-0,D2-D1) -> 0.27423839 | I2: =IF(A2<>A1,E2-0,E2-E1) -> 0.51237323 | J2: =IF(A2<>A1,F2-0,F2-F1) -> 0.26886706
A3: AAV CN EQUITY | B3: 2022 | C3: 0.41035629 | D3: 0.28529917 | E3: 0.56397363 | F3: 0.42706643 | G3: =IF(A3<>A2,C3-0,C3-C2) -> 0.082340022 | H3: =IF(A3<>A2,D3-0,D3-D2) -> 0.011060785 | I3: =IF(A3<>A2,E3-0,E3-E2) -> 0.051600405 | J3: =IF(A3<>A2,F3-0,F3-F2) -> 0.15819937
A4: AAV CN EQUITY | B4: 2023 | C4: 0.38751429 | D4: 0.27132183 | E4: 0.52778796 | F4: 0.40441631 | G4: =IF(A4<>A3,C4-0,C4-C3) -> -0.022841996 | H4: =IF(A4<>A3,D4-0,D4-D3) -> -0.013977347 | I4: =IF(A4<>A3,E4-0,E4-E3) -> -0.036185668 | J4: =IF(A4<>A3,F4-0,F4-F3) -> -0.022650115
A5: AAV CN EQUITY | B5: 2024 | C5: 0.375051 | D5: 0.26750334 | E5: 0.45098611 | F5: 0.42092097 | G5: =IF(A5<>A4,C5-0,C5-C4) -> -0.01246329 | H5: =IF(A5<>A4,D5-0,D5-D4) -> -0.0038184837 | I5: =IF(A5<>A4,E5-0,E5-E4) -> -0.076801851 | J5: =IF(A5<>A4,F5-0,F5-F4) -> 0.01650466
A6: AC CN EQUITY | B6: 2014 | C6: 0.47337539 | D6: 0.34599989 | E6: 0.61867288 | F6: 0.46985388 | G6: =IF(A6<>A5,C6-0,C6-C5) -> 0.47337539 | H6: =IF(A6<>A5,D6-0,D6-D5) -> 0.34599989 | I6: =IF(A6<>A5,E6-0,E6-E5) -> 0.61867288 | J6: =IF(A6<>A5,F6-0,F6-F5) -> 0.46985388
A7: AC CN EQUITY | B7: 2015 | C7: 0.44113341 | D7: 0.36070612 | E7: 0.69112079 | F7: 0.61321137 | G7: =IF(A7<>A6,C7-0,C7-C6) -> -0.032241978 | H7: =IF(A7<>A6,D7-0,D7-D6) -> 0.014706225 | I7: =IF(A7<>A6,E7-0,E7-E6) -> 0.072447912 | J7: =IF(A7<>A6,F7-0,F7-F6) -> 0.14335749
A8: AC CN EQUITY | B8: 2016 | C8: 0.5512753 | D8: 0.33358586 | E8: 0.7360353 | F8: 0.58842892 | G8: =IF(A8<>A7,C8-0,C8-C7) -> 0.11014189 | H8: =IF(A8<>A7,D8-0,D8-D7) -> -0.027120259 | I8: =IF(A8<>A7,E8-0,E8-E7) -> 0.044914504 | J8: =IF(A8<>A7,F8-0,F8-F7) -> -0.024782449
A9: AC CN EQUITY | B9: 2017 | C9: 0.61598381 | D9: 0.44964349 | E9: 0.79584639 | F9: 0.61809747 | G9: =IF(A9<>A8,C9-0,C9-C8) -> 0.064708513 | H9: =IF(A9<>A8,D9-0,D9-D8) -> 0.11605764 | I9: =IF(A9<>A8,E9-0,E9-E8) -> 0.059811099 | J9: =IF(A9<>A8,F9-0,F9-F8) -> 0.029668545
A10: AC CN EQUITY | B10: 2018 | C10: 0.40669482 | D10: 0.50891298 | E10: 0.8389932 | F10: 0.61909178 | G10: =IF(A10<>A9,C10-0,C10-C9) -> -0.209289 | H10: =IF(A10<>A9,D10-0,D10-D9) -> 0.059269488 | I10: =IF(A10<>A9,E10-0,E10-E9) -> 0.043146802 | J10: =IF(A10<>A9,F10-0,F10-F9) -> 0.00099431464
A11: AC CN EQUITY | B11: 2019 | C11: 0.49096424 | D11: 0.53867464 | E11: 0.86833679 | F11: 0.66234647 | G11: =IF(A11<>A10,C11-0,C11-C10) -> 0.084269425 | H11: =IF(A11<>A10,D11-0,D11-D10) -> 0.029761655 | I11: =IF(A11<>A10,E11-0,E11-E10) -> 0.029343595 | J11: =IF(A11<>A10,F11-0,F11-F10) -> 0.043254689
A12: AC CN EQUITY | B12: 2020 | C12: 0.61702698 | D12: 0.55796162 | E12: 0.86866569 | F12: 0.60685149 | G12: =IF(A12<>A11,C12-0,C12-C11) -> 0.12606274 | H12: =IF(A12<>A11,D12-0,D12-D11) -> 0.019286982 | I12: =IF(A12<>A11,E12-0,E12-E11) -> 0.00032889644 | J12: =IF(A12<>A11,F12-0,F12-F11) -> -0.055494985
A13: AC CN EQUITY | B13: 2021 | C13: 0.43034235 | D13: 0.63042647 | E13: 0.77109226 | F13: 0.66029355 | G13: =IF(A13<>A12,C13-0,C13-C12) -> -0.18668462 | H13: =IF(A13<>A12,D13-0,D13-D12) -> 0.072464855 | I13: =IF(A13<>A12,E13-0,E13-E12) -> -0.097573427 | J13: =IF(A13<>A12,F13-0,F13-F12) -> 0.053442065
... A290: BRE CN EQUITY | B290: 2022 | C290: 0.21300165 | D290: 0.14347436 | E290: 0.10643395 | F290: 0.37098112 | G290: =IF(A290<>A289,C290-0,C290-C289) -> -0.054933712 | H290: =IF(A290<>A289,D290-0,D290-D289) -> -0.020032824 | I290: =IF(A290<>A289,E290-0,E290-E289) -> 0.0079214409 | J290: =IF(A290<>A289,F290-0,F290-F289) -> -0.14274524
A291: BRE CN EQUITY | B291: 2024 | C291: 0.014022102 | D291: 0.010504025 | E291: 0.032847222 | F291: #N/A | G291: =IF(A291<>A290,C291-0,C291-C290) -> -0.19897955 | H291: =IF(A291<>A290,D291-0,D291-D290) -> -0.13297034 | I291: =IF(A291<>A290,E291-0,E291-E290) -> -0.073586727 | J291: =IF(A291<>A290,F291-0,F291-F290) -> #N/A
A292: BTB-U CN EQUITY | B292: 2020 | C292: 0.083188111 | D292: 0 | E292: 0.22581768 | F292: 0.034644807 | G292: =IF(A292<>A291,C292-0,C292-C291) -> 0.083188111 | H292: =IF(A292<>A291,D292-0,D292-D291) -> 0 | I292: =IF(A292<>A291,E292-0,E292-E291) -> 0.22581768 | J292: =IF(A292<>A291,F292-0,F292-F291) -> 0.034644807
A293: BTB-U CN EQUITY | B293: 2021 | C293: 0.10689827 | D293: 0.043806882 | E293: 0.22251521 | F293: 0.062153535 | G293: =IF(A293<>A292,C293-0,C293-C292) -> 0.023710155 | H293: =IF(A293<>A292,D293-0,D293-D292) -> 0.043806882 | I293: =IF(A293<>A292,E293-0,E293-E292) -> -0.0033024627 | J293: =IF(A293<>A292,F293-0,F293-F292) -> 0.027508728
A294: BTB-U CN EQUITY | B294: 2022 | C294: 0.1559515 | D294: 0.092722741 | E294: 0.31396304 | F294: 0.06622346 | G294: =IF(A294<>A293,C294-0,C294-C293) -> 0.049053232 | H294: =IF(A294<>A293,D294-0,D294-D293) -> 0.04891586 | I294: =IF(A294<>A293,E294-0,E294-E293) -> 0.091447826 | J294: =IF(A294<>A293,F294-0,F294-F293) -> 0.0040699251
A295: BTB-U CN EQUITY | B295: 2023 | C295: 0.25029394 | D295: 0.16059154 | E295: 0.30128783 | F295: 0.30744545 | G295: =IF(A295<>A294,C295-0,C295-C294) -> 0.094342446 | H295: =IF(A295<>A294,D295-0,D295-D294) -> 0.067868803 | I295: =IF(A295<>A294,E295-0,E295-E294) -> -0.012675212 | J295: =IF(A295<>A294,F295-0,F295-F294) -> 0.24122199
A296: BTB-U CN EQUITY | B296: 2024 | C296: 0.29213154 | D296: 0.22489308 | E296: 0.37315278 | F296: 0.28938747 | G296: =IF(A296<>A295,C296-0,C296-C295) -> 0.041837595 | H296: =IF(A296<>A295,D296-0,D296-D295) -> 0.064301537 | I296: =IF(A296<>A295,E296-0,E296-E295) -> 0.071864951 | J296: =IF(A296<>A295,F296-0,F296-F295) -> -0.018057979
A297: BTE CN EQUITY | B297: 2014 | C297: 0.34320423 | D297: 0.28131842 | E297: 0.34698959 | F297: 0.39197833 | G297: =IF(A297<>A296,C297-0,C297-C296) -> 0.34320423 | H297: =IF(A297<>A296,D297-0,D297-D296) -> 0.28131842 | I297: =IF(A297<>A296,E297-0,E297-E296) -> 0.34698959 | J297: =IF(A297<>A296,F297-0,F297-F296) -> 0.39197833
A298: BTE CN EQUITY | B298: 2015 | C298: 0.40157941 | D298: 0.30207565 | E298: 0.62142439 | F298: 0.36013672 | G298: =IF(A298<>A297,C298-0,C298-C297) -> 0.058375184 | H298: =IF(A298<>A297,D298-0,D298-D297) -> 0.02075723 | I298: =IF(A298<>A297,E298-0,E298-E297) -> 0.27443481 | J298: =IF(A298<>A297,F298-0,F298-F297) -> -0.031841613
A299: BTE CN EQUITY | B299: 2016 | C299: 0.38045257 | D299: 0.27024347 | E299: 0.42176893 | F299: 0.44792377 | G299: =IF(A299<>A298,C299-0,C299-C298) -> -0.021126841 | H299: =IF(A299<>A298,D299-0,D299-D298) -> -0.031832176 | I299: =IF(A299<>A298,E299-0,E299-E298) -> -0.19965546 | J299: =IF(A299<>A298,F299-0,F299-F298) -> 0.087787052
A300: BTE CN EQUITY | B300: 2017 | C300: 0.34381415 | D300: 0.28471128 | E300: 0.28918495 | F300: 0.4230553 | G300: =IF(A300<>A299,C300-0,C300-C299) -> -0.036638422 | H300: =IF(A300<>A299,D300-0,D300-D299) -> 0.014467812 | I300: =IF(A300<>A299,E300-0,E300-E299) -> -0.13258398 | J300: =IF(A300<>A299,F300-0,F300-F299) -> -0.024868469
A301: BTE CN EQUITY | B301: 2018 | C301: 0.3929047 | D301: 0.27682418 | E301: 0.61812036 | F301: 0.36208365 | G301: =IF(A301<>A300,C301-0,C301-C300) -> 0.049090556 | H301: =IF(A301<>A300,D301-0,D301-D300) -> -0.0078871061 | I301: =IF(A301<>A300,E301-0,E301-E300) -> 0.3289354 | J301: =IF(A301<>A300,F301-0,F301-F300) -> -0.060971656
A302: BTE CN EQUITY | B302: 2019 | C302: 0.41963842 | D302: 0.31908787 | E302: 0.67417062 | F302: 0.35960587 | G302: =IF(A302<>A301,C302-0,C302-C301) -> 0.026733718 | H302: =IF(A302<>A301,D302-0,D302-D301) -> 0.042263691 | I302: =IF(A302<>A301,E302-0,E302-E301) -> 0.05605026 | J302: =IF(A302<>A301,F302-0,F302-F301) -> -0.0024777798
A303: BTE CN EQUITY | B303: 2020 | C303: 0.53842405 | D303: 0.41263081 | E303: 0.93891367 | F303: 0.41730656 | G303: =IF(A303<>A302,C303-0,C303-C302) -> 0.11878563 | H303: =IF(A303<>A302,D303-0,D303-D302) -> 0.093542939 | I303: =IF(A303<>A302,E303-0,E303-E302) -> 0.26474306 | J303: =IF(A303<>A302,F303-0,F303-F302) -> 0.05770069
... A2095: XTC CN EQUITY | B2095: 2024 | C2095: 0.24393174 | D2095: 0.085651007 | E2095: 0.24609722 | F2095: 0.37258632 | G2095: =IF(A2095<>A2094,C2095-0,C2095-C2094) -> -0.017835029 | H2095: =IF(A2095<>A2094,D2095-0,D2095-D2094) -> -0.0033593059 | I2095: =IF(A2095<>A2094,E2095-0,E2095-E2094) -> -0.028701517 | J2095: =IF(A2095<>A2094,F2095-0,F2095-F2094) -> -0.023346151
G2096: =IF(A2096<>A2095,C2096-0,C2096-C2095) -> 0 | H2096: =IF(A2096<>A2095,D2096-0,D2096-D2095) -> 0 | I2096: =IF(A2096<>A2095,E2096-0,E2096-E2095) -> 0 | J2096: =IF(A2096<>A2095,F2096-0,F2096-F2095) -> 0
G2097: =IF(A2097<>A2096,C2097-0,C2097-C2096) -> 0 | H2097: =IF(A2097<>A2096,D2097-0,D2097-D2096) -> 0 | I2097: =IF(A2097<>A2096,E2097-0,E2097-E2096) -> 0 | J2097: =IF(A2097<>A2096,F2097-0,F2097-F2096) -> 0
G2098: =IF(A2098<>A2097,C2098-0,C2098-C2097) -> 0 | H2098: =IF(A2098<>A2097,D2098-0,D2098-D2097) -> 0 | I2098: =IF(A2098<>A2097,E2098-0,E2098-E2097) -> 0 | J2098: =IF(A2098<>A2097,F2098-0,F2098-F2097) -> 0
G2099: =IF(A2099<>A2098,C2099-0,C2099-C2098) -> 0 | H2099: =IF(A2099<>A2098,D2099-0,D2099-D2098) -> 0 | I2099: =IF(A2099<>A2098,E2099-0,E2099-E2098) -> 0 | J2099: =IF(A2099<>A2098,F2099-0,F2099-F2098) -> 0
G2100: =IF(A2100<>A2099,C2100-0,C2100-C2099) -> 0 | H2100: =IF(A2100<>A2099,D2100-0,D2100-D2099) -> 0 | I2100: =IF(A2100<>A2099,E2100-0,E2100-E2099) -> 0 | J2100: =IF(A2100<>A2099,F2100-0,F2100-F2099) -> 0
G2101: =IF(A2101<>A2100,C2101-0,C2101-C2100) -> 0 | H2101: =IF(A2101<>A2100,D2101-0,D2101-D2100) -> 0 | I2101: =IF(A2101<>A2100,E2101-0,E2101-E2100) -> 0 | J2101: =IF(A2101<>A2100,F2101-0,F2101-F2100) -> 0
G2102: =IF(A2102<>A2101,C2102-0,C2102-C2101) -> 0 | H2102: =IF(A2102<>A2101,D2102-0,D2102-D2101) -> 0 | I2102: =IF(A2102<>A2101,E2102-0,E2102-E2101) -> 0 | J2102: =IF(A2102<>A2101,F2102-0,F2102-F2101) -> 0
G2103: =IF(A2103<>A2102,C2103-0,C2103-C2102) -> 0 | H2103: =IF(A2103<>A2102,D2103-0,D2103-D2102) -> 0 | I2103: =IF(A2103<>A2102,E2103-0,E2103-E2102) -> 0 | J2103: =IF(A2103<>A2102,F2103-0,F2103-F2102) -> 0
G2104: =IF(A2104<>A2103,C2104-0,C2104-C2103) -> 0 | H2104: =IF(A2104<>A2103,D2104-0,D2104-D2103) -> 0 | I2104: =IF(A2104<>A2103,E2104-0,E2104-E2103) -> 0 | J2104: =IF(A2104<>A2103,F2104-0,F2104-F2103) -> 0
G2105: =IF(A2105<>A2104,C2105-0,C2105-C2104) -> 0 | H2105: =IF(A2105<>A2104,D2105-0,D2105-D2104) -> 0 | I2105: =IF(A2105<>A2104,E2105-0,E2105-E2104) -> 0 | J2105: =IF(A2105<>A2104,F2105-0,F2105-F2104) -> 0
G2106: =IF(A2106<>A2105,C2106-0,C2106-C2105) -> 0 | H2106: =IF(A2106<>A2105,D2106-0,D2106-D2105) -> 0 | I2106: =IF(A2106<>A2105,E2106-0,E2106-E2105) -> 0 | J2106: =IF(A2106<>A2105,F2106-0,F2106-F2105) -> 0
G2107: =IF(A2107<>A2106,C2107-0,C2107-C2106) -> 0 | H2107: =IF(A2107<>A2106,D2107-0,D2107-D2106) -> 0 | I2107: =IF(A2107<>A2106,E2107-0,E2107-E2106) -> 0 | J2107: =IF(A2107<>A2106,F2107-0,F2107-F2106) -> 0
...

Sheet CLEAN v1
A1: TICKER | B1: Year | C1: ESGCombinedScore | D1: EnvironmentPillarScore | E1: GovernancePillarScore | F1: SocialPillarScore | G1: ESG Momentum
A2: AC CN EQUITY | B2: 2014 | C2: {=INDEX('DIRTY ESG DATA'!$I$2:$I$8376, MATCH(1, ('DIRTY ESG DATA'!$A$2:$A$8376='CLEAN v1'!B2)* ('DIRTY ESG DATA'!$C$2:$C$8376='CLEAN v1'!A2)* ('DIRTY ESG DATA'!$G$2:$G$8376='CLEAN v1'!C$1), 0))} -> 0.47337539 | D2: {=INDEX('DIRTY ESG DATA'!$I$2:$I$8376, MATCH(1, ('DIRTY ESG DATA'!$A$2:$A$8376=B2)* ('DIRTY ESG DATA'!$C$2:$C$8376=A2)* ('DIRTY ESG DATA'!$G$2:$G$8376='CLEAN v1'!D$1), 0))} -> 0.34599989 | E2: {=INDEX('DIRTY ESG DATA'!$I$2:$I$8376, MATCH(1, ('DIRTY ESG DATA'!$A$2:$A$8376=B2)* ('DIRTY ESG DATA'!$C$2:$C$8376=A2)* ('DIRTY ESG DATA'!$G$2:$G$8376='CLEAN v1'!E$1), 0))} -> 0.61867288 | F2: {=INDEX('DIRTY ESG DATA'!$I$2:$I$8376, MATCH(1, ('DIRTY ESG DATA'!$A$2:$A$8376=B2)* ('DIRTY ESG DATA'!$C$2:$C$8376=A2)* ('DIRTY ESG DATA'!$G$2:$G$8376='CLEAN v1'!F$1), 0))} -> 0.46985388
A3: ACO/X CN EQUITY | B3: 2014 | C3: {=INDEX('DIRTY ESG DATA'!$I$2:$I$8376, MATCH(1, ('DIRTY ESG DATA'!$A$2:$A$8376='CLEAN v1'!B3)* ('DIRTY ESG DATA'!$C$2:$C$8376='CLEAN v1'!A3)* ('DIRTY ESG DATA'!$G$2:$G$8376='CLEAN v1'!C$1), 0))} -> 0.43132298 | D3: {=INDEX('DIRTY ESG DATA'!$I$2:$I$8376, MATCH(1, ('DIRTY ESG DATA'!$A$2:$A$8376=B3)* ('DIRTY ESG DATA'!$C$2:$C$8376=A3)* ('DIRTY ESG DATA'!$G$2:$G$8376='CLEAN v1'!D$1), 0))} -> 0.36314036 | E3: {=INDEX('DIRTY ESG DATA'!$I$2:$I$8376, MATCH(1, ('DIRTY ESG DATA'!$A$2:$A$8376=B3)* ('DIRTY ESG DATA'!$C$2:$C$8376=A3)* ('DIRTY ESG DATA'!$G$2:$G$8376='CLEAN v1'!E$1), 0))} -> 0.56489455 | F3: {=INDEX('DIRTY ESG DATA'!$I$2:$I$8376, MATCH(1, ('DIRTY ESG DATA'!$A$2:$A$8376=B3)* ('DIRTY ESG DATA'!$C$2:$C$8376=A3)* ('DIRTY ESG DATA'!$G$2:$G$8376='CLEAN v1'!F$1), 0))} -> 0.4237582
A4: ACQ CN EQUITY | B4: 2014 | C4: {=INDEX('DIRTY ESG DATA'!$I$2:$I$8376, MATCH(1, ('DIRTY ESG DATA'!$A$2:$A$8376='CLEAN v1'!B4)* ('DIRTY ESG DATA'!$C$2:$C$8376='CLEAN v1'!A4)* ('DIRTY ESG DATA'!$G$2:$G$8376='CLEAN v1'!C$1), 0))} -> 0.17189387 | D4: {=INDEX('DIRTY ESG DATA'!$I$2:$I$8376, MATCH(1, ('DIRTY ESG DATA'!$A$2:$A$8376=B4)* ('DIRTY ESG DATA'!$C$2:$C$8376=A4)* ('DIRTY ESG DATA'!$G$2:$G$8376='CLEAN v1'!D$1), 0))} -> 0 | E4: {=INDEX('DIRTY ESG DATA'!$I$2:$I$8376, MATCH(1, ('DIRTY ESG DATA'!$A$2:$A$8376=B4)* ('DIRTY ESG DATA'!$C$2:$C$8376=A4)* ('DIRTY ESG DATA'!$G$2:$G$8376='CLEAN v1'!E$1), 0))} -> 0.29294653 | F4: {=INDEX('DIRTY ESG DATA'!$I$2:$I$8376, MATCH(1, ('DIRTY ESG DATA'!$A$2:$A$8376=B4)* ('DIRTY ESG DATA'!$C$2:$C$8376=A4)* ('DIRTY ESG DATA'!$G$2:$G$8376='CLEAN v1'!F$1), 0))} -> 0.14029872
A5: AGF/B CN EQUITY | B5: 2014 | C5: {=INDEX('DIRTY ESG DATA'!$I$2:$I$8376, MATCH(1, ('DIRTY ESG DATA'!$A$2:$A$8376='CLEAN v1'!B5)* ('DIRTY ESG DATA'!$C$2:$C$8376='CLEAN v1'!A5)* ('DIRTY ESG DATA'!$G$2:$G$8376='CLEAN v1'!C$1), 0))} -> 0.35752508 | D5: {=INDEX('DIRTY ESG DATA'!$I$2:$I$8376, MATCH(1, ('DIRTY ESG DATA'!$A$2:$A$8376=B5)* ('DIRTY ESG DATA'!$C$2:$C$8376=A5)* ('DIRTY ESG DATA'!$G$2:$G$8376='CLEAN v1'!D$1), 0))} -> 0.31333907 | E5: {=INDEX('DIRTY ESG DATA'!$I$2:$I$8376, MATCH(1, ('DIRTY ESG DATA'!$A$2:$A$8376=B5)* ('DIRTY ESG DATA'!$C$2:$C$8376=A5)* ('DIRTY ESG DATA'!$G$2:$G$8376='CLEAN v1'!E$1), 0))} -> 0.42923777 | F5: {=INDEX('DIRTY ESG DATA'!$I$2:$I$8376, MATCH(1, ('DIRTY ESG DATA'!$A$2:$A$8376=B5)* ('DIRTY ESG DATA'!$C$2:$C$8376=A5)* ('DIRTY ESG DATA'!$G$2:$G$8376='CLEAN v1'!F$1), 0))} -> 0.35157824
A6: AIM CN EQUITY | B6: 2014 | C6: {=INDEX('DIRTY ESG DATA'!$I$2:$I$8376, MATCH(1, ('DIRTY ESG DATA'!$A$2:$A$8376='CLEAN v1'!B6)* ('DIRTY ESG DATA'!$C$2:$C$8376='CLEAN v1'!A6)* ('DIRTY ESG DATA'!$G$2:$G$8376='CLEAN v1'!C$1), 0))} -> 0.53523779 | D6: {=INDEX('DIRTY ESG DATA'!$I$2:$I$8376, MATCH(1, ('DIRTY ESG DATA'!$A$2:$A$8376=B6)* ('DIRTY ESG DATA'!$C$2:$C$8376=A6)* ('DIRTY ESG DATA'!$G$2:$G$8376='CLEAN v1'!D$1), 0))} -> 0.25952112 | E6: {=INDEX('DIRTY ESG DATA'!$I$2:$I$8376, MATCH(1, ('DIRTY ESG DATA'!$A$2:$A$8376=B6)* ('DIRTY ESG DATA'!$C$2:$C$8376=A6)* ('DIRTY ESG DATA'!$G$2:$G$8376='CLEAN v1'!E$1), 0))} -> 0.77217227 | F6: {=INDEX('DIRTY ESG DATA'!$I$2:$I$8376, MATCH(1, ('DIRTY ESG DATA'!$A$2:$A$8376=B6)* ('DIRTY ESG DATA'!$C$2:$C$8376=A6)* ('DIRTY ESG DATA'!$G$2:$G$8376='CLEAN v1'!F$1), 0))} -> 0.50085559
A7: AP-U CN EQUITY | B7: 2014 | C7: {=INDEX('DIRTY ESG DATA'!$I$2:$I$8376, MATCH(1, ('DIRTY ESG DATA'!$A$2:$A$8376='CLEAN v1'!B7)* ('DIRTY ESG DATA'!$C$2:$C$8376='CLEAN v1'!A7)* ('DIRTY ESG DATA'!$G$2:$G$8376='CLEAN v1'!C$1), 0))} -> 0.25373336 | D7: {=INDEX('DIRTY ESG DATA'!$I$2:$I$8376, MATCH(1, ('DIRTY ESG DATA'!$A$2:$A$8376=B7)* ('DIRTY ESG DATA'!$C$2:$C$8376=A7)* ('DIRTY ESG DATA'!$G$2:$G$8376='CLEAN v1'!D$1), 0))} -> 0.032409382 | E7: {=INDEX('DIRTY ESG DATA'!$I$2:$I$8376, MATCH(1, ('DIRTY ESG DATA'!$A$2:$A$8376=B7)* ('DIRTY ESG DATA'!$C$2:$C$8376=A7)* ('DIRTY ESG DATA'!$G$2:$G$8376='CLEAN v1'!E$1), 0))} -> 0.47026341 | F7: {=INDEX('DIRTY ESG DATA'!$I$2:$I$8376, MATCH(1, ('DIRTY ESG DATA'!$A$2:$A$8376=B7)* ('DIRTY ESG DATA'!$C$2:$C$8376=A7)* ('DIRTY ESG DATA'!$G$2:$G$8376='CLEAN v1'!F$1), 0))} -> 0.29812758
A8: AQN CN EQUITY | B8: 2014 | C8: {=INDEX('DIRTY ESG DATA'!$I$2:$I$8376, MATCH(1, ('DIRTY ESG DATA'!$A$2:$A$8376='CLEAN v1'!B8)* ('DIRTY ESG DATA'!$C$2:$C$8376='CLEAN v1'!A8)* ('DIRTY ESG DATA'!$G$2:$G$8376='CLEAN v1'!C$1), 0))} -> 0.24099934 | D8: {=INDEX('DIRTY ESG DATA'!$I$2:$I$8376, MATCH(1, ('DIRTY ESG DATA'!$A$2:$A$8376=B8)* ('DIRTY ESG DATA'!$C$2:$C$8376=A8)* ('DIRTY ESG DATA'!$G$2:$G$8376='CLEAN v1'!D$1), 0))} -> 0.13910611 | E8: {=INDEX('DIRTY ESG DATA'!$I$2:$I$8376, MATCH(1, ('DIRTY ESG DATA'!$A$2:$A$8376=B8)* ('DIRTY ESG DATA'!$C$2:$C$8376=A8)* ('DIRTY ESG DATA'!$G$2:$G$8376='CLEAN v1'!E$1), 0))} -> 0.56204713 | F8: {=INDEX('DIRTY ESG DATA'!$I$2:$I$8376, MATCH(1, ('DIRTY ESG DATA'!$A$2:$A$8376=B8)* ('DIRTY ESG DATA'!$C$2:$C$8376=A8)* ('DIRTY ESG DATA'!$G$2:$G$8376='CLEAN v1'!F$1), 0))} -> 0.14497146
A9: ARE CN EQUITY | B9: 2014 | C9: {=INDEX('DIRTY ESG DATA'!$I$2:$I$8376, MATCH(1, ('DIRTY ESG DATA'!$A$2:$A$8376='CLEAN v1'!B9)* ('DIRTY ESG DATA'!$C$2:$C$8376='CLEAN v1'!A9)* ('DIRTY ESG DATA'!$G$2:$G$8376='CLEAN v1'!C$1), 0))} -> 0.32827268 | D9: {=INDEX('DIRTY ESG DATA'!$I$2:$I$8376, MATCH(1, ('DIRTY ESG DATA'!$A$2:$A$8376=B9)* ('DIRTY ESG DATA'!$C$2:$C$8376=A9)* ('DIRTY ESG DATA'!$G$2:$G$8376='CLEAN v1'!D$1), 0))} -> 0.10304297 | E9: {=INDEX('DIRTY ESG DATA'!$I$2:$I$8376, MATCH(1, ('DIRTY ESG DATA'!$A$2:$A$8376=B9)* ('DIRTY ESG DATA'!$C$2:$C$8376=A9)* ('DIRTY ESG DATA'!$G$2:$G$8376='CLEAN v1'!E$1), 0))} -> 0.62202787 | F9: {=INDEX('DIRTY ESG DATA'!$I$2:$I$8376, MATCH(1, ('DIRTY ESG DATA'!$A$2:$A$8376=B9)* ('DIRTY ESG DATA'!$C$2:$C$8376=A9)* ('DIRTY ESG DATA'!$G$2:$G$8376='CLEAN v1'!F$1), 0))} -> 0.34392572
A10: ATH CN EQUITY | B10: 2014 | C10: {=INDEX('DIRTY ESG DATA'!$I$2:$I$8376, MATCH(1, ('DIRTY ESG DATA'!$A$2:$A$8376='CLEAN v1'!B10)* ('DIRTY ESG DATA'!$C$2:$C$8376='CLEAN v1'!A10)* ('DIRTY ESG DATA'!$G$2:$G$8376='CLEAN v1'!C$1), 0))} -> 0.11173973 | D10: {=INDEX('DIRTY ESG DATA'!$I$2:$I$8376, MATCH(1, ('DIRTY ESG DATA'!$A$2:$A$8376=B10)* ('DIRTY ESG DATA'!$C$2:$C$8376=A10)* ('DIRTY ESG DATA'!$G$2:$G$8376='CLEAN v1'!D$1), 0))} -> 0.086423445 | E10: {=INDEX('DIRTY ESG DATA'!$I$2:$I$8376, MATCH(1, ('DIRTY ESG DATA'!$A$2:$A$8376=B10)* ('DIRTY ESG DATA'!$C$2:$C$8376=A10)* ('DIRTY ESG DATA'!$G$2:$G$8376='CLEAN v1'!E$1), 0))} -> 0.071170255 | F10: {=INDEX('DIRTY ESG DATA'!$I$2:$I$8376, MATCH(1, ('DIRTY ESG DATA'!$A$2:$A$8376=B10)* ('DIRTY ESG DATA'!$C$2:$C$8376=A10)* ('DIRTY ESG DATA'!$G$2:$G$8376='CLEAN v1'!F$1), 0))} -> 0.15530983
A11: AX-U CN EQUITY | B11: 2014 | C11: {=INDEX('DIRTY ESG DATA'!$I$2:$I$8376, MATCH(1, ('DIRTY ESG DATA'!$A$2:$A$8376='CLEAN v1'!B11)* ('DIRTY ESG DATA'!$C$2:$C$8376='CLEAN v1'!A11)* ('DIRTY ESG DATA'!$G$2:$G$8376='CLEAN v1'!C$1), 0))} -> 0.24897136 | D11: {=INDEX('DIRTY ESG DATA'!$I$2:$I$8376, MATCH(1, ('DIRTY ESG DATA'!$A$2:$A$8376=B11)* ('DIRTY ESG DATA'!$C$2:$C$8376=A11)* ('DIRTY ESG DATA'!$G$2:$G$8376='CLEAN v1'!D$1), 0))} -> 0.032409382 | E11: {=INDEX('DIRTY ESG DATA'!$I$2:$I$8376, MATCH(1, ('DIRTY ESG DATA'!$A$2:$A$8376=B11)* ('DIRTY ESG DATA'!$C$2:$C$8376=A11)* ('DIRTY ESG DATA'!$G$2:$G$8376='CLEAN v1'!E$1), 0))} -> 0.56803185 | F11: {=INDEX('DIRTY ESG DATA'!$I$2:$I$8376, MATCH(1, ('DIRTY ESG DATA'!$A$2:$A$8376=B11)* ('DIRTY ESG DATA'!$C$2:$C$8376=A11)* ('DIRTY ESG DATA'!$G$2:$G$8376='CLEAN v1'!F$1), 0))} -> 0.17824431
A12: BB CN EQUITY | B12: 2014 | C12: {=INDEX('DIRTY ESG DATA'!$I$2:$I$8376, MATCH(1, ('DIRTY ESG DATA'!$A$2:$A$8376='CLEAN v1'!B12)* ('DIRTY ESG DATA'!$C$2:$C$8376='CLEAN v1'!A12)* ('DIRTY ESG DATA'!$G$2:$G$8376='CLEAN v1'!C$1), 0))} -> 0.55095175 | D12: {=INDEX('DIRTY ESG DATA'!$I$2:$I$8376, MATCH(1, ('DIRTY ESG DATA'!$A$2:$A$8376=B12)* ('DIRTY ESG DATA'!$C$2:$C$8376=A12)* ('DIRTY ESG DATA'!$G$2:$G$8376='CLEAN v1'!D$1), 0))} -> 0.73226958 | E12: {=INDEX('DIRTY ESG DATA'!$I$2:$I$8376, MATCH(1, ('DIRTY ESG DATA'!$A$2:$A$8376=B12)* ('DIRTY ESG DATA'!$C$2:$C$8376=A12)* ('DIRTY ESG DATA'!$G$2:$G$8376='CLEAN v1'!E$1), 0))} -> 0.4125536 | F12: {=INDEX('DIRTY ESG DATA'!$I$2:$I$8376, MATCH(1, ('DIRTY ESG DATA'!$A$2:$A$8376=B12)* ('DIRTY ESG DATA'!$C$2:$C$8376=A12)* ('DIRTY ESG DATA'!$G$2:$G$8376='CLEAN v1'!F$1), 0))} -> 0.65089197
A13: BCE CN EQUITY | B13: 2014 | C13: {=INDEX('DIRTY ESG DATA'!$I$2:$I$8376, MATCH(1, ('DIRTY ESG DATA'!$A$2:$A$8376='CLEAN v1'!B13)* ('DIRTY ESG DATA'!$C$2:$C$8376='CLEAN v1'!A13)* ('DIRTY ESG DATA'!$G$2:$G$8376='CLEAN v1'!C$1), 0))} -> 0.57561993 | D13: {=INDEX('DIRTY ESG DATA'!$I$2:$I$8376, MATCH(1, ('DIRTY ESG DATA'!$A$2:$A$8376=B13)* ('DIRTY ESG DATA'!$C$2:$C$8376=A13)* ('DIRTY ESG DATA'!$G$2:$G$8376='CLEAN v1'!D$1), 0))} -> 0.82549086 | E13: {=INDEX('DIRTY ESG DATA'!$I$2:$I$8376, MATCH(1, ('DIRTY ESG DATA'!$A$2:$A$8376=B13)* ('DIRTY ESG DATA'!$C$2:$C$8376=A13)* ('DIRTY ESG DATA'!$G$2:$G$8376='CLEAN v1'!E$1), 0))} -> 0.41014702 | F13: {=INDEX('DIRTY ESG DATA'!$I$2:$I$8376, MATCH(1, ('DIRTY ESG DATA'!$A$2:$A$8376=B13)* ('DIRTY ESG DATA'!$C$2:$C$8376=A13)* ('DIRTY ESG DATA'!$G$2:$G$8376='CLEAN v1'!F$1), 0))} -> 0.56260866
... A2095: XTC CN EQUITY | B2095: 2024 | C2095: {=INDEX('DIRTY ESG DATA'!$I$2:$I$8376, MATCH(1, ('DIRTY ESG DATA'!$A$2:$A$8376='CLEAN v1'!B2095)* ('DIRTY ESG DATA'!$C$2:$C$8376='CLEAN v1'!A2095)* ('DIRTY ESG DATA'!$G$2:$G$8376='CLEAN v1'!C$1), 0))} -> 0.24393174 | D2095: {=INDEX('DIRTY ESG DATA'!$I$2:$I$8376, MATCH(1, ('DIRTY ESG DATA'!$A$2:$A$8376=B2095)* ('DIRTY ESG DATA'!$C$2:$C$8376=A2095)* ('DIRTY ESG DATA'!$G$2:$G$8376='CLEAN v1'!D$1), 0))} -> 0.085651007 | E2095: {=INDEX('DIRTY ESG DATA'!$I$2:$I$8376, MATCH(1, ('DIRTY ESG DATA'!$A$2:$A$8376=B2095)* ('DIRTY ESG DATA'!$C$2:$C$8376=A2095)* ('DIRTY ESG DATA'!$G$2:$G$8376='CLEAN v1'!E$1), 0))} -> 0.24609722 | F2095: {=INDEX('DIRTY ESG DATA'!$I$2:$I$8376, MATCH(1, ('DIRTY ESG DATA'!$A$2:$A$8376=B2095)* ('DIRTY ESG DATA'!$C$2:$C$8376=A2095)* ('DIRTY ESG DATA'!$G$2:$G$8376='CLEAN v1'!F$1), 0))} -> 0.37258632

Sheet DIRTY ESG DATA
A1: Year | B1: CUSIP | C1: TICKER | D1: Company Name | E1: Field ID | F1: Field Pillar | G1: Field Name | H1: Value | I1: Value Score
A2: 2021 | B2: 00791P107 | C2: =VLOOKUP(B2,'REFERENCE SHEET'!B:C,2,FALSE) -> AAV CN EQUITY | D2: ADVANTAGE ENERGY LTD. | E2: 2 | F2: ESG Scores | G2: ESGCombinedScore | H2: C- | I2: 0.32801626
A3: 2021 | B3: 00791P107 | C3: =VLOOKUP(B3,'REFERENCE SHEET'!B:C,2,FALSE) -> AAV CN EQUITY | D3: ADVANTAGE ENERGY LTD. | E3: 4 | F3: ESG Scores | G3: EnvironmentPillarScore | H3: C- | I3: 0.27423839
A4: 2021 | B4: 00791P107 | C4: =VLOOKUP(B4,'REFERENCE SHEET'!B:C,2,FALSE) -> AAV CN EQUITY | D4: ADVANTAGE ENERGY LTD. | E4: 5 | F4: ESG Scores | G4: GovernancePillarScore | H4: B- | I4: 0.51237323
A5: 2021 | B5: 00791P107 | C5: =VLOOKUP(B5,'REFERENCE SHEET'!B:C,2,FALSE) -> AAV CN EQUITY | D5: ADVANTAGE ENERGY LTD. | E5: 6 | F5: ESG Scores | G5: SocialPillarScore | H5: C- | I5: 0.26886706
A6: 2022 | B6: 00791P107 | C6: =VLOOKUP(B6,'REFERENCE SHEET'!B:C,2,FALSE) -> AAV CN EQUITY | D6: ADVANTAGE ENERGY LTD. | E6: 2 | F6: ESG Scores | G6: ESGCombinedScore | H6: C | I6: 0.41035629
A7: 2022 | B7: 00791P107 | C7: =VLOOKUP(B7,'REFERENCE SHEET'!B:C,2,FALSE) -> AAV CN EQUITY | D7: ADVANTAGE ENERGY LTD. | E7: 4 | F7: ESG Scores | G7: EnvironmentPillarScore | H7: C- | I7: 0.28529917
A8: 2022 | B8: 00791P107 | C8: =VLOOKUP(B8,'REFERENCE SHEET'!B:C,2,FALSE) -> AAV CN EQUITY | D8: ADVANTAGE ENERGY LTD. | E8: 5 | F8: ESG Scores | G8: GovernancePillarScore | H8: B- | I8: 0.56397363
A9: 2022 | B9: 00791P107 | C9: =VLOOKUP(B9,'REFERENCE SHEET'!B:C,2,FALSE) -> AAV CN EQUITY | D9: ADVANTAGE ENERGY LTD. | E9: 6 | F9: ESG Scores | G9: SocialPillarScore | H9: C+ | I9: 0.42706643
A10: 2023 | B10: 00791P107 | C10: =VLOOKUP(B10,'REFERENCE SHEET'!B:C,2,FALSE) -> AAV CN EQUITY | D10: ADVANTAGE ENERGY LTD. | E10: 2 | F10: ESG Scores | G10: ESGCombinedScore | H10: C | I10: 0.38751429
A11: 2023 | B11: 00791P107 | C11: =VLOOKUP(B11,'REFERENCE SHEET'!B:C,2,FALSE) -> AAV CN EQUITY | D11: ADVANTAGE ENERGY LTD. | E11: 4 | F11: ESG Scores | G11: EnvironmentPillarScore | H11: C- | I11: 0.27132183
A12: 2023 | B12: 00791P107 | C12: =VLOOKUP(B12,'REFERENCE SHEET'!B:C,2,FALSE) -> AAV CN EQUITY | D12: ADVANTAGE ENERGY LTD. | E12: 5 | F12: ESG Scores | G12: GovernancePillarScore | H12: B- | I12: 0.52778796
A13: 2023 | B13: 00791P107 | C13: =VLOOKUP(B13,'REFERENCE SHEET'!B:C,2,FALSE) -> AAV CN EQUITY | D13: ADVANTAGE ENERGY LTD. | E13: 6 | F13: ESG Scores | G13: SocialPillarScore | H13: C | I13: 0.40441631
... A8376: 2024 | B8376: 30150P109 | C8376: =VLOOKUP(B8376,'REFERENCE SHEET'!B:C,2,FALSE) -> XTC CN EQUITY | D8376: EXCO TECHNOLOGIES LIMITED | E8376: 6 | F8376: ESG Scores | G8376: SocialPillarScore | H8376: C | I8376: 0.37258632

Sheet REFERENCE SHEET
A1: Ticker | B1: CUSIP | D1: Name | E1: 2024-Q4 | F1: 2024-Q3 | G1: 2024-Q2 | H1: 2024-Q1 | I1: 2023-Q4 | J1: 2023-Q3 | K1: 2023-Q2 | L1: 2023-Q1 | M1: 2022-Q4 | N1: 2022-Q3 | O1: 2022-Q2 | P1: 2022-Q1 | Q1: 2021-Q4 | R1: 2021-Q3 | S1: 2021-Q2 | T1: 2021-Q1 | U1: 2020-Q4 | V1: 2020-Q3 | W1: 2020-Q2 | X1: 2020-Q1 | Y1: 2019-Q4 | Z1: 2019-Q3 | AA1: 2019-Q2 | AB1: 2019-Q1 | AC1: 2018-Q4 | AD1: 2018-Q3 | AE1: 2018-Q2 | AF1: 2018-Q1 | AG1: 2017-Q4 | AH1: 2017-Q3 | AI1: 2017-Q2 | AJ1: 2017-Q1 | AK1: 2016-Q4 | AL1: 2016-Q3 | AM1: 2016-Q2 | AN1: 2016-Q1 | AO1: 2015-Q4 | AP1: 2015-Q3 | AQ1: 2015-Q2 | AR1: 2015-Q1
A2: AAV | B2: 00791P107 | C2: =A2&" CN EQUITY" -> AAV CN EQUITY | D2: Advantage Energy Ltd | E2: 1646387712 | F2: 1577886464 | G2: 1733170560 | H2: 1580187264 | I2: 1409015808 | J2: 1553945728 | K2: 1453393536 | L2: 1298478080 | M2: 1630605312 | N2: 1853482880 | O2: 1515478144 | P2: 1662120320 | Q2: 1414042752 | R2: 1221305472 | S2: 965594624 | T2: 445827328 | U2: 320753824 | V2: 328256864 | W2: 311375072 | X2: 267282512 | Y2: 514004832 | Z2: 401858336 | AA2: 304664672 | AB2: 409072704 | AC2: 368165440 | AD2: 669391680 | AE2: 765294208 | AF2: 708519744 | AG2: 1004201216 | AH2: 1454174720 | AI2: 1623263488 | AJ2: 1623166720 | AK2: 1683971072 | AL2: 1697906560 | AM2: 1332163456 | AN2: 1314780160 | AO2: 1200238592 | AP2: 1189886976 | AQ2: 1348260224 | AR2: 1161495680 | AZ2: AAV CN EQUITY
A3: ABX | B3: 06849F108 | C3: =A3&" CN EQUITY" -> ABX CN EQUITY | D3: Barrick Mining Corp | E3: 38807977984 | F3: 47092707328 | G3: 40063614976 | H3: 39552983040 | I3: 42027216896 | J3: 34635382784 | K3: 39373791232 | L3: 44041723904 | M3: 40809807872 | N3: 37830107136 | O3: 40418488320 | P3: 54305181696 | Q3: 42771628032 | R3: 40672067584 | S3: 45597442048 | T3: 44331745280 | U3: 51565649920 | V3: 66499747840 | W3: 64951975936 | X3: 45977956352 | Y3: 42880098304 | Z3: 40744468480 | AA3: 36213465088 | AB3: 32096307200 | AC3: 21518743552 | AD3: 16678699008 | AE3: 20152412160 | AF3: 18728630272 | AG3: 21202667520 | AH3: 23413340160 | AI3: 24049934336 | AJ3: 29442402304 | AK3: 25045110784 | AL3: 27070646272 | AM3: 32136636416 | AN3: 20552036352 | AO3: 11927520256 | AP3: 9888047104 | AQ3: 15548340224 | AR3: 16130674688 | AZ3: AC CN EQUITY
A4: AC | B4: 008911877 | C4: =A4&" CN EQUITY" -> AC CN EQUITY | D4: Air Canada | E4: 7779318784 | F4: 5875700224 | G4: 6417025024 | H4: 7029621760 | I4: 6699790848 | J4: 6947129344 | K4: 8957712384 | L4: 6863493120 | M4: 6962915840 | N4: 5958284288 | O4: 5741809152 | P4: 8677977088 | Q4: 7557477376 | R4: 8274573312 | S4: 9121979392 | T4: 8788898816 | U4: 7563556352 | V4: 4655280128 | W4: 5029078528 | X4: 4117028352 | Y4: 12846358528 | Z4: 11526511616 | AA4: 10641859584 | AB4: 8722577408 | AC4: 7027732480 | AD4: 7527800320 | AE4: 5788850176 | AF4: 7310460416 | AG4: 7066720768 | AH4: 7189917696 | AI4: 4717142016 | AJ4: 3760470784 | AK4: 3735870720 | AL4: 2927563520 | AM4: 2458871808 | AN4: 2523493376 | AO4: 2894456832 | AP4: 3065968384 | AQ4: 3789085440 | AR4: 3550374656 | AZ4: ACO/X CN EQUITY
A5: ACO/X | B5: 046789400 | C5: =A5&" CN EQUITY" -> ACO/X CN EQUITY | D5: Atco Ltd/Canada | E5: 5356498432 | F5: 5438578688 | G5: 4408354816 | H5: 4251751936 | I5: 4357063680 | J5: 3918804224 | K5: 4473836544 | L5: 4942422528 | M5: 4803340288 | N5: 4836183040 | O5: 5043595776 | P5: 4898488320 | Q5: 4888135680 | R5: 4650233344 | S5: 5050794496 | T5: 4790389248 | U5: 4201691648 | V5: 4416777728 | W5: 4600962560 | X5: 4468485120 | Y5: 5708773888 | Z5: 5564491776 | AA5: 5058420736 | AB5: 5159705600 | AC5: 4430725632 | AD5: 4332813824 | AE5: 4656373760 | AF5: 4748883456 | AG5: 5159636992 | AH5: 5252987904 | AI5: 5815187968 | AJ5: 5930008576 | AK5: 5122024960 | AL5: 5346150400 | AM5: 5192025600 | AN5: 4518471680 | AO5: 4107735808 | AP5: 4514950144 | AQ5: 4546976768 | AR5: 5197527552 | AZ5: ACQ CN EQUITY
A6: AEM | B6: 008474108 | C6: =A6&" CN EQUITY" -> AEM CN EQUITY | D6: Agnico Eagle Mines Ltd | E6: 56443891712 | F6: 54646591488 | G6: 44764639232 | H6: 40299433984 | I6: 36073746432 | J6: 30578929664 | K6: 32715147264 | L6: 31490955264 | M6: 32076687360 | N6: 26591344640 | O6: 26859173888 | P6: 34790236160 | Q6: 16452568064 | R6: 16057384960 | S6: 18287462400 | T6: 17688954880 | U6: 21762924544 | V6: 25655674880 | W6: 21053421568 | X6: 13530664960 | Y6: 19183237120 | Z6: 16999652352 | AA6: 15823868928 | AB6: 13658712064 | AC6: 12926810112 | AD6: 10335356928 | AE6: 14079306752 | AF6: 12637274112 | AG6: 13488970752 | AH6: 13082985472 | AI6: 13550573568 | AJ6: 12744101888 | AK6: 12717728768 | AL6: 15931622400 | AM6: 15424679936 | AN6: 10380139520 | AO6: 7916745216 | AP6: 7354202112 | AQ6: 7666540544 | AR6: 7615286784 | AZ6: ADEN CN EQUITY
A7: AG | B7: 32076V103 | C7: =A7&" CN EQUITY" -> AG CN EQUITY | D7: First Majestic Silver Corp | E7: 2383937280 | F7: 2449124864 | G7: 2351210752 | H7: 2282816512 | I7: 2332766208 | J7: 1997036544 | K7: 2126761216 | L7: 2676179456 | M7: 3026874112 | N7: 2776702464 | O7: 2426123008 | P7: 4274784768 | Q7: 3610731264 | R7: 3677938176 | S7: 4930934272 | T7: 4364550144 | U7: 3779883776 | V7: 2728916992 | W7: 2829510144 | X7: 1814737280 | Y7: 3226195200 | Z7: 2440404992 | AA7: 2089173248 | AB7: 1728342912 | AC7: 1553197312 | AD7: 1415606144 | AE7: 1936780800 | AF7: 1309354624 | AG7: 1405099264 | AH7: 1411037952 | AI7: 1776939136 | AJ7: 1774540288 | AK7: 1687144832 | AL7: 2213533952 | AM7: 2847280384 | AN7: 1310686848 | AO7: 701422144 | AP7: 522668032 | AQ7: 739398528 | AR7: 801995456 | AZ7: ADN CN EQUITY
A8: AGI | B8: 011532108 | C8: =A8&" CN EQUITY" -> AGI CN EQUITY | D8: Alamos Gold Inc | E8: 11142990848 | F8: 11315946496 | G8: 8559896064 | H8: 7924278272 | I8: 7070629888 | J8: 6068656640 | K8: 6250302976 | L8: 6500131840 | M8: 5383944704 | N8: 4016207104 | O8: 3545876224 | P8: 4114842112 | Q8: 3815324672 | R8: 3574255616 | S8: 3719620352 | T8: 3857068288 | U8: 4367131648 | V8: 4594193920 | W8: 4954233856 | X8: 2769891584 | Y8: 3062084608 | Z8: 3011848960 | AA8: 3081672960 | AB8: 2636103936 | AC8: 1921017216 | AD8: 2311550208 | AE8: 2914751232 | AF8: 2607320832 | AG8: 3186339072 | AH8: 2534509824 | AI8: 2749072128 | AJ8: 3191288832 | AK8: 2491526144 | AL8: 2876170752 | AM8: 2948805120 | AN8: 1844908672 | AO8: 1167923456 | AP8: 1262198016 | AQ8: 904238144 | AR8: 944992512 | AZ8: ADW/A CN EQUITY
A9: AIF | B9: 02215R107 | C9: =A9&" CN EQUITY" -> AIF CN EQUITY | D9: Altus Group Ltd/Canada | E9: 2586639872 | F9: 2534984448 | G9: 2331340288 | H9: 2386389760 | I9: 1932735104 | J9: 2158483456 | K9: 2015424000 | L9: 2613003520 | M9: 2451339776 | N9: 2028156160 | O9: 2017189120 | P9: 2264322560 | Q9: 3172848128 | R9: 2585094400 | S9: 2395868160 | T9: 2473533184 | U9: 2004295040 | V9: 2244134912 | W9: 1652837120 | X9: 1470111360 | Y9: 1524445952 | Z9: 1602520320 | AA9: 1270935168 | AB9: 1026608960 | AC9: 930303872 | AD9: 1200637440 | AE9: 1144430976 | AF9: 1266111616 | AG9: 1429149184 | AH9: 1227808256 | AI9: 1081707136 | AJ9: 1101388928 | AK9: 1158704128 | AL9: 1089304064 | AM9: 826008064 | AN9: 766711360 | AO9: 708210112 | AP9: 682053312 | AQ9: 578221632 | AR9: 632991104 | AZ9: AGF/B CN EQUITY
A10: ALA | B10: 021361100 | C10: =A10&" CN EQUITY" -> ALA CN EQUITY | D10: AltaGas Ltd | E10: 9971879936 | F10: 9966685184 | G10: 9166783488 | H10: 8836188160 | I10: 8194971136 | J10: 7339083264 | K10: 6704039936 | L10: 6344253440 | M10: 6581919232 | N10: 7441016832 | O10: 7622471168 | P10: 7852406272 | Q10: 7651362816 | R10: 7001172992 | S10: 7283146752 | T10: 5853430272 | U10: 5231352320 | V10: 4493476864 | W10: 4373315584 | X10: 3562669824 | Y10: 5511896576 | Z10: 5391819264 | AA10: 5465117184 | AB10: 4847395328 | AC10: 3791446016 | AD10: 5468099072 | AE10: 7151847424 | AF10: 6280448000 | AG10: 7304140288 | AH10: 7250946048 | AI10: 7411161088 | AJ10: 7626598400 | AK10: 5636426752 | AL10: 5525857792 | AM10: 5104321024 | AN10: 4907148800 | AO10: 4549060096 | AP10: 4758144512 | AQ10: 5129059328 | AR10: 5678100480 | AZ10: AI CN EQUITY
A11: AP-U | B11: 019456102 | C11: =A11&" CN EQUITY" -> AP-U CN EQUITY | D11: Allied Properties Real Estate | E11: 2194445056 | F11: 2587269888 | G11: 1959006080 | H11: 2248611072 | I11: 2568023296 | J11: 2281697536 | K11: 2763997184 | L11: 3099952640 | M11: 3257750016 | N11: 3481720320 | O11: 4223621888 | P11: 5933940736 | Q11: 5592894976 | R11: 5118230528 | S11: 5732876288 | T11: 5171678208 | U11: 4814089216 | V11: 4562122240 | W11: 5042698240 | X11: 5495291904 | Y11: 6395615744 | Z11: 6228705280 | AA11: 5507816960 | AB11: 5362827776 | AC11: 4600924160 | AD11: 4474274304 | AE11: 4195988480 | AF11: 3761268992 | AG11: 3902223872 | AH11: 3694500864 | AI11: 3295697664 | AJ11: 3056056832 | AK11: 3044201728 | AL11: 3190695936 | AM11: 2989293312 | AN11: 2702574592 | AO11: 2439813632 | AP11: 2699483392 | AQ11: 2738897408 | AR11: 3112945664 | AZ11: AIF CN EQUITY
A12: AQN | B12: 015857105 | C12: =A12&" CN EQUITY" -> AQN CN EQUITY | D12: Algonquin Power & Utilities Co | E12: 4895110144 | F12: 5668532736 | G12: 5543098880 | H12: 5901607936 | I12: 5761210880 | J12: 5538054144 | K12: 7540876800 | L12: 7750265856 | M12: 6062156800 | N12: 10194551808 | O12: 11687590912 | P12: 13028030464 | Q12: 12275508224 | R12: 11499719680 | S12: 11300712448 | T12: 11886893056 | U12: 12507805696 | V12: 11454545920 | W12: 9255700480 | X12: 9934031872 | Y12: 9544770560 | Z12: 8951825408 | AA12: 7796688384 | AB12: 7122724864 | AC12: 6506654208 | AD12: 6308524032 | AE12: 5977105920 | AF12: 5513651200 | AG12: 6068597760 | AH12: 5044759552 | AI12: 5220695040 | AJ12: 4736491520 | AK12: 3112865280 | AL12: 3211252480 | AM12: 3086951168 | AN12: 2744537600 | AO12: 2754637056 | AP12: 2247969536 | AQ12: 2228918784 | AR12: 2228918784 | AZ12: AIM CN EQUITY
A13: ARE | B13: 00762V109 | C13: =A13&" CN EQUITY" -> ARE CN EQUITY | D13: Aecon Group Inc | E13: 1697589760 | F13: 1307172224 | G13: 1057283520 | H13: 1059151488 | I13: 807557248 | J13: 701163456 | K13: 763145664 | L13: 844885696 | M13: 555817728 | N13: 580832576 | O13: 799964096 | P13: 1032164416 | Q13: 1018221312 | R13: 1156356736 | S13: 1085723392 | T13: 1171319680 | U13: 979629184 | V13: 819107904 | W13: 883774272 | X13: 758210752 | Y13: 1061183104 | Z13: 1108290816 | AA13: 1151260160 | AB13: 1046676032 | AC13: 1055079808 | AD13: 972319936 | AE13: 923766080 | AF13: 1093209344 | AG13: 1174446464 | AH13: 1033082304 | AI13: 945496384 | AJ13: 1000904640 | AK13: 876374464 | AL13: 1039578176 | AM13: 1007718336 | AN13: 922963392 | AO13: 869642432 | AP13: 767387584 | AQ13: 719708352 | AR13: 633343360 | AZ13: ALS CN EQUITY
A14: ARX | B14: 00208D408 | C14: =A14&" CN EQUITY" -> ARX CN EQUITY | D14: ARC Resources Ltd | E14: 15429603328 | F14: 13611326464 | G14: 14585907200 | H14: 14436017152 | I14: 11817239552 | J14: 13177922560 | K14: 10782667776 | L14: 9495879680 | M14: 11421119488 | N14: 10864626688 | O14: 10912884736 | P14: 11547301888 | Q14: 8034594304 | R14: 8605234176 | S14: 7635851264 | T14: 2735747328 | U14: 2124921600 | V14: 2107213952 | W14: 1614940416 | X14: 1434322176 | Y14: 2896976640 | Z14: 2234709248 | AA14: 2268476160 | AB14: 3227535616 | AC14: 2866668544 | AD14: 5096299520 | AE14: 4804002816 | AF14: 4966730240 | AG14: 5217854464 | AH14: 6080831488 | AI14: 5997367296 | AJ14: 6739075584 | AK14: 8160606208 | AL14: 8345443840 | AM14: 7755399168 | AN14: 6580125184 | AO14: 5779362816 | AP14: 6055498240 | AQ14: 7263007744 | AR14: 7367747584 | AZ14: AND CN EQUITY
A15: ASTL | B15: 15658107 | C15: =A15&" CN EQUITY" -> ASTL CN EQUITY | D15: Algoma Steel Group Inc | E15: 1474472064 | F15: 1447303808 | G15: 988127936 | H15: 1202390528 | I15: 1381052032 | J15: 954186048 | K15: 969395392 | L15: 1134068352 | M15: 886839232 | N15: 937696704 | O15: 1701514624 | P15: 1573530368 | Q15: 1521966208 | R15: -- | S15: -- | T15: -- | U15: -- | V15: -- | W15: -- | X15: -- | Y15: -- | Z15: -- | AA15: -- | AB15: -- | AC15: -- | AD15: -- | AE15: -- | AF15: -- | AG15: -- | AH15: -- | AI15: -- | AJ15: -- | AK15: -- | AL15: -- | AM15: -- | AN15: -- | AO15: -- | AP15: -- | AQ15: -- | AR15: -- | AZ15: APR-U CN EQUITY
A16: ATD | B16: 01626P148 | C16: =A16&" CN EQUITY" -> ATD CN EQUITY | D16: Alimentation Couche-Tard Inc | E16: 75558395904 | F16: 70880894976 | G16: 73444433920 | H16: 74355777536 | I16: 75187961856 | J16: 66640760832 | K16: 66502021120 | L16: 66952843264 | M16: 59886936064 | N16: 56837222400 | O16: 51509608448 | P16: 58808741888 | Q16: 56287309824 | R16: 52039499776 | S16: 49006710784 | T16: 44091064320 | U16: 48310153216 | V16: 51617562624 | W16: 47666987008 | X16: 37258641408 | Y16: 46330957824 | Z16: 45748342784 | AA16: 46503993344 | AB16: 44454727680 | AC16: 38328074240 | AD16: 36487589888 | AE16: 32300642304 | AF16: 32479109120 | AG16: 36855721984 | AH16: 32420294656 | AI16: 35355680768 | AJ16: 34423926784 | AK16: 34978963456 | AL16: 36170809344 | AM16: 31551803392 | AN16: 33026658304 | AO16: 34668249088 | AP16: 34958462976 | AQ16: 30412279808 | AR16: 28787920896 | AZ16: AP-U CN EQUITY
A17: ATH | B17: 04682R107 | C17: =A17&" CN EQUITY" -> ATH CN EQUITY | D17: Athabasca Oil Corp | E17: 2793556736 | F17: 2580307200 | G17: 2872803584 | H17: 2966092032 | I17: 2416014592 | J17: 2527933696 | K17: 1698880384 | L17: 1894919296 | M17: 1413438464 | N17: 1246526080 | O17: 1445492992 | P17: 1077703168 | Q17: 631705088 | R17: 488221344 | S17: 520061888 | T17: 281257952 | U17: 90214816 | V17: 68987800 | W17: 95521568 | X17: 75923296 | Y17: 308833792 | Z17: 334853984 | AA17: 382096224 | AB17: 438569824 | AC17: 510705728 | AD17: 820115072 | AE17: 927252032 | AF17: 607085312 | AG17: 545465152 | AH17: 570905152 | AI17: 514023904 | AJ17: 775165824 | AK17: 833090496 | AL17: 523829952 | AM17: 579702400 | AN17: 416717472 | AO17: 617558976 | AP17: 512335392 | AQ17: 822005248 | AR17: 849367680 | AZ17: AQN CN EQUITY
A18: ATRL | B18: 04764T104 | C18: =A18&" CN EQUITY" -> ATRL CN EQUITY | D18: AtkinsRealis Group Inc | E18: 13307099136 | F18: 9623729152 | G18: 10379665408 | H18: 9725705216 | I18: 7489144320 | J18: 7954363392 | K18: 6100510208 | L18: 5831912448 | M18: 4188724480 | N18: 4037747712 | O18: 3886771200 | P18: 5284183040 | Q18: 5426381824 | R18: 6175998464 | S18: 5661624832 | T18: 4722409472 | U18: 3814793984 | V18: 3748083200 | W18: 4021947904 | X18: 3644506368 | Y18: 5257849856 | Z18: 3275842304 | AA18: 4648676352 | AB18: 5954800128 | AC18: 8061451264 | AD18: 9246442496 | AE18: 10191333376 | AF18: 9929096192 | AG18: 10010983424 | AH18: 9892482048 | AI18: 9396936704 | AJ18: 7847200768 | AK18: 8685224960 | AL18: 7740161536 | AM18: 8143421440 | AN18: 7106723328 | AO18: 6158466560 | AP18: 5687970304 | AQ18: 6383876096 | AR18: 5996510720 | AZ18: ARE CN EQUITY
A19: ATS | B19: 00217Y104 | C19: =A19&" CN EQUITY" -> ATS CN EQUITY | D19: ATS Corp | E19: 4293112064 | F19: 3842648576 | G19: 4335091200 | H19: 4509460992 | I19: 5648172544 | J19: 5725241856 | K19: 6024563200 | L19: 5194683904 | M19: 3862636032 | N19: 3345015040 | O19: 3241583872 | P19: 4160936192 | Q19: 4634822144 | R19: 3705853696 | S19: 3276103424 | T19: 2437281024 | U19: 2056299904 | V19: 1599625472 | W19: 1761543808 | X19: 1518985984 | Y19: 1975765120 | Z19: 1665746816 | AA19: 1957670528 | AB19: 1830841984 | AC19: 1354661632 | AD19: 2259861760 | AE19: 1853425280 | AF19: 1661912576 | AG19: 1459590144 | AH19: 1241471104 | AI19: 1244077184 | AJ19: 1256128896 | AK19: 1158921472 | AL19: 1015939200 | AM19: 897115776 | AN19: 975747904 | AO19: 1053123200 | AP19: 1194227712 | AQ19: 1401017472 | AR19: 1244195072 | AZ19: ARIS CN EQUITY
A20: ATZ | B20: 04045U102 | C20: =A20&" CN EQUITY" -> ATZ CN EQUITY | D20: Aritzia Inc | E20: 6032571904 | F20: 5729277952 | G20: 4333110272 | H20: 4143386880 | I20: 3049657600 | J20: 2621653248 | K20: 4134684672 | L20: 4857106432 | M20: 5291279360 | N20: 4981030912 | O20: 3844553216 | P20: 5792592384 | Q20: 5936025088 | R20: 4555462144 | S20: 4081010176 | T20: 3210651392 | U20: 2823394048 | V20: 1907240192 | W20: 2078703744 | X20: 1333765376 | Y20: 2056904704 | Z20: 2151201024 | AA20: 2330675968 | AB20: 2466418688 | AC20: 1964058496 | AD20: 1932424576 | AE20: 1753467520 | AF20: 1347300864 | AG20: 1411837952 | AH20: 1636499712 | AI20: 1638474496 | AJ20: 1689236352 | AK20: 1871906688 | AL20: -- | AM20: -- | AN20: -- | AO20: -- | AP20: -- | AQ20: -- | AR20: -- | AZ20: ATH CN EQUITY
A21: AYA | B21: 05466C109 | C21: =A21&" CN EQUITY" -> AYA CN EQUITY | D21: Aya Gold & Silver Inc | E21: 1403046400 | F21: 2295978496 | G21: 1767660672 | H21: 1516343424 | I21: 1188287488 | J21: 852561600 | K21: 996763904 | L21: 1263948544 | M21: 946734720 | N21: 840725632 | O21: 688534336 | P21: 933738048 | Q21: 999685888 | R21: 811713792 | S21: 886323712 | T21: 466110112 | U21: 354899584 | V21: 240594272 | W21: 113747376 | X21: 77196232 | Y21: 155255296 | Z21: 139370160 | AA21: 149661248 | AB21: 172384688 | AC21: 148894192 | AD21: 180711392 | AE21: 199540208 | AF21: 128069064 | AG21: 88561944 | AH21: 81589704 | AI21: 39012444 | AJ21: 29522930 | AK21: 27907546 | AL21: 33887736 | AM21: 29301140 | AN21: 26213546 | AO21: 18824054 | AP21: 28236080 | AQ21: 31213850 | AR21: 29939816 | AZ21: ATS CN EQUITY
A22: BAM | B22: 113004105 | C22: =A22&" CN EQUITY" -> BAM CN EQUITY | D22: Brookfield Asset Management Lt | E22: 34540109824 | F22: 28370855936 | G22: 23110426624 | H22: 23509430272 | I22: 21964765184 | J22: 18675122176 | K22: 17834174464 | L22: 18256191488 | M22: 63499468800 | N22: -- | O22: -- | P22: -- | Q22: -- | R22: -- | S22: -- | T22: -- | U22: -- | V22: -- | W22: -- | X22: -- | Y22: -- | Z22: -- | AA22: -- | AB22: -- | AC22: -- | AD22: -- | AE22: -- | AF22: -- | AG22: -- | AH22: -- | AI22: -- | AJ22: -- | AK22: -- | AL22: -- | AM22: -- | AN22: -- | AO22: -- | AP22: -- | AQ22: -- | AR22: -- | AZ22: ATZ CN EQUITY
A23: BB | B23: 09228F103 | C23: =A23&" CN EQUITY" -> BB CN EQUITY | D23: BlackBerry Ltd | E23: 3230044160 | F23: 2102991616 | G23: 2018386304 | H23: 2186052608 | I23: 2698442240 | J23: 3753091072 | K23: 4280980224 | L23: 3609374720 | M23: 2559327744 | N23: 3758977536 | O23: 4005552384 | P23: 5341632512 | Q23: 6780739584 | R23: 6991048192 | S23: 8578220032 | T23: 5960425984 | U23: 4743413760 | V23: 3400018432 | W23: 3694890240 | X23: 3197728256 | Y23: 4610301952 | Z23: 3805451264 | AA23: 5347258368 | AB23: 7372897280 | AC23: 5249024000 | AD23: 7862163968 | AE23: 6810575872 | AF23: 7948834816 | AG23: 7529755136 | AH23: 7399238656 | AI23: 6887924224 | AJ23: 5464121344 | AK23: 4896849920 | AL23: 5468687872 | AM23: 4530219520 | AN23: 5493122560 | AO23: 6749996544 | AP23: 4293288960 | AQ23: 5405492224 | AR23: 5970178048 | AZ23: AX-U CN EQUITY
A24: BBD/B | B24: 097751861 | C24: =A24&" CN EQUITY" -> BBD/B CN EQUITY | D24: Bombardier Inc | E24: 9768412160 | F24: 10286349312 | G24: 8760404992 | H24: 5793561600 | I24: 5297312256 | J24: 4707893760 | K24: 6467159552 | L24: 7276578304 | M24: 5108203008 | N24: 2439795200 | O24: 1933459200 | P24: 3541554176 | Q24: 4117212672 | R24: 5291314176 | S24: 2983207936 | T24: 2416227840 | U24: 1274648448 | V24: 827308800 | W24: 1094477568 | X24: 1193630336 | Y24: 4703885824 | Z24: 4371474432 | AA24: 5360430080 | AB24: 6275293696 | AC24: 4956424192 | AD24: 11128473600 | AE24: 12563041280 | AF24: 8418777088 | AG24: 6810583552 | AH24: 5092957696 | AI24: 5317615616 | AJ24: 4633240064 | AK24: 4925295104 | AL24: 4115937024 | AM24: 4446145024 | AN24: 2983606528 | AO24: 3054138112 | AP24: 3757637120 | AQ24: 5114784768 | AR24: 5647144448 | AZ24: AYA CN EQUITY
A25: BBU-U | B25: G16234109 | C25: =A25&" CN EQUITY" -> BBU-U CN EQUITY | D25: Brookfield Business Partners L | E25: 4881168384 | F25: 4565836288 | G25: 3730710016 | H25: 4319618048 | I25: 3945631488 | J25: 2975849984 | K25: 3320768512 | L25: 3594973696 | M25: 3303400704 | N25: 3905199872 | O25: 3963250688 | P25: 5632005120 | Q25: 8565309952 | R25: 8571139584 | S25: 8501852160 | T25: 7527044096 | U25: 7225088512 | V25: 6094448640 | W25: 6001179136 | X25: 5124467200 | Y25: 7747236864 | Z25: 7483372544 | AA25: 6592053248 | AB25: 6845444608 | AC25: 5375516160 | AD25: 7654745600 | AE25: 6514484224 | AF25: 6003823104 | AG25: 5596587008 | AH25: 3995844352 | AI25: 3787412480 | AJ25: 3558461440 | AK25: 3161479936 | AL25: 3104999936 | AM25: 2205900032 | AN25: -- | AO25: -- | AP25: -- | AQ25: -- | AR25: -- | AZ25: BB CN EQUITY
A26: BCE | B26: 05534B760 | C26: =A26&" CN EQUITY" -> BCE CN EQUITY | D26: BCE Inc | E26: 30397272064 | F26: 42895552512 | G26: 40423264256 | H26: 41992036352 | I26: 47593349120 | J26: 47302213632 | K26: 55102255104 | L26: 55221215232 | M26: 54179221504 | N26: 52819214336 | O26: 57696374784 | P26: 63046504448 | Q26: 59811401728 | R26: 57555828736 | S26: 55308185600 | T26: 51315638272 | U26: 49225105408 | V26: 49936977920 | W26: 51203035136 | X26: 52201984000 | Y26: 54370328576 | Z26: 57677279232 | AA26: 53606068224 | AB26: 53311856640 | AC26: 48432807936 | AD26: 46992797696 | AE26: 47808401408 | AF26: 49954467840 | AG26: 54381891584 | AH26: 52634619904 | AI26: 52529074176 | AJ26: 52900503552 | AK26: 50516602880 | AL26: 52695031808 | AM26: 53150429184 | AN26: 51375751168 | AO26: 46264786944 | AP26: 46371414016 | AQ26: 44993060864 | AR26: 45069574144 | AZ26: BBD/B CN EQUITY
A27: BDGI | B27: 056533102 | C27: =A27&" CN EQUITY" -> BDGI CN EQUITY | D27: Badger Infrastructure Solution | E27: 1232156416 | F27: 1267360384 | G27: 1419960960 | H27: 1730566528 | I27: 1403413632 | J27: 1195883520 | K27: 927335488 | L27: 1126592000 | M27: 919061888 | N27: 970427264 | O27: 973529920 | P27: 1084534400 | Q27: 1095910656 | R27: 1166925824 | S27: 1309734144 | T27: 1494184064 | U27: 1325491456 | V27: 1327234176 | W27: 1035856064 | X27: 794188864 | Y27: 1231085568 | Z27: 1450954112 | AA27: 1714319488 | AB27: 1457422720 | AC27: 1196497024 | AD27: 1098180096 | AE27: 1174978560 | AF27: 956084544 | AG27: 1008396480 | AH27: 985765120 | AI27: 987620160 | AJ27: 1296668800 | AK27: 1190931840 | AL27: 1051804352 | AM27: 834765312 | AN27: 815843968 | AO27: 905998656 | AP27: 722392960 | AQ27: 970229312 | AR27: 1001718208 | AZ27: BCE CN EQUITY
A28: BDT | B28: 09076P104 | C28: =A28&" CN EQUITY" -> BDT CN EQUITY | D28: Bird Construction Inc | E28: 1443276544 | F28: 1337495424 | G28: 1445380992 | H28: 1004545152 | I28: 774354816 | J28: 553341056 | K28: 453857952 | L28: 488811456 | M28: 436005792 | N28: 320023936 | O28: 401103840 | P28: 490238016 | Q28: 527287776 | R28: 528361696 | S28: 468333728 | T28: 474698400 | U28: 424311424 | V28: 341040256 | W28: 252975280 | X28: 193876848 | Y28: 303995488 | Z28: 241495728 | AA28: 240220224 | AB28: 335032800 | AC28: 259777968 | AD28: 335457984 | AE28: 308672352 | AF28: 363519104 | AG28: 431120896 | AH28: 423042688 | AI28: 362243584 | AJ28: 425593696 | AK28: 385202720 | AL28: 482566304 | AM28: 568450304 | AN28: 471086720 | AO28: 552719104 | AP28: 510202240 | AQ28: 473637760 | AR28: 400933920 | AZ28: BDGI CN EQUITY
A29: BEI-U | B29: 096631106 | C29: =A29&" CN EQUITY" -> BEI-U CN EQUITY | D29: Boardwalk Real Estate Investme | E29: 3512735232 | F29: 4683282432 | G29: 3853347584 | H29: 4268861696 | I29: 3900366336 | J29: 3403053824 | K29: 3167728128 | L29: 2808627200 | M29: 2517780992 | N29: 2356312832 | O29: 2133211904 | P29: 2994544640 | Q29: 2792836864 | R29: 2408777216 | S29: 2082275712 | T29: 1849496832 | U29: 1718590464 | V29: 1398201216 | W29: 1513317248 | X29: 1158154880 | Y29: 2321870592 | Z29: 2245030912 | AA29: 2014006656 | AB29: 2061525888 | AC29: 1911385344 | AD29: 2536212736 | AE29: 2308727040 | AF29: 2237953536 | AG29: 2178301952 | AH29: 1921495808 | AI29: 2403765504 | AJ29: 2384555520 | AK29: 2527558912 | AL29: 2688619520 | AM29: 2990472192 | AN29: 2690697728 | AO29: 2465217280 | AP29: 2848118272 | AQ29: 2942155008 | AR29: 3062688256 | AZ29: BDT CN EQUITY
A30: BEP-U | B30: N/A | C30: =A30&" CN EQUITY" -> BEP-U CN EQUITY | D30: Brookfield Renewable Partners | E30: 21579894784 | F30: 25139193856 | G30: 22311528448 | H30: 20831242240 | I30: 23024877568 | J30: 14260872192 | K30: 18355118080 | L30: 20015509504 | M30: 16103885824 | N30: 20268904448 | O30: 21007316992 | P30: 24093843456 | Q30: 21272969216 | R30: 21969442816 | S30: 22483159040 | T30: 21701414912 | U30: 22225080320 | V30: 21895790592 | W30: 20063913984 | X30: 18268190720 | Y30: 18608826368 | Z30: 16600801280 | AA30: 13975518208 | AB30: 13140388864 | AC30: 10938591232 | AD30: 12130399232 | AE30: 12237450240 | AF30: 12420482048 | AG30: 13579982848 | AH30: 12956984320 | AI30: 12264250368 | AJ30: 11682019328 | AK30: 11811981312 | AL30: 11945080832 | AM30: 11393988608 | AN30: 5621567488 | AO30: 5194257920 | AP30: 5260904448 | AQ30: 5325898240 | AR30: 5734274048 | AZ30: BEI-U CN EQUITY
A31: BHC | B31: 071734107 | C31: =A31&" CN EQUITY" -> BHC CN EQUITY | D31: Bausch Health Cos Inc | E31: 4202151168 | F31: 3989100032 | G31: 3499240704 | H31: 5243661312 | I31: 3882023424 | J31: 4080543744 | K31: 3855473152 | L31: 3964307200 | M31: 3075879168 | N31: 3450889728 | O31: 3889521664 | P31: 10271504384 | Q31: 12555016192 | R31: 12673125376 | S31: 13038433280 | T31: 14180221952 | U31: 9379537920 | V31: 7348358656 | W31: 8811429888 | X31: 7706696704 | Y31: 13595064320 | Z31: 10107984896 | AA31: 11555979264 | AB31: 11531496448 | AC31: 8831370240 | AD31: 11596721152 | AE31: 10670482432 | AF31: 7154718208 | AG31: 9124427776 | AH31: 6210264576 | AI31: 7690444800 | AJ31: 5012095488 | AK31: 6642988032 | AL31: 10982937600 | AM31: 8888025088 | AN31: 11617552384 | AO31: 47425544192 | AP31: 81271693312 | AQ31: 94578049024 | AR31: 85286240256 | AZ31: BHC CN EQUITY
A32: BIR | B32: 090697103 | C32: =A32&" CN EQUITY" -> BIR CN EQUITY | D32: Birchcliff Energy Ltd | E32: 1465057792 | F32: 1535390464 | G32: 1616449280 | H32: 1433702656 | I32: 1540620544 | J32: 2062201600 | K32: 2086199040 | L32: 2042483840 | M32: 2507785728 | N32: 2601390592 | O32: 2321688064 | P32: 2223447296 | Q32: 1713037056 | R32: 1861889152 | S32: 1383495808 | T32: 694355008 | U32: 470705344 | V32: 406880896 | W32: 303166176 | X32: 207429472 | Y32: 688772224 | Z32: 569101376 | AA32: 691403328 | AB32: 946644480 | AC32: 808370560 | AD32: 1382603904 | AE32: 1281265408 | AF32: 991421696 | AG32: 1169483520 | AH32: 1605827072 | AI32: 1621683456 | AJ32: 2007341568 | AK32: 2466674944 | AL32: 2413155072 | AM32: 1047875904 | AN32: 805706880 | AO32: 615322496 | AP32: 971696576 | AQ32: 1061461568 | AR32: 1032441728 | AZ32: BIR CN EQUITY
A33: BLX | B33: 09950M300 | C33: =A33&" CN EQUITY" -> BLX CN EQUITY | D33: Boralex Inc | E33: 2950414848 | F33: 3697524480 | G33: 3443692032 | H33: 2941165824 | I33: 3461162496 | J33: 2998714880 | K33: 3706773248 | L33: 4228825088 | M33: 4112569344 | N33: 4508206080 | O33: 4404535808 | P33: 4158109696 | Q33: 3558816512 | R33: 3837939456 | S33: 3873856000 | T33: 4055491072 | U33: 4844643840 | V33: 3946991360 | W33: 2980759040 | X33: 2411611392 | Y33: 2356172288 | Z33: 2019772032 | AA33: 1756115328 | AB33: 1690931968 | AC33: 1501564928 | AD33: 1607230080 | AE33: 1607276032 | AF33: 1705835776 | AG33: 1791820032 | AH33: 1635582336 | AI33: 1666187136 | AJ33: 1625110144 | AK33: 1448215552 | AL33: 1221076992 | AM33: 1270153728 | AN33: 1048702272 | AO33: 937428928 | AP33: 611554880 | AQ33: 636734848 | AR33: 636627328 | AZ33: BLDP CN EQUITY
A34: BMO | B34: 063671101 | C34: =A34&" CN EQUITY" -> BMO CN EQUITY | D34: Bank of Montreal | E34: 101824733184 | F34: 89017958400 | G34: 83743760384 | H34: 96434372608 | I34: 96082706432 | J34: 82597347328 | K34: 85753184256 | L34: 86131032064 | M34: 86252838912 | N34: 81996111872 | O34: 83472424960 | P34: 98775031808 | Q34: 88286445568 | R34: 81930592256 | S34: 82238578688 | T34: 72483643392 | U34: 62571487232 | V34: 50052005888 | W34: 46462717952 | X34: 45452005376 | Y34: 64325668864 | Z34: 62347444224 | AA34: 63186227200 | AB34: 63833980928 | AC34: 57021808640 | AD34: 68178124800 | AE34: 65102888960 | AF34: 62822809600 | AG34: 65166413824 | AH34: 61257621504 | AI34: 62143553536 | AJ34: 64728539136 | AK34: 62573797376 | AL34: 55438409728 | AM34: 52753158144 | AN34: 50735632384 | AO34: 50172903424 | AP34: 46747967488 | AQ34: 47694241792 | AR34: 49122926592 | AZ34: BLX CN EQUITY
A35: BN | B35: 11271J107 | C35: =A35&" CN EQUITY" -> BN CN EQUITY | D35: Brookfield Corp | E35: 136088051712 | F35: 118175293440 | G35: 93528629248 | H35: 85826363392 | I35: 87132307456 | J35: 69575475200 | K35: 73055068160 | L35: 72165679104 | M35: 69743304704 | N35: 88254849024 | O35: 93991280640 | P35: 110846091264 | Q35: 119800979456 | R35: 106435616768 | S35: 99787628544 | T35: 84435189760 | U35: 82881200128 | V35: 69342814208 | W35: 70279823360 | X35: 62968913920 | Y35: 78628151296 | Z35: 69971222528 | AA35: 62293467136 | AB35: 61842223104 | AC35: 51992440832 | AD35: 57047818240 | AE35: 52900311040 | AF35: 49715200000 | AG35: 54130814976 | AH35: 50940960768 | AI35: 50284101632 | AJ35: 47873687552 | AK35: 43750924288 | AL35: 45545762816 | AM35: 42193850368 | AN35: 44578361344 | AO35: 42826743808 | AP35: 41226108928 | AQ35: 42778300416 | AR35: 42847125504 | AZ35: BMO CN EQUITY
A36: BNS | B36: 064149107 | C36: =A36&" CN EQUITY" -> BNS CN EQUITY | D36: Bank of Nova Scotia/The | E36: 96107962368 | F36: 91179737088 | G36: 76946628608 | H36: 85636816896 | I36: 78306205696 | J36: 73381396480 | K36: 79415238656 | L36: 81134870528 | M36: 79088025600 | N36: 78270201856 | O36: 91120304128 | P36: 107822759936 | Q36: 108878938112 | R36: 94732427264 | S36: 97839628288 | T36: 95342108672 | U36: 83348447232 | V36: 67016228864 | W36: 68054503424 | X36: 69439946752 | Y36: 89193775104 | Z36: 91836203008 | AA36: 85982740480 | AB36: 85930418176 | AC36: 83500679168 | AD36: 94831009792 | AE36: 91748442112 | AF36: 95073230848 | AG36: 97313292288 | AH36: 96102490112 | AI36: 93761978368 | AJ36: 94080827392 | AK36: 90345447424 | AL36: 83759710208 | AM36: 76162138112 | AN36: 76310020096 | AO36: 67340046336 | AP36: 71038173184 | AQ36: 77994139648 | AR36: 76861440000 | AZ36: BN CN EQUITY
A37: BTE | B37: 07317Q105 | C37: =A37&" CN EQUITY" -> BTE CN EQUITY | D37: Baytex Energy Corp | E37: 2880359168 | F37: 3200988672 | G37: 3844379648 | H37: 4018018304 | I37: 3742175488 | J37: 5107334656 | K37: 3701906944 | L37: 2762795520 | M37: 3318009600 | N37: 3226009856 | O37: 3537859840 | P37: 3074961152 | Q37: 2206073088 | R37: 1946535040 | S37: 1348225152 | T37: 735207872 | U37: 387202208 | V37: 257850816 | W37: 386776224 | X37: 187755264 | Y37: 1043894912 | Z37: 1093524736 | AA37: 1129781888 | AB37: 1261711488 | AC37: 1335236864 | AD37: 2075828864 | AE37: 1033846336 | AF37: 835120704 | AG37: 887649856 | AH37: 880607360 | AI37: 737742912 | AJ37: 1063286528 | AK37: 1531425408 | AL37: 1173681280 | AM37: 1580360704 | AN37: 1080833792 | AO37: 941983808 | AP37: 889422144 | AQ37: 3996853504 | AR37: 3381658880 | AZ37: BNE CN EQUITY
... A58: CRT-U | B58: 126462100 | C58: =A58&" CN EQUITY" -> CRT-U CN EQUITY | D58: CT Real Estate Investment Trus | E58: 3368365568 | F58: 3745509376 | G58: 3106722048 | H58: 3363651328 | I58: 3441017600 | J58: 3215531008 | K58: 3551411968 | L58: 3719106304 | M58: 3617022464 | N58: 3482457088 | O58: 3844391424 | P58: 4101921536 | Q58: 4018398208 | R58: 3951115520 | S58: 3722534912 | T58: 3715717120 | U58: 3561179648 | V58: 3174835968 | W58: 3086204160 | X58: 2658953472 | Y58: 3667992320 | Z58: 3292231936 | AA58: 3114806272 | AB58: 3145472512 | AC58: 2525577728 | AD58: 2435382016 | AE58: 2444858112 | AF58: 2520667904 | AG58: 2748096512 | AH58: 2632486912 | AI58: 2725353472 | AJ58: 2850439424 | AK58: 2842858496 | AL58: 2918667776 | AM58: 2804953600 | AN58: 2738626560 | AO58: 2463810560 | AP58: 2437277184 | AQ58: 2290803200 | AR58: 2401419776 | AZ58: CHP-U CN EQUITY
A59: CS | B59: 14071L108 | C59: =A59&" CN EQUITY" -> CS CN EQUITY | D59: Capstone Copper Corp | E59: 6773049856 | F59: 8036252672 | G59: 7311205888 | H59: 6490013184 | I59: 4480161280 | J59: 4000624640 | K59: 4174262784 | L59: 4224392448 | M59: 3416378368 | N59: 2248458496 | O59: 2241561344 | P59: 2925462016 | Q59: -- | R59: -- | S59: -- | T59: -- | U59: -- | V59: -- | W59: -- | X59: -- | Y59: -- | Z59: -- | AA59: -- | AB59: -- | AC59: -- | AD59: -- | AE59: -- | AF59: -- | AG59: -- | AH59: -- | AI59: -- | AJ59: -- | AK59: -- | AL59: -- | AM59: -- | AN59: -- | AO59: -- | AP59: -- | AQ59: -- | AR59: -- | AZ59: CIGI CN EQUITY
A60: CSH-U | B60: 16141A103 | C60: =A60&" CN EQUITY" -> CSH-U CN EQUITY | D60: Chartwell Retirement Residence | E60: 4102958592 | F60: 4238998272 | G60: 3483450880 | H60: 2867942400 | I60: 2719440640 | J60: 2385311488 | K60: 2197363712 | L60: 1983892224 | M60: 1958368512 | N60: 2155597568 | O60: 2587181056 | P60: 2877223936 | Q60: 2742643968 | R60: 2798332160 | S60: 2788822016 | T60: 2464687104 | U60: 2355238912 | V60: 2125819008 | W60: 1972170624 | X60: 1883770240 | Y60: 2925632000 | Z60: 3098223360 | AA60: 3203461888 | AB60: 3152947200 | AC60: 2877222400 | AD60: 3081385216 | AE60: 3226614272 | AF60: 3293967104 | AG60: 3422358016 | AH60: 2844364032 | AI60: 2956993280 | AJ60: 2976082944 | AK60: 2796639744 | AL60: 3016171264 | AM60: 2746574848 | AN60: 2455719936 | AO60: 2211889664 | AP60: 2140482176 | AQ60: 1999408896 | AR60: 2152673536 | AZ60: CJ CN EQUITY
...
