Workbook

Sheet FINAL
A1: Security | B1: Name | C1: Sector | D1: INDUSTRY | E1: Year | F1: Quarter | G1: Index | H1: Closing Stock Price | I1: SP Volatility | J1: MC RAW | K1: Log MCap | L1: PB RAW | M1: Book to Mkt | N1: ROA | O1: Total Assets | P1: Asset Growth | Q1: ESGCombinedScore | R1: EnvironmentPillarScore | S1: GovernancePillarScore | T1: SocialPillarScore | U1: ESG Momentum | V1: ESG Mom-Env | W1: ESG Mom - Gov | X1: ESG Mom - Social
A2: AAV CN EQUITY | B2: Advantage Energy Ltd | C2: Energy | D2: =VLOOKUP(C2,INDUSTRY!A:B,2,FALSE) -> Natural Resources | E2: 2015 | F2: Q1 | G2: 2015-Q1 | H2: 6.82 | I2: 0.43338782 | J2: 1161495680 | K2: 20.872974 | L2: 0.86407202 | M2: 1.1573109 | N2: 0.97533798 | O2: 1454.767 | P2: 0.088701862 | Q2: 0 | R2: 0 | S2: 0 | T2: 0 | U2: 0 | V2: 0 | W2: 0 | X2: 0
A3: AAV CN EQUITY | B3: Advantage Energy Ltd | C3: Energy | D3: =VLOOKUP(C3,INDUSTRY!A:B,2,FALSE) -> Natural Resources | E3: 2015 | F3: Q2 | G3: 2015-Q2 | H3: 7.9 | I3: 0.11026483 | J3: 1348260224 | K3: 21.022081 | L3: 1.0568269 | M3: 0.94622871 | N3: 6.8927059 | O3: 1508.438 | P3: 0.036893221 | Q3: 0 | R3: 0 | S3: 0 | T3: 0 | U3: 0 | V3: 0 | W3: 0 | X3: 0
A4: AAV CN EQUITY | B4: Advantage Energy Ltd | C4: Energy | D4: =VLOOKUP(C4,INDUSTRY!A:B,2,FALSE) -> Natural Resources | E4: 2015 | F4: Q3 | G4: 2015-Q3 | H4: 6.97 | I4: 1.0395672 | J4: 1189886976 | K4: 20.897124 | L4: 1.226446 | M4: 0.81536405 | N4: 5.0444198 | O4: 1493.8691 | P4: -0.0096583087 | Q4: 0 | R4: 0 | S4: 0 | T4: 0 | U4: 0 | V4: 0 | W4: 0 | X4: 0
A5: AAV CN EQUITY | B5: Advantage Energy Ltd | C5: Energy | D5: =VLOOKUP(C5,INDUSTRY!A:B,2,FALSE) -> Natural Resources | E5: 2015 | F5: Q4 | G5: 2015-Q4 | H5: 7.03 | I5: 1.1470942 | J5: 1200238592 | K5: 20.905786 | L5: 1.0742 | M5: 0.93092531 | N5: 4.388618 | O5: 1518.964 | P5: 0.016798602 | Q5: 0 | R5: 0 | S5: 0 | T5: 0 | U5: 0 | V5: 0 | W5: 0 | X5: 0
A6: AAV CN EQUITY | B6: Advantage Energy Ltd | C6: Energy | D6: =VLOOKUP(C6,INDUSTRY!A:B,2,FALSE) -> Natural Resources | E6: 2016 | F6: Q1 | G6: 2016-Q1 | H6: 7.13 | I6: 0.92477024 | J6: 1314780160 | K6: 20.996935 | L6: 1.070385 | M6: 0.9342433 | N6: 1.438526 | O6: 1517.4429 | P6: -0.0010013562 | Q6: 0 | R6: 0 | S6: 0 | T6: 0 | U6: 0 | V6: 0 | W6: 0 | X6: 0
A7: AAV CN EQUITY | B7: Advantage Energy Ltd | C7: Energy | D7: =VLOOKUP(C7,INDUSTRY!A:B,2,FALSE) -> Natural Resources | E7: 2016 | F7: Q2 | G7: 2016-Q2 | H7: 7.22 | I7: 0.22470351 | J7: 1332163456 | K7: 21.01007 | L7: 1.065817 | M7: 0.93824737 | N7: 2.089612 | O7: 1554.14 | P7: 0.024183504 | Q7: 0 | R7: 0 | S7: 0 | T7: 0 | U7: 0 | V7: 0 | W7: 0 | X7: 0
A8: AAV CN EQUITY | B8: Advantage Energy Ltd | C8: Energy | D8: =VLOOKUP(C8,INDUSTRY!A:B,2,FALSE) -> Natural Resources | E8: 2016 | F8: Q3 | G8: 2016-Q3 | H8: 9.2 | I8: 0.5591884 | J8: 1697906560 | K8: 21.252662 | L8: 1.1047651 | M8: 0.90516983 | N8: 0.286286 | O8: 1505.225 | P8: -0.031474044 | Q8: 0 | R8: 0 | S8: 0 | T8: 0 | U8: 0 | V8: 0 | W8: 0 | X8: 0
A9: AAV CN EQUITY | B9: Advantage Energy Ltd | C9: Energy | D9: =VLOOKUP(C9,INDUSTRY!A:B,2,FALSE) -> Natural Resources | E9: 2016 | F9: Q4 | G9: 2016-Q4 | H9: 9.12 | I9: 1.5932645 | J9: 1683971072 | K9: 21.244421 | L9: 1.397257 | M9: 0.71568797 | N9: 0.36416301 | O9: 1512.0931 | P9: 0.0045628369 | Q9: 0 | R9: 0 | S9: 0 | T9: 0 | U9: 0 | V9: 0 | W9: 0 | X9: 0
A10: AAV CN EQUITY | B10: Advantage Energy Ltd | C10: Energy | D10: =VLOOKUP(C10,INDUSTRY!A:B,2,FALSE) -> Natural Resources | E10: 2017 | F10: Q1 | G10: 2017-Q1 | H10: 8.78 | I10: 2.2606341 | J10: 1623166720 | K10: 21.207645 | L10: 1.393764 | M10: 0.71748157 | N10: -1.044095 | O10: 1496.459 | P10: -0.010339343 | Q10: 0 | R10: 0 | S10: 0 | T10: 0 | U10: 0 | V10: 0 | W10: 0 | X10: 0
A11: AAV CN EQUITY | B11: Advantage Energy Ltd | C11: Energy | D11: =VLOOKUP(C11,INDUSTRY!A:B,2,FALSE) -> Natural Resources | E11: 2017 | F11: Q2 | G11: 2017-Q2 | H11: 8.77 | I11: 1.8253493 | J11: 1623263488 | K11: 21.207704 | L11: 1.297083 | M11: 0.77096067 | N11: 0.76613802 | O11: 1532.51 | P11: 0.024090833 | Q11: 0 | R11: 0 | S11: 0 | T11: 0 | U11: 0 | V11: 0 | W11: 0 | X11: 0
A12: AAV CN EQUITY | B12: Advantage Energy Ltd | C12: Energy | D12: =VLOOKUP(C12,INDUSTRY!A:B,2,FALSE) -> Natural Resources | E12: 2017 | F12: Q3 | G12: 2017-Q3 | H12: 7.82 | I12: 0.807589 | J12: 1454174720 | K12: 21.097704 | L12: 1.281309 | M12: 0.78045186 | N12: 3.9336181 | O12: 1541.7411 | P12: 0.0060235198 | Q12: 0 | R12: 0 | S12: 0 | T12: 0 | U12: 0 | V12: 0 | W12: 0 | X12: 0
A13: AAV CN EQUITY | B13: Advantage Energy Ltd | C13: Energy | D13: =VLOOKUP(C13,INDUSTRY!A:B,2,FALSE) -> Natural Resources | E13: 2017 | F13: Q4 | G13: 2017-Q4 | H13: 5.4 | I13: 0.95325757 | J13: 1004201216 | K13: 20.727458 | L13: 1.128872 | M13: 0.88584 | N13: 4.1560621 | O13: 1604.752 | P13: 0.040869992 | Q13: 0 | R13: 0 | S13: 0 | T13: 0 | U13: 0 | V13: 0 | W13: 0 | X13: 0
... A37: AAV CN EQUITY | B37: Advantage Energy Ltd | C37: Energy | D37: =VLOOKUP(C37,INDUSTRY!A:B,2,FALSE) -> Natural Resources | E37: 2023 | F37: Q4 | G37: 2023-Q4 | H37: 8.53 | I37: 0.38064638 | J37: 1409015808 | K37: 21.066157 | L37: 0.99283201 | M37: 1.0072197 | N37: 7.7911472 | O37: 2283.7189 | P37: 0.023283405 | Q37: 0.38751429 | R37: 0.27132183 | S37: 0.52778796 | T37: 0.40441631 | U37: -0.022841996 | V37: -0.013977347 | W37: -0.036185668 | X37: -0.022650115
A38: AAV CN EQUITY | B38: Advantage Energy Ltd | C38: Energy | D38: =VLOOKUP(C38,INDUSTRY!A:B,2,FALSE) -> Natural Resources | E38: 2024 | F38: Q1 | G38: 2024-Q1 | H38: 9.88 | I38: n/a | J38: 1580187264 | K38: 21.180809 | L38: 0.88915098 | M38: 1.1246684 | N38: 4.4994378 | O38: 2299.028 | P38: 0.0067035641 | Q38: 0.375051 | R38: 0.26750334 | S38: 0.45098611 | T38: 0.42092097 | U38: -0.01246329 | V38: -0.0038184837 | W38: -0.076801851 | X38: 0.01650466
A39: AAV CN EQUITY | B39: Advantage Energy Ltd | C39: Energy | D39: =VLOOKUP(C39,INDUSTRY!A:B,2,FALSE) -> Natural Resources | E39: 2024 | F39: Q2 | G39: 2024-Q2 | H39: 10.38 | I39: n/a | J39: 1733170560 | K39: 21.273218 | L39: 1.014098 | M39: 0.98609794 | N39: 4.1665492 | O39: 2342.176 | P39: 0.018767946 | Q39: 0.375051 | R39: 0.26750334 | S39: 0.45098611 | T39: 0.42092097 | U39: -0.01246329 | V39: -0.0038184837 | W39: -0.076801851 | X39: 0.01650466
A40: AAV CN EQUITY | B40: Advantage Energy Ltd | C40: Energy | D40: =VLOOKUP(C40,INDUSTRY!A:B,2,FALSE) -> Natural Resources | E40: 2024 | F40: Q3 | G40: 2024-Q3 | H40: 9.45 | I40: n/a | J40: 1577886464 | K40: 21.179352 | L40: 1.068455 | M40: 0.93593087 | N40: 3.184761 | O40: 2818.4819 | P40: 0.20336043 | Q40: 0.375051 | R40: 0.26750334 | S40: 0.45098611 | T40: 0.42092097 | U40: -0.01246329 | V40: -0.0038184837 | W40: -0.076801851 | X40: 0.01650466
A41: AAV CN EQUITY | B41: Advantage Energy Ltd | C41: Energy | D41: =VLOOKUP(C41,INDUSTRY!A:B,2,FALSE) -> Natural Resources | E41: 2024 | F41: Q4 | G41: 2024-Q4 | H41: 9.86 | I41: n/a | J41: 1646387712 | K41: 21.221849 | L41: 0.97480702 | M41: 1.0258441 | N41: 1.77763 | O41: 2848.394 | P41: 0.010612828 | Q41: 0.375051 | R41: 0.26750334 | S41: 0.45098611 | T41: 0.42092097 | U41: -0.01246329 | V41: -0.0038184837 | W41: -0.076801851 | X41: 0.01650466
A42: ACQ CN EQUITY | B42: AutoCanada Inc | C42: Consumer Discretionary | D42: =VLOOKUP(C42,INDUSTRY!A:B,2,FALSE) -> Service | E42: 2015 | F42: Q1 | G42: 2015-Q1 | H42: 31.67 | I42: 9.8389579 | J42: 776221696 | K42: 20.469949 | L42: 2.8477969 | M42: 0.35114863 | N42: 5.374836 | O42: 1357.9869 | P42: 0.12088868 | Q42: 0.27490535 | R42: 0 | S42: 0.52746401 | T42: 0.17130996 | U42: 0.10301148 | V42: 0 | W42: 0.23451748 | X42: 0.031011237
A43: ACQ CN EQUITY | B43: AutoCanada Inc | C43: Consumer Discretionary | D43: =VLOOKUP(C43,INDUSTRY!A:B,2,FALSE) -> Service | E43: 2015 | F43: Q2 | G43: 2015-Q2 | H43: 41.3 | I43: 3.2871923 | J43: 1012249920 | K43: 20.735441 | L43: 2.032541 | M43: 0.49199499 | N43: 4.7069578 | O43: 1449.2131 | P43: 0.067177459 | Q43: 0.27490535 | R43: 0 | S43: 0.52746401 | T43: 0.17130996 | U43: 0.10301148 | V43: 0 | W43: 0.23451748 | X43: 0.031011237
A44: ACQ CN EQUITY | B44: AutoCanada Inc | C44: Consumer Discretionary | D44: =VLOOKUP(C44,INDUSTRY!A:B,2,FALSE) -> Service | E44: 2015 | F44: Q3 | G44: 2015-Q3 | H44: 25.86 | I44: 2.484195 | J44: 633820416 | K44: 20.267276 | L44: 2.6015649 | M44: 0.38438403 | N44: 4.3450532 | O44: 1517.978 | P44: 0.04744984 | Q44: 0.27490535 | R44: 0 | S44: 0.52746401 | T44: 0.17130996 | U44: 0.10301148 | V44: 0 | W44: 0.23451748 | X44: 0.031011237
A45: ACQ CN EQUITY | B45: AutoCanada Inc | C45: Consumer Discretionary | D45: =VLOOKUP(C45,INDUSTRY!A:B,2,FALSE) -> Service | E45: 2015 | F45: Q4 | G45: 2015-Q4 | H45: 24.15 | I45: 2.1752701 | J45: 663151360 | K45: 20.312514 | L45: 1.605267 | M45: 0.62294931 | N45: 3.4335761 | O45: 1508.028 | P45: -0.0065547407 | Q45: 0.27490535 | R45: 0 | S45: 0.52746401 | T45: 0.17130996 | U45: 0.10301148 | V45: 0 | W45: 0.23451748 | X45: 0.031011237
A46: ACQ CN EQUITY | B46: AutoCanada Inc | C46: Consumer Discretionary | D46: =VLOOKUP(C46,INDUSTRY!A:B,2,FALSE) -> Service | E46: 2016 | F46: Q1 | G46: 2016-Q1 | H46: 18.22 | I46: 0.45756602 | J46: 500315424 | K46: 20.030749 | L46: 1.463537 | M46: 0.68327621 | N46: 1.736092 | O46: 1532.182 | P46: 0.016016933 | Q46: 0.22123307 | R46: 0 | S46: 0.42600849 | T46: 0.13649007 | U46: -0.053672279 | V46: 0 | W46: -0.10145552 | X46: -0.03481989
A47: ACQ CN EQUITY | B47: AutoCanada Inc | C47: Consumer Discretionary | D47: =VLOOKUP(C47,INDUSTRY!A:B,2,FALSE) -> Service | E47: 2016 | F47: Q2 | G47: 2016-Q2 | H47: 22.15 | I47: 1.7917287 | J47: 608231936 | K47: 20.226067 | L47: 1.108619 | M47: 0.90202317 | N47: 1.809517 | O47: 1578.225 | P47: 0.030050612 | Q47: 0.22123307 | R47: 0 | S47: 0.42600849 | T47: 0.13649007 | U47: -0.053672279 | V47: 0 | W47: -0.10145552 | X47: -0.03481989
A48: ACQ CN EQUITY | B48: AutoCanada Inc | C48: Consumer Discretionary | D48: =VLOOKUP(C48,INDUSTRY!A:B,2,FALSE) -> Service | E48: 2016 | F48: Q3 | G48: 2016-Q3 | H48: 22.15 | I48: 2.0976078 | J48: 608231936 | K48: 20.226067 | L48: 1.3082221 | M48: 0.76439622 | N48: 1.679831 | O48: 1548.879 | P48: -0.018594337 | Q48: 0.22123307 | R48: 0 | S48: 0.42600849 | T48: 0.13649007 | U48: -0.053672279 | V48: 0 | W48: -0.10145552 | X48: -0.03481989
A49: ACQ CN EQUITY | B49: AutoCanada Inc | C49: Consumer Discretionary | D49: =VLOOKUP(C49,INDUSTRY!A:B,2,FALSE) -> Service | E49: 2016 | F49: Q4 | G49: 2016-Q4 | H49: 23.12 | I49: 2.0335089 | J49: 634867904 | K49: 20.268928 | L49: 1.413289 | M49: 0.70756939 | N49: -1.214255 | O49: 1547.344 | P49: -0.00099102385 | Q49: 0.22123307 | R49: 0 | S49: 0.42600849 | T49: 0.13649007 | U49: -0.053672279 | V49: 0 | W49: -0.10145552 | X49: -0.03481989
A50: ACQ CN EQUITY | B50: AutoCanada Inc | C50: Consumer Discretionary | D50: =VLOOKUP(C50,INDUSTRY!A:B,2,FALSE) -> Service | E50: 2017 | F50: Q1 | G50: 2017-Q1 | H50: 22.44 | I50: 2.0212599 | J50: 616195328 | K50: 20.239075 | L50: 1.437192 | M50: 0.69580127 | N50: 0.16573 | O50: 1600.615 | P50: 0.034427406 | Q50: 0.26669986 | R50: 0 | S50: 0.55621735 | T50: 0.12614907 | U50: 0.045466796 | V50: 0 | W50: 0.13020885 | X50: -0.010340998
A51: ACQ CN EQUITY | B51: AutoCanada Inc | C51: Consumer Discretionary | D51: =VLOOKUP(C51,INDUSTRY!A:B,2,FALSE) -> Service | E51: 2017 | F51: Q2 | G51: 2017-Q2 | H51: 19.08 | I51: 3.0177751 | J51: 523930752 | K51: 20.07687 | L51: 0.69552898 | M51: 1.4377546 | N51: -0.060756002 | O51: 1707.063 | P51: 0.066504436 | Q51: 0.26669986 | R51: 0 | S51: 0.55621735 | T51: 0.12614907 | U51: 0.045466796 | V51: 0 | W51: 0.13020885 | X51: -0.010340998
A52: ACQ CN EQUITY | B52: AutoCanada Inc | C52: Consumer Discretionary | D52: =VLOOKUP(C52,INDUSTRY!A:B,2,FALSE) -> Service | E52: 2017 | F52: Q3 | G52: 2017-Q3 | H52: 23.81 | I52: 4.3392242 | J52: 653815040 | K52: 20.298335 | L52: 1.126552 | M52: 0.88766432 | N52: 0.604958 | O52: 1698.29 | P52: -0.0051392314 | Q52: 0.26669986 | R52: 0 | S52: 0.55621735 | T52: 0.12614907 | U52: 0.045466796 | V52: 0 | W52: 0.13020885 | X52: -0.010340998
A53: ACQ CN EQUITY | B53: AutoCanada Inc | C53: Consumer Discretionary | D53: =VLOOKUP(C53,INDUSTRY!A:B,2,FALSE) -> Service | E53: 2017 | F53: Q4 | G53: 2017-Q4 | H53: 22.64 | I53: 4.732296 | J53: 621687232 | K53: 20.247948 | L53: 1.375158 | M53: 0.72718919 | N53: 3.3658171 | O53: 1693.5331 | P53: -0.002801048 | Q53: 0.26669986 | R53: 0 | S53: 0.55621735 | T53: 0.12614907 | U53: 0.045466796 | V53: 0 | W53: 0.13020885 | X53: -0.010340998
... A77: ACQ CN EQUITY | B77: AutoCanada Inc | C77: Consumer Discretionary | D77: =VLOOKUP(C77,INDUSTRY!A:B,2,FALSE) -> Service | E77: 2023 | F77: Q4 | G77: 2023-Q4 | H77: 22.9 | I77: 4.8404227 | J77: 540695936 | K77: 20.108368 | L77: 1.061255 | M77: 0.94228062 | N77: 2.89101 | O77: 3065.3381 | P77: 0.05421292 | Q77: 0.45576793 | R77: 0.084677419 | S77: 0.52546742 | T77: 0.56002912 | U77: 0.18854959 | V77: -0.0099727864 | W77: 0.1320738 | X77: 0.32871288
A78: ACQ CN EQUITY | B78: AutoCanada Inc | C78: Consumer Discretionary | D78: =VLOOKUP(C78,INDUSTRY!A:B,2,FALSE) -> Service | E78: 2024 | F78: Q1 | G78: 2024-Q1 | H78: 26.88 | I78: n/a | J78: 634668416 | K78: 20.268613 | L78: 0.58389503 | M78: 1.7126366 | N78: 1.67803 | O78: 3159.4391 | P78: 0.030698405 | Q78: 0.46061779 | R78: 0.07312253 | S78: 0.58279167 | T78: 0.52503417 | U78: 0.0048498607 | V78: -0.01155489 | W78: 0.057324245 | X78: -0.034994947
A79: ACQ CN EQUITY | B79: AutoCanada Inc | C79: Consumer Discretionary | D79: =VLOOKUP(C79,INDUSTRY!A:B,2,FALSE) -> Service | E79: 2024 | F79: Q2 | G79: 2024-Q2 | H79: 19.23 | I79: n/a | J79: 448930752 | K79: 19.922379 | L79: 1.182011 | M79: 0.84601581 | N79: 1.325309 | O79: 3173.0921 | P79: 0.0043213341 | Q79: 0.46061779 | R79: 0.07312253 | S79: 0.58279167 | T79: 0.52503417 | U79: 0.0048498607 | V79: -0.01155489 | W79: 0.057324245 | X79: -0.034994947
A80: ACQ CN EQUITY | B80: AutoCanada Inc | C80: Consumer Discretionary | D80: =VLOOKUP(C80,INDUSTRY!A:B,2,FALSE) -> Service | E80: 2024 | F80: Q3 | G80: 2024-Q3 | H80: 16.09 | I80: n/a | J80: 372487264 | K80: 19.735713 | L80: 0.90373999 | M80: 1.1065129 | N80: -1.197926 | O80: 3197.515 | P80: 0.0076968809 | Q80: 0.46061779 | R80: 0.07312253 | S80: 0.58279167 | T80: 0.52503417 | U80: 0.0048498607 | V80: -0.01155489 | W80: 0.057324245 | X80: -0.034994947
A81: ACQ CN EQUITY | B81: AutoCanada Inc | C81: Consumer Discretionary | D81: =VLOOKUP(C81,INDUSTRY!A:B,2,FALSE) -> Service | E81: 2024 | F81: Q4 | G81: 2024-Q4 | H81: 17.33 | I81: n/a | J81: 401193536 | K81: 19.809955 | L81: 0.76310599 | M81: 1.310434 | N81: -1.635744 | O81: 3105.922 | P81: -0.028645045 | Q81: 0.46061779 | R81: 0.07312253 | S81: 0.58279167 | T81: 0.52503417 | U81: 0.0048498607 | V81: -0.01155489 | W81: 0.057324245 | X81: -0.034994947
A82: ADEN CN EQUITY | B82: ADENTRA Inc | C82: Industrials | D82: =VLOOKUP(C82,INDUSTRY!A:B,2,FALSE) -> Manufacturing | E82: 2015 | F82: Q1 | G82: 2015-Q1 | H82: 12.88 | I82: 0.9954689 | J82: 214470224 | K82: 19.183681 | L82: 1.768145 | M82: 0.56556449 | N82: 9.6963778 | O82: 138.45286 | P82: -0.048764052 | Q82: 0 | R82: 0 | S82: 0 | T82: 0 | U82: 0 | V82: 0 | W82: 0 | X82: 0
A83: ADEN CN EQUITY | B83: ADENTRA Inc | C83: Industrials | D83: =VLOOKUP(C83,INDUSTRY!A:B,2,FALSE) -> Manufacturing | E83: 2015 | F83: Q2 | G83: 2015-Q2 | H83: 16.84 | I83: 1.2664221 | J83: 280409824 | K83: 19.451763 | L83: 1.790699 | M83: 0.55844114 | N83: 9.5147266 | O83: 147.03581 | P83: 0.061991813 | Q83: 0 | R83: 0 | S83: 0 | T83: 0 | U83: 0 | V83: 0 | W83: 0 | X83: 0
A84: ADEN CN EQUITY | B84: ADENTRA Inc | C84: Industrials | D84: =VLOOKUP(C84,INDUSTRY!A:B,2,FALSE) -> Manufacturing | E84: 2015 | F84: Q3 | G84: 2015-Q3 | H84: 15.95 | I84: 1.3131641 | J84: 265590064 | K84: 19.397465 | L84: 2.2789409 | M84: 0.43880032 | N84: 9.6708918 | O84: 151.8353 | P84: 0.032641627 | Q84: 0 | R84: 0 | S84: 0 | T84: 0 | U84: 0 | V84: 0 | W84: 0 | X84: 0
A85: ADEN CN EQUITY | B85: ADENTRA Inc | C85: Industrials | D85: =VLOOKUP(C85,INDUSTRY!A:B,2,FALSE) -> Manufacturing | E85: 2015 | F85: Q4 | G85: 2015-Q4 | H85: 17.98 | I85: 1.305 | J85: 299392448 | K85: 19.517266 | L85: 1.969663 | M85: 0.50770106 | N85: 10.219131 | O85: 148.37738 | P85: -0.022774151 | Q85: 0 | R85: 0 | S85: 0 | T85: 0 | U85: 0 | V85: 0 | W85: 0 | X85: 0
A86: ADEN CN EQUITY | B86: ADENTRA Inc | C86: Industrials | D86: =VLOOKUP(C86,INDUSTRY!A:B,2,FALSE) -> Manufacturing | E86: 2016 | F86: Q1 | G86: 2016-Q1 | H86: 18.02 | I86: 1.3790667 | J86: 302052544 | K86: 19.526112 | L86: 2.1083331 | M86: 0.47430835 | N86: 11.48519 | O86: 137.40526 | P86: -0.073947338 | Q86: 0 | R86: 0 | S86: 0 | T86: 0 | U86: 0 | V86: 0 | W86: 0 | X86: 0
...

Sheet INDUSTRY
A1: Sector | B1: Canadian Industry
A2: Energy | B2: Natural Resources
A3: Materials | B3: Natural Resources
A4: Industrials | B4: Manufacturing
A5: Utilities | B5: Service
A6: Real Estate | B6: Service
A7: Consumer Staples | B7: Manufacturing
A8: Information Technology | B8: Service
A9: Communication Services | B9: Service
A10: Health Care | B10: Service
A11: Financials | B11: Service
A12: Consumer Discretionary | B12: Service
