Workbook

Sheet Sheet3
A2: things to fix
A3: - | B3: price to book --> those highlighted in red are missing values
A4: - | B4: pull total assets for all companies
A5: - | B5: pull the ibsn numbers or whatever for each company for easier extraction of ESG scores
A6: - | B6: need to get all numbers (minus stock prices) for companies that didn’t start on mar 31 2015
A7: - | B7: roa - those in red are missing values
L8: AAV CN EQUITY
L9: ACQ CN EQUITY
L10: ADEN CN EQUITY
L11: ADN CN EQUITY
L12: ADW/A CN EQUITY
L13: AGF/B CN EQUITY
L14: AI CN EQUITY
L15: AIF CN EQUITY
L16: AIM CN EQUITY
L17: ALS CN EQUITY
L18: AND CN EQUITY
L19: APR-U CN EQUITY
... L247: WRN CN EQUITY

Sheet COMBINED DATA
A1: Security | C1: Name | D1: Sector | E1: Year | F1: Quarter | G1: Index | H1: Closing Stock Price | I1: SP Volatility | J1: MC RAW (million's) | K1: Log MCap | L1: PB RAW | M1: Book to Mkt | N1: ROA | O1: Total Assets (mil) | P1: Asset Growth | Q1: ESGScore | R1: ESG Momentum | S1: EnvironmentPillarScore | T1: GovernancePillarScore | U1: SocialPillarScore
A2: AAV CN Equity | B2: =VLOOKUP(A2,Sheet3!L:L,1,FALSE) -> AAV CN EQUITY | C2: =VLOOKUP(A2,'ALL - prices'!B:C,2,FALSE) -> Advantage Energy Ltd | D2: =VLOOKUP(A2,'ALL - prices'!B:I,8,FALSE) -> Energy | E2: 2015 | F2: Q1 | G2: =E2&"-"&F2 -> 2015-Q1 | H2: =INDEX('ALL - prices'!$J$3:$DY$219,MATCH('COMBINED DATA'!A2,'ALL - prices'!$B$3:$B$219,0),MATCH('COMBINED DATA'!G2,'ALL - prices'!$J$1:$DY$1,0)) -> 6.82 | I2: =STDEV(H3:H6) -> 0.43338782 | J2: =INDEX('market cap'!$B$3:$DQ$219,MATCH(A2,'market cap'!$A$3:$A$219,0),MATCH(G2,'market cap'!$B$1:$DQ$1,0)) -> 1161.4957 | K2: =LN(J2) -> 7.0574639 | L2: =INDEX('PB2'!$D$2:$AQ$224,MATCH(A2,'PB2'!$B$2:$B$224,0),MATCH(G2,'PB2'!$D$1:$AQ$1,0)) -> 1.0568269 | M2: =1/L2 -> 0.94622871 | N2: =INDEX('ROA2'!$D$2:$AQ$224,MATCH(A2,'ROA2'!$B$2:$B$224,0),MATCH(G2,'ROA2'!$D$1:$AQ$1,0)) -> 0.97533798 | O2: 1454.767 | P2: 0.088701862
A3: AAV CN Equity | B3: =VLOOKUP(A3,Sheet3!L:L,1,FALSE) -> AAV CN EQUITY | C3: =VLOOKUP(A3,'ALL - prices'!B:C,2,FALSE) -> Advantage Energy Ltd | D3: =VLOOKUP(A3,'ALL - prices'!B:I,8,FALSE) -> Energy | E3: 2015 | F3: Q2 | G3: =E3&"-"&F3 -> 2015-Q2 | H3: =INDEX('ALL - prices'!$J$3:$DY$219,MATCH('COMBINED DATA'!A3,'ALL - prices'!$B$3:$B$219,0),MATCH('COMBINED DATA'!G3,'ALL - prices'!$J$1:$DY$1,0)) -> 7.9 | I3: =STDEV(H4:H7) -> 0.11026483 | J3: =INDEX('market cap'!$B$3:$DQ$219,MATCH(A3,'market cap'!$A$3:$A$219,0),MATCH(G3,'market cap'!$B$1:$DQ$1,0)) -> 1348.2602 | K3: =LN(J3) -> 7.2065703 | L3: =INDEX('PB2'!$D$2:$AQ$224,MATCH(A3,'PB2'!$B$2:$B$224,0),MATCH(G3,'PB2'!$D$1:$AQ$1,0)) -> 1.226446 | M3: =1/L3 -> 0.81536405 | N3: =INDEX('ROA2'!$D$2:$AQ$224,MATCH(A3,'ROA2'!$B$2:$B$224,0),MATCH(G3,'ROA2'!$D$1:$AQ$1,0)) -> 6.8927059 | O3: 1508.438 | P3: 0.036893221
A4: AAV CN Equity | B4: =VLOOKUP(A4,Sheet3!L:L,1,FALSE) -> AAV CN EQUITY | C4: =VLOOKUP(A4,'ALL - prices'!B:C,2,FALSE) -> Advantage Energy Ltd | D4: =VLOOKUP(A4,'ALL - prices'!B:I,8,FALSE) -> Energy | E4: 2015 | F4: Q3 | G4: =E4&"-"&F4 -> 2015-Q3 | H4: =INDEX('ALL - prices'!$J$3:$DY$219,MATCH('COMBINED DATA'!A4,'ALL - prices'!$B$3:$B$219,0),MATCH('COMBINED DATA'!G4,'ALL - prices'!$J$1:$DY$1,0)) -> 6.97 | I4: =STDEV(H5:H8) -> 1.0395672 | J4: =INDEX('market cap'!$B$3:$DQ$219,MATCH(A4,'market cap'!$A$3:$A$219,0),MATCH(G4,'market cap'!$B$1:$DQ$1,0)) -> 1189.8869 | K4: =LN(J4) -> 7.0816135 | L4: =INDEX('PB2'!$D$2:$AQ$224,MATCH(A4,'PB2'!$B$2:$B$224,0),MATCH(G4,'PB2'!$D$1:$AQ$1,0)) -> 1.0742 | M4: =1/L4 -> 0.93092531 | N4: =INDEX('ROA2'!$D$2:$AQ$224,MATCH(A4,'ROA2'!$B$2:$B$224,0),MATCH(G4,'ROA2'!$D$1:$AQ$1,0)) -> 5.0444198 | O4: 1493.8691 | P4: -0.0096583087
A5: AAV CN Equity | B5: =VLOOKUP(A5,Sheet3!L:L,1,FALSE) -> AAV CN EQUITY | C5: =VLOOKUP(A5,'ALL - prices'!B:C,2,FALSE) -> Advantage Energy Ltd | D5: =VLOOKUP(A5,'ALL - prices'!B:I,8,FALSE) -> Energy | E5: 2015 | F5: Q4 | G5: =E5&"-"&F5 -> 2015-Q4 | H5: =INDEX('ALL - prices'!$J$3:$DY$219,MATCH('COMBINED DATA'!A5,'ALL - prices'!$B$3:$B$219,0),MATCH('COMBINED DATA'!G5,'ALL - prices'!$J$1:$DY$1,0)) -> 7.03 | I5: =STDEV(H6:H9) -> 1.1470942 | J5: =INDEX('market cap'!$B$3:$DQ$219,MATCH(A5,'market cap'!$A$3:$A$219,0),MATCH(G5,'market cap'!$B$1:$DQ$1,0)) -> 1200.2386 | K5: =LN(J5) -> 7.0902756 | L5: =INDEX('PB2'!$D$2:$AQ$224,MATCH(A5,'PB2'!$B$2:$B$224,0),MATCH(G5,'PB2'!$D$1:$AQ$1,0)) -> 1.070385 | M5: =1/L5 -> 0.9342433 | N5: =INDEX('ROA2'!$D$2:$AQ$224,MATCH(A5,'ROA2'!$B$2:$B$224,0),MATCH(G5,'ROA2'!$D$1:$AQ$1,0)) -> 4.388618 | O5: 1518.964 | P5: 0.016798602
A6: AAV CN Equity | B6: =VLOOKUP(A6,Sheet3!L:L,1,FALSE) -> AAV CN EQUITY | C6: =VLOOKUP(A6,'ALL - prices'!B:C,2,FALSE) -> Advantage Energy Ltd | D6: =VLOOKUP(A6,'ALL - prices'!B:I,8,FALSE) -> Energy | E6: 2016 | F6: Q1 | G6: =E6&"-"&F6 -> 2016-Q1 | H6: =INDEX('ALL - prices'!$J$3:$DY$219,MATCH('COMBINED DATA'!A6,'ALL - prices'!$B$3:$B$219,0),MATCH('COMBINED DATA'!G6,'ALL - prices'!$J$1:$DY$1,0)) -> 7.13 | I6: =STDEV(H7:H10) -> 0.92477024 | J6: =INDEX('market cap'!$B$3:$DQ$219,MATCH(A6,'market cap'!$A$3:$A$219,0),MATCH(G6,'market cap'!$B$1:$DQ$1,0)) -> 1314.7801 | K6: =LN(J6) -> 7.1814247 | L6: =INDEX('PB2'!$D$2:$AQ$224,MATCH(A6,'PB2'!$B$2:$B$224,0),MATCH(G6,'PB2'!$D$1:$AQ$1,0)) -> 1.065817 | M6: =1/L6 -> 0.93824737 | N6: =INDEX('ROA2'!$D$2:$AQ$224,MATCH(A6,'ROA2'!$B$2:$B$224,0),MATCH(G6,'ROA2'!$D$1:$AQ$1,0)) -> 1.438526 | O6: 1517.4429 | P6: -0.0010013562
A7: AAV CN Equity | B7: =VLOOKUP(A7,Sheet3!L:L,1,FALSE) -> AAV CN EQUITY | C7: =VLOOKUP(A7,'ALL - prices'!B:C,2,FALSE) -> Advantage Energy Ltd | D7: =VLOOKUP(A7,'ALL - prices'!B:I,8,FALSE) -> Energy | E7: 2016 | F7: Q2 | G7: =E7&"-"&F7 -> 2016-Q2 | H7: =INDEX('ALL - prices'!$J$3:$DY$219,MATCH('COMBINED DATA'!A7,'ALL - prices'!$B$3:$B$219,0),MATCH('COMBINED DATA'!G7,'ALL - prices'!$J$1:$DY$1,0)) -> 7.22 | I7: =STDEV(H8:H11) -> 0.22470351 | J7: =INDEX('market cap'!$B$3:$DQ$219,MATCH(A7,'market cap'!$A$3:$A$219,0),MATCH(G7,'market cap'!$B$1:$DQ$1,0)) -> 1332.1635 | K7: =LN(J7) -> 7.1945596 | L7: =INDEX('PB2'!$D$2:$AQ$224,MATCH(A7,'PB2'!$B$2:$B$224,0),MATCH(G7,'PB2'!$D$1:$AQ$1,0)) -> 1.1047651 | M7: =1/L7 -> 0.90516983 | N7: =INDEX('ROA2'!$D$2:$AQ$224,MATCH(A7,'ROA2'!$B$2:$B$224,0),MATCH(G7,'ROA2'!$D$1:$AQ$1,0)) -> 2.089612 | O7: 1554.14 | P7: 0.024183504
A8: AAV CN Equity | B8: =VLOOKUP(A8,Sheet3!L:L,1,FALSE) -> AAV CN EQUITY | C8: =VLOOKUP(A8,'ALL - prices'!B:C,2,FALSE) -> Advantage Energy Ltd | D8: =VLOOKUP(A8,'ALL - prices'!B:I,8,FALSE) -> Energy | E8: 2016 | F8: Q3 | G8: =E8&"-"&F8 -> 2016-Q3 | H8: =INDEX('ALL - prices'!$J$3:$DY$219,MATCH('COMBINED DATA'!A8,'ALL - prices'!$B$3:$B$219,0),MATCH('COMBINED DATA'!G8,'ALL - prices'!$J$1:$DY$1,0)) -> 9.2 | I8: =STDEV(H9:H12) -> 0.5591884 | J8: =INDEX('market cap'!$B$3:$DQ$219,MATCH(A8,'market cap'!$A$3:$A$219,0),MATCH(G8,'market cap'!$B$1:$DQ$1,0)) -> 1697.9066 | K8: =LN(J8) -> 7.4371514 | L8: =INDEX('PB2'!$D$2:$AQ$224,MATCH(A8,'PB2'!$B$2:$B$224,0),MATCH(G8,'PB2'!$D$1:$AQ$1,0)) -> 1.397257 | M8: =1/L8 -> 0.71568797 | N8: =INDEX('ROA2'!$D$2:$AQ$224,MATCH(A8,'ROA2'!$B$2:$B$224,0),MATCH(G8,'ROA2'!$D$1:$AQ$1,0)) -> 0.286286 | O8: 1505.225 | P8: -0.031474044
A9: AAV CN Equity | B9: =VLOOKUP(A9,Sheet3!L:L,1,FALSE) -> AAV CN EQUITY | C9: =VLOOKUP(A9,'ALL - prices'!B:C,2,FALSE) -> Advantage Energy Ltd | D9: =VLOOKUP(A9,'ALL - prices'!B:I,8,FALSE) -> Energy | E9: 2016 | F9: Q4 | G9: =E9&"-"&F9 -> 2016-Q4 | H9: =INDEX('ALL - prices'!$J$3:$DY$219,MATCH('COMBINED DATA'!A9,'ALL - prices'!$B$3:$B$219,0),MATCH('COMBINED DATA'!G9,'ALL - prices'!$J$1:$DY$1,0)) -> 9.12 | I9: =STDEV(H10:H13) -> 1.5932645 | J9: =INDEX('market cap'!$B$3:$DQ$219,MATCH(A9,'market cap'!$A$3:$A$219,0),MATCH(G9,'market cap'!$B$1:$DQ$1,0)) -> 1683.9711 | K9: =LN(J9) -> 7.42891 | L9: =INDEX('PB2'!$D$2:$AQ$224,MATCH(A9,'PB2'!$B$2:$B$224,0),MATCH(G9,'PB2'!$D$1:$AQ$1,0)) -> 1.393764 | M9: =1/L9 -> 0.71748157 | N9: =INDEX('ROA2'!$D$2:$AQ$224,MATCH(A9,'ROA2'!$B$2:$B$224,0),MATCH(G9,'ROA2'!$D$1:$AQ$1,0)) -> 0.36416301 | O9: 1512.0931 | P9: 0.0045628369
A10: AAV CN Equity | B10: =VLOOKUP(A10,Sheet3!L:L,1,FALSE) -> AAV CN EQUITY | C10: =VLOOKUP(A10,'ALL - prices'!B:C,2,FALSE) -> Advantage Energy Ltd | D10: =VLOOKUP(A10,'ALL - prices'!B:I,8,FALSE) -> Energy | E10: 2017 | F10: Q1 | G10: =E10&"-"&F10 -> 2017-Q1 | H10: =INDEX('ALL - prices'!$J$3:$DY$219,MATCH('COMBINED DATA'!A10,'ALL - prices'!$B$3:$B$219,0),MATCH('COMBINED DATA'!G10,'ALL - prices'!$J$1:$DY$1,0)) -> 8.78 | I10: =STDEV(H11:H14) -> 2.2606341 | J10: =INDEX('market cap'!$B$3:$DQ$219,MATCH(A10,'market cap'!$A$3:$A$219,0),MATCH(G10,'market cap'!$B$1:$DQ$1,0)) -> 1623.1667 | K10: =LN(J10) -> 7.3921343 | L10: =INDEX('PB2'!$D$2:$AQ$224,MATCH(A10,'PB2'!$B$2:$B$224,0),MATCH(G10,'PB2'!$D$1:$AQ$1,0)) -> 1.297083 | M10: =1/L10 -> 0.77096067 | N10: =INDEX('ROA2'!$D$2:$AQ$224,MATCH(A10,'ROA2'!$B$2:$B$224,0),MATCH(G10,'ROA2'!$D$1:$AQ$1,0)) -> -1.044095 | O10: 1496.459 | P10: -0.010339343
A11: AAV CN Equity | B11: =VLOOKUP(A11,Sheet3!L:L,1,FALSE) -> AAV CN EQUITY | C11: =VLOOKUP(A11,'ALL - prices'!B:C,2,FALSE) -> Advantage Energy Ltd | D11: =VLOOKUP(A11,'ALL - prices'!B:I,8,FALSE) -> Energy | E11: 2017 | F11: Q2 | G11: =E11&"-"&F11 -> 2017-Q2 | H11: =INDEX('ALL - prices'!$J$3:$DY$219,MATCH('COMBINED DATA'!A11,'ALL - prices'!$B$3:$B$219,0),MATCH('COMBINED DATA'!G11,'ALL - prices'!$J$1:$DY$1,0)) -> 8.77 | I11: =STDEV(H12:H15) -> 1.8253493 | J11: =INDEX('market cap'!$B$3:$DQ$219,MATCH(A11,'market cap'!$A$3:$A$219,0),MATCH(G11,'market cap'!$B$1:$DQ$1,0)) -> 1623.2635 | K11: =LN(J11) -> 7.3921939 | L11: =INDEX('PB2'!$D$2:$AQ$224,MATCH(A11,'PB2'!$B$2:$B$224,0),MATCH(G11,'PB2'!$D$1:$AQ$1,0)) -> 1.281309 | M11: =1/L11 -> 0.78045186 | N11: =INDEX('ROA2'!$D$2:$AQ$224,MATCH(A11,'ROA2'!$B$2:$B$224,0),MATCH(G11,'ROA2'!$D$1:$AQ$1,0)) -> 0.76613802 | O11: 1532.51 | P11: 0.024090833
A12: AAV CN Equity | B12: =VLOOKUP(A12,Sheet3!L:L,1,FALSE) -> AAV CN EQUITY | C12: =VLOOKUP(A12,'ALL - prices'!B:C,2,FALSE) -> Advantage Energy Ltd | D12: =VLOOKUP(A12,'ALL - prices'!B:I,8,FALSE) -> Energy | E12: 2017 | F12: Q3 | G12: =E12&"-"&F12 -> 2017-Q3 | H12: =INDEX('ALL - prices'!$J$3:$DY$219,MATCH('COMBINED DATA'!A12,'ALL - prices'!$B$3:$B$219,0),MATCH('COMBINED DATA'!G12,'ALL - prices'!$J$1:$DY$1,0)) -> 7.82 | I12: =STDEV(H13:H16) -> 0.807589 | J12: =INDEX('market cap'!$B$3:$DQ$219,MATCH(A12,'market cap'!$A$3:$A$219,0),MATCH(G12,'market cap'!$B$1:$DQ$1,0)) -> 1454.1747 | K12: =LN(J12) -> 7.2821938 | L12: =INDEX('PB2'!$D$2:$AQ$224,MATCH(A12,'PB2'!$B$2:$B$224,0),MATCH(G12,'PB2'!$D$1:$AQ$1,0)) -> 1.128872 | M12: =1/L12 -> 0.88584 | N12: =INDEX('ROA2'!$D$2:$AQ$224,MATCH(A12,'ROA2'!$B$2:$B$224,0),MATCH(G12,'ROA2'!$D$1:$AQ$1,0)) -> 3.9336181 | O12: 1541.7411 | P12: 0.0060235198
A13: AAV CN Equity | B13: =VLOOKUP(A13,Sheet3!L:L,1,FALSE) -> AAV CN EQUITY | C13: =VLOOKUP(A13,'ALL - prices'!B:C,2,FALSE) -> Advantage Energy Ltd | D13: =VLOOKUP(A13,'ALL - prices'!B:I,8,FALSE) -> Energy | E13: 2017 | F13: Q4 | G13: =E13&"-"&F13 -> 2017-Q4 | H13: =INDEX('ALL - prices'!$J$3:$DY$219,MATCH('COMBINED DATA'!A13,'ALL - prices'!$B$3:$B$219,0),MATCH('COMBINED DATA'!G13,'ALL - prices'!$J$1:$DY$1,0)) -> 5.4 | I13: =STDEV(H14:H17) -> 0.95325757 | J13: =INDEX('market cap'!$B$3:$DQ$219,MATCH(A13,'market cap'!$A$3:$A$219,0),MATCH(G13,'market cap'!$B$1:$DQ$1,0)) -> 1004.2012 | K13: =LN(J13) -> 6.9119477 | L13: =INDEX('PB2'!$D$2:$AQ$224,MATCH(A13,'PB2'!$B$2:$B$224,0),MATCH(G13,'PB2'!$D$1:$AQ$1,0)) -> 0.76558602 | M13: =1/L13 -> 1.306189 | N13: =INDEX('ROA2'!$D$2:$AQ$224,MATCH(A13,'ROA2'!$B$2:$B$224,0),MATCH(G13,'ROA2'!$D$1:$AQ$1,0)) -> 4.1560621 | O13: 1604.752 | P13: 0.040869992
... A37: AAV CN Equity | B37: =VLOOKUP(A37,Sheet3!L:L,1,FALSE) -> AAV CN EQUITY | C37: =VLOOKUP(A37,'ALL - prices'!B:C,2,FALSE) -> Advantage Energy Ltd | D37: =VLOOKUP(A37,'ALL - prices'!B:I,8,FALSE) -> Energy | E37: 2023 | F37: Q4 | G37: =E37&"-"&F37 -> 2023-Q4 | H37: =INDEX('ALL - prices'!$J$3:$DY$219,MATCH('COMBINED DATA'!A37,'ALL - prices'!$B$3:$B$219,0),MATCH('COMBINED DATA'!G37,'ALL - prices'!$J$1:$DY$1,0)) -> 8.53 | I37: =STDEV(H38:H41) -> 0.38064638 | J37: =INDEX('market cap'!$B$3:$DQ$219,MATCH(A37,'market cap'!$A$3:$A$219,0),MATCH(G37,'market cap'!$B$1:$DQ$1,0)) -> 1409.0158 | K37: =LN(J37) -> 7.2506467 | L37: =INDEX('PB2'!$D$2:$AQ$224,MATCH(A37,'PB2'!$B$2:$B$224,0),MATCH(G37,'PB2'!$D$1:$AQ$1,0)) -> 0.88915098 | M37: =1/L37 -> 1.1246684 | N37: =INDEX('ROA2'!$D$2:$AQ$224,MATCH(A37,'ROA2'!$B$2:$B$224,0),MATCH(G37,'ROA2'!$D$1:$AQ$1,0)) -> 7.7911472 | O37: 2283.7189 | P37: 0.023283405
A38: AAV CN Equity | B38: =VLOOKUP(A38,Sheet3!L:L,1,FALSE) -> AAV CN EQUITY | C38: =VLOOKUP(A38,'ALL - prices'!B:C,2,FALSE) -> Advantage Energy Ltd | D38: =VLOOKUP(A38,'ALL - prices'!B:I,8,FALSE) -> Energy | E38: 2024 | F38: Q1 | G38: =E38&"-"&F38 -> 2024-Q1 | H38: =INDEX('ALL - prices'!$J$3:$DY$219,MATCH('COMBINED DATA'!A38,'ALL - prices'!$B$3:$B$219,0),MATCH('COMBINED DATA'!G38,'ALL - prices'!$J$1:$DY$1,0)) -> 9.88 | I38: N/A | J38: =INDEX('market cap'!$B$3:$DQ$219,MATCH(A38,'market cap'!$A$3:$A$219,0),MATCH(G38,'market cap'!$B$1:$DQ$1,0)) -> 1580.1872 | K38: =LN(J38) -> 7.3652986 | L38: =INDEX('PB2'!$D$2:$AQ$224,MATCH(A38,'PB2'!$B$2:$B$224,0),MATCH(G38,'PB2'!$D$1:$AQ$1,0)) -> 1.014098 | M38: =1/L38 -> 0.98609794 | N38: =INDEX('ROA2'!$D$2:$AQ$224,MATCH(A38,'ROA2'!$B$2:$B$224,0),MATCH(G38,'ROA2'!$D$1:$AQ$1,0)) -> 4.4994378 | O38: 2299.028 | P38: 0.0067035641
A39: AAV CN Equity | B39: =VLOOKUP(A39,Sheet3!L:L,1,FALSE) -> AAV CN EQUITY | C39: =VLOOKUP(A39,'ALL - prices'!B:C,2,FALSE) -> Advantage Energy Ltd | D39: =VLOOKUP(A39,'ALL - prices'!B:I,8,FALSE) -> Energy | E39: 2024 | F39: Q2 | G39: =E39&"-"&F39 -> 2024-Q2 | H39: =INDEX('ALL - prices'!$J$3:$DY$219,MATCH('COMBINED DATA'!A39,'ALL - prices'!$B$3:$B$219,0),MATCH('COMBINED DATA'!G39,'ALL - prices'!$J$1:$DY$1,0)) -> 10.38 | I39: N/A | J39: =INDEX('market cap'!$B$3:$DQ$219,MATCH(A39,'market cap'!$A$3:$A$219,0),MATCH(G39,'market cap'!$B$1:$DQ$1,0)) -> 1733.1706 | K39: =LN(J39) -> 7.4577077 | L39: =INDEX('PB2'!$D$2:$AQ$224,MATCH(A39,'PB2'!$B$2:$B$224,0),MATCH(G39,'PB2'!$D$1:$AQ$1,0)) -> 1.068455 | M39: =1/L39 -> 0.93593087 | N39: =INDEX('ROA2'!$D$2:$AQ$224,MATCH(A39,'ROA2'!$B$2:$B$224,0),MATCH(G39,'ROA2'!$D$1:$AQ$1,0)) -> 4.1665492 | O39: 2342.176 | P39: 0.018767946
A40: AAV CN Equity | B40: =VLOOKUP(A40,Sheet3!L:L,1,FALSE) -> AAV CN EQUITY | C40: =VLOOKUP(A40,'ALL - prices'!B:C,2,FALSE) -> Advantage Energy Ltd | D40: =VLOOKUP(A40,'ALL - prices'!B:I,8,FALSE) -> Energy | E40: 2024 | F40: Q3 | G40: =E40&"-"&F40 -> 2024-Q3 | H40: =INDEX('ALL - prices'!$J$3:$DY$219,MATCH('COMBINED DATA'!A40,'ALL - prices'!$B$3:$B$219,0),MATCH('COMBINED DATA'!G40,'ALL - prices'!$J$1:$DY$1,0)) -> 9.45 | I40: N/A | J40: =INDEX('market cap'!$B$3:$DQ$219,MATCH(A40,'market cap'!$A$3:$A$219,0),MATCH(G40,'market cap'!$B$1:$DQ$1,0)) -> 1577.8865 | K40: =LN(J40) -> 7.3638416 | L40: =INDEX('PB2'!$D$2:$AQ$224,MATCH(A40,'PB2'!$B$2:$B$224,0),MATCH(G40,'PB2'!$D$1:$AQ$1,0)) -> 0.97480702 | M40: =1/L40 -> 1.0258441 | N40: =INDEX('ROA2'!$D$2:$AQ$224,MATCH(A40,'ROA2'!$B$2:$B$224,0),MATCH(G40,'ROA2'!$D$1:$AQ$1,0)) -> 3.184761 | O40: 2818.4819 | P40: 0.20336043
A41: AAV CN Equity | B41: =VLOOKUP(A41,Sheet3!L:L,1,FALSE) -> AAV CN EQUITY | C41: =VLOOKUP(A41,'ALL - prices'!B:C,2,FALSE) -> Advantage Energy Ltd | D41: =VLOOKUP(A41,'ALL - prices'!B:I,8,FALSE) -> Energy | E41: 2024 | F41: Q4 | G41: =E41&"-"&F41 -> 2024-Q4 | H41: =INDEX('ALL - prices'!$J$3:$DY$219,MATCH('COMBINED DATA'!A41,'ALL - prices'!$B$3:$B$219,0),MATCH('COMBINED DATA'!G41,'ALL - prices'!$J$1:$DY$1,0)) -> 9.86 | I41: N/A | J41: =INDEX('market cap'!$B$3:$DQ$219,MATCH(A41,'market cap'!$A$3:$A$219,0),MATCH(G41,'market cap'!$B$1:$DQ$1,0)) -> 1646.3877 | K41: =LN(J41) -> 7.4063389 | L41: =INDEX('PB2'!$D$2:$AQ$224,MATCH(A41,'PB2'!$B$2:$B$224,0),MATCH(G41,'PB2'!$D$1:$AQ$1,0)) -> 1.0170997 | M41: =1/L41 -> 0.98318777 | N41: =INDEX('ROA2'!$D$2:$AQ$224,MATCH(A41,'ROA2'!$B$2:$B$224,0),MATCH(G41,'ROA2'!$D$1:$AQ$1,0)) -> 1.77763 | O41: 2848.394 | P41: 0.010612828
A42: ABX CN Equity | B42: =VLOOKUP(A42,Sheet3!L:L,1,FALSE) -> #N/A | C42: =VLOOKUP(A42,'ALL - prices'!B:C,2,FALSE) -> Barrick Mining Corp | D42: =VLOOKUP(A42,'ALL - prices'!B:I,8,FALSE) -> Materials | E42: 2015 | F42: Q1 | G42: =E42&"-"&F42 -> 2015-Q1 | H42: =INDEX('ALL - prices'!$J$3:$DY$219,MATCH('COMBINED DATA'!A42,'ALL - prices'!$B$3:$B$219,0),MATCH('COMBINED DATA'!G42,'ALL - prices'!$J$1:$DY$1,0)) -> 11.5543 | I42: =STDEV(H43:H46) -> 3.392744 | J42: =INDEX(MarketCap2!$E$2:$AR$224,MATCH(A42,MarketCap2!$B$2:$B$224,0),MATCH(G42,MarketCap2!$E$1:$AR$1,0)) -> 16130674688 | K42: =LN(J42) -> 23.503989 | L42: =INDEX('PB2'!$D$2:$AQ$224,MATCH(A42,'PB2'!$B$2:$B$224,0),MATCH(G42,'PB2'!$D$1:$AQ$1,0)) -> 1.249226 | M42: =1/L42 -> 0.80049568 | N42: =INDEX('ROA2'!$D$2:$AQ$224,MATCH(A42,'ROA2'!$B$2:$B$224,0),MATCH(G42,'ROA2'!$D$1:$AQ$1,0)) -> -8.1511908 | O42: 33878.999 | P42: -0.096319041
A43: ABX CN Equity | B43: =VLOOKUP(A43,Sheet3!L:L,1,FALSE) -> #N/A | C43: =VLOOKUP(A43,'ALL - prices'!B:C,2,FALSE) -> Barrick Mining Corp | D43: =VLOOKUP(A43,'ALL - prices'!B:I,8,FALSE) -> Materials | E43: 2015 | F43: Q2 | G43: =E43&"-"&F43 -> 2015-Q2 | H43: =INDEX('ALL - prices'!$J$3:$DY$219,MATCH('COMBINED DATA'!A43,'ALL - prices'!$B$3:$B$219,0),MATCH('COMBINED DATA'!G43,'ALL - prices'!$J$1:$DY$1,0)) -> 11.1849 | I43: =STDEV(H44:H47) -> 7.3544072 | J43: =INDEX(MarketCap2!$E$2:$AR$224,MATCH(A43,MarketCap2!$B$2:$B$224,0),MATCH(G43,MarketCap2!$E$1:$AR$1,0)) -> 15548340224 | K43: =LN(J43) -> 23.46722 | L43: =INDEX('PB2'!$D$2:$AQ$224,MATCH(A43,'PB2'!$B$2:$B$224,0),MATCH(G43,'PB2'!$D$1:$AQ$1,0)) -> 1.224861 | M43: =1/L43 -> 0.81641915 | N43: =INDEX('ROA2'!$D$2:$AQ$224,MATCH(A43,'ROA2'!$B$2:$B$224,0),MATCH(G43,'ROA2'!$D$1:$AQ$1,0)) -> -8.2381153 | O43: 33517.001 | P43: -0.010685036
A44: ABX CN Equity | B44: =VLOOKUP(A44,Sheet3!L:L,1,FALSE) -> #N/A | C44: =VLOOKUP(A44,'ALL - prices'!B:C,2,FALSE) -> Barrick Mining Corp | D44: =VLOOKUP(A44,'ALL - prices'!B:I,8,FALSE) -> Materials | E44: 2015 | F44: Q3 | G44: =E44&"-"&F44 -> 2015-Q3 | H44: =INDEX('ALL - prices'!$J$3:$DY$219,MATCH('COMBINED DATA'!A44,'ALL - prices'!$B$3:$B$219,0),MATCH('COMBINED DATA'!G44,'ALL - prices'!$J$1:$DY$1,0)) -> 7.1349 | I44: =STDEV(H45:H48) -> 6.3429034 | J44: =INDEX(MarketCap2!$E$2:$AR$224,MATCH(A44,MarketCap2!$B$2:$B$224,0),MATCH(G44,MarketCap2!$E$1:$AR$1,0)) -> 9888047104 | K44: =LN(J44) -> 23.014593 | L44: =INDEX('PB2'!$D$2:$AQ$224,MATCH(A44,'PB2'!$B$2:$B$224,0),MATCH(G44,'PB2'!$D$1:$AQ$1,0)) -> 0.75509399 | M44: =1/L44 -> 1.3243384 | N44: =INDEX('ROA2'!$D$2:$AQ$224,MATCH(A44,'ROA2'!$B$2:$B$224,0),MATCH(G44,'ROA2'!$D$1:$AQ$1,0)) -> -7.583395 | O44: 33193.001 | P44: -0.0096667284
A45: ABX CN Equity | B45: =VLOOKUP(A45,Sheet3!L:L,1,FALSE) -> #N/A | C45: =VLOOKUP(A45,'ALL - prices'!B:C,2,FALSE) -> Barrick Mining Corp | D45: =VLOOKUP(A45,'ALL - prices'!B:I,8,FALSE) -> Materials | E45: 2015 | F45: Q4 | G45: =E45&"-"&F45 -> 2015-Q4 | H45: =INDEX('ALL - prices'!$J$3:$DY$219,MATCH('COMBINED DATA'!A45,'ALL - prices'!$B$3:$B$219,0),MATCH('COMBINED DATA'!G45,'ALL - prices'!$J$1:$DY$1,0)) -> 8.6289 | I45: =STDEV(H46:H49) -> 3.4876187 | J45: =INDEX(MarketCap2!$E$2:$AR$224,MATCH(A45,MarketCap2!$B$2:$B$224,0),MATCH(G45,MarketCap2!$E$1:$AR$1,0)) -> 11927520256 | K45: =LN(J45) -> 23.202114 | L45: =INDEX('PB2'!$D$2:$AQ$224,MATCH(A45,'PB2'!$B$2:$B$224,0),MATCH(G45,'PB2'!$D$1:$AQ$1,0)) -> 1.201969 | M45: =1/L45 -> 0.83196819 | N45: =INDEX('ROA2'!$D$2:$AQ$224,MATCH(A45,'ROA2'!$B$2:$B$224,0),MATCH(G45,'ROA2'!$D$1:$AQ$1,0)) -> -8.7770262 | O45: 32397.001 | P45: -0.023980967
A46: ABX CN Equity | B46: =VLOOKUP(A46,Sheet3!L:L,1,FALSE) -> #N/A | C46: =VLOOKUP(A46,'ALL - prices'!B:C,2,FALSE) -> Barrick Mining Corp | D46: =VLOOKUP(A46,'ALL - prices'!B:I,8,FALSE) -> Materials | E46: 2016 | F46: Q1 | G46: =E46&"-"&F46 -> 2016-Q1 | H46: =INDEX('ALL - prices'!$J$3:$DY$219,MATCH('COMBINED DATA'!A46,'ALL - prices'!$B$3:$B$219,0),MATCH('COMBINED DATA'!G46,'ALL - prices'!$J$1:$DY$1,0)) -> 14.8869 | I46: =STDEV(H47:H50) -> 2.2089316 | J46: =INDEX(MarketCap2!$E$2:$AR$224,MATCH(A46,MarketCap2!$B$2:$B$224,0),MATCH(G46,MarketCap2!$E$1:$AR$1,0)) -> 20552036352 | K46: =LN(J46) -> 23.746226 | L46: =INDEX('PB2'!$D$2:$AQ$224,MATCH(A46,'PB2'!$B$2:$B$224,0),MATCH(G46,'PB2'!$D$1:$AQ$1,0)) -> 2.2083249 | M46: =1/L46 -> 0.45283192 | N46: =INDEX('ROA2'!$D$2:$AQ$224,MATCH(A46,'ROA2'!$B$2:$B$224,0),MATCH(G46,'ROA2'!$D$1:$AQ$1,0)) -> -9.4306078 | O46: 26308 | P46: -0.18794953
A47: ABX CN Equity | B47: =VLOOKUP(A47,Sheet3!L:L,1,FALSE) -> #N/A | C47: =VLOOKUP(A47,'ALL - prices'!B:C,2,FALSE) -> Barrick Mining Corp | D47: =VLOOKUP(A47,'ALL - prices'!B:I,8,FALSE) -> Materials | E47: 2016 | F47: Q2 | G47: =E47&"-"&F47 -> 2016-Q2 | H47: =INDEX('ALL - prices'!$J$3:$DY$219,MATCH('COMBINED DATA'!A47,'ALL - prices'!$B$3:$B$219,0),MATCH('COMBINED DATA'!G47,'ALL - prices'!$J$1:$DY$1,0)) -> 23.3029 | I47: =STDEV(H48:H51) -> 1.7264674 | J47: =INDEX(MarketCap2!$E$2:$AR$224,MATCH(A47,MarketCap2!$B$2:$B$224,0),MATCH(G47,MarketCap2!$E$1:$AR$1,0)) -> 32136636416 | K47: =LN(J47) -> 24.193263 | L47: =INDEX('PB2'!$D$2:$AQ$224,MATCH(A47,'PB2'!$B$2:$B$224,0),MATCH(G47,'PB2'!$D$1:$AQ$1,0)) -> 3.3727789 | M47: =1/L47 -> 0.29649142 | N47: =INDEX('ROA2'!$D$2:$AQ$224,MATCH(A47,'ROA2'!$B$2:$B$224,0),MATCH(G47,'ROA2'!$D$1:$AQ$1,0)) -> -10.114974 | O47: 25366 | P47: -0.035806604
A48: ABX CN Equity | B48: =VLOOKUP(A48,Sheet3!L:L,1,FALSE) -> #N/A | C48: =VLOOKUP(A48,'ALL - prices'!B:C,2,FALSE) -> Barrick Mining Corp | D48: =VLOOKUP(A48,'ALL - prices'!B:I,8,FALSE) -> Materials | E48: 2016 | F48: Q3 | G48: =E48&"-"&F48 -> 2016-Q3 | H48: =INDEX('ALL - prices'!$J$3:$DY$219,MATCH('COMBINED DATA'!A48,'ALL - prices'!$B$3:$B$219,0),MATCH('COMBINED DATA'!G48,'ALL - prices'!$J$1:$DY$1,0)) -> 19.649 | I48: =STDEV(H49:H52) -> 1.9628205 | J48: =INDEX(MarketCap2!$E$2:$AR$224,MATCH(A48,MarketCap2!$B$2:$B$224,0),MATCH(G48,MarketCap2!$E$1:$AR$1,0)) -> 27070646272 | K48: =LN(J48) -> 24.021716 | L48: =INDEX('PB2'!$D$2:$AQ$224,MATCH(A48,'PB2'!$B$2:$B$224,0),MATCH(G48,'PB2'!$D$1:$AQ$1,0)) -> 2.745357 | M48: =1/L48 -> 0.36425135 | N48: =INDEX('ROA2'!$D$2:$AQ$224,MATCH(A48,'ROA2'!$B$2:$B$224,0),MATCH(G48,'ROA2'!$D$1:$AQ$1,0)) -> -9.6297426 | O48: 25604 | P48: 0.0093826434
A49: ABX CN Equity | B49: =VLOOKUP(A49,Sheet3!L:L,1,FALSE) -> #N/A | C49: =VLOOKUP(A49,'ALL - prices'!B:C,2,FALSE) -> Barrick Mining Corp | D49: =VLOOKUP(A49,'ALL - prices'!B:I,8,FALSE) -> Materials | E49: 2016 | F49: Q4 | G49: =E49&"-"&F49 -> 2016-Q4 | H49: =INDEX('ALL - prices'!$J$3:$DY$219,MATCH('COMBINED DATA'!A49,'ALL - prices'!$B$3:$B$219,0),MATCH('COMBINED DATA'!G49,'ALL - prices'!$J$1:$DY$1,0)) -> 18.2018 | I49: =STDEV(H50:H53) -> 2.5129984 | J49: =INDEX(MarketCap2!$E$2:$AR$224,MATCH(A49,MarketCap2!$B$2:$B$224,0),MATCH(G49,MarketCap2!$E$1:$AR$1,0)) -> 25045110784 | K49: =LN(J49) -> 23.943944 | L49: =INDEX('PB2'!$D$2:$AQ$224,MATCH(A49,'PB2'!$B$2:$B$224,0),MATCH(G49,'PB2'!$D$1:$AQ$1,0)) -> 2.3469679 | M49: =1/L49 -> 0.42608166 | N49: =INDEX('ROA2'!$D$2:$AQ$224,MATCH(A49,'ROA2'!$B$2:$B$224,0),MATCH(G49,'ROA2'!$D$1:$AQ$1,0)) -> -8.2447224 | O49: 25628 | P49: 0.00093737354
A50: ABX CN Equity | B50: =VLOOKUP(A50,Sheet3!L:L,1,FALSE) -> #N/A | C50: =VLOOKUP(A50,'ALL - prices'!B:C,2,FALSE) -> Barrick Mining Corp | D50: =VLOOKUP(A50,'ALL - prices'!B:I,8,FALSE) -> Materials | E50: 2017 | F50: Q1 | G50: =E50&"-"&F50 -> 2017-Q1 | H50: =INDEX('ALL - prices'!$J$3:$DY$219,MATCH('COMBINED DATA'!A50,'ALL - prices'!$B$3:$B$219,0),MATCH('COMBINED DATA'!G50,'ALL - prices'!$J$1:$DY$1,0)) -> 21.4276 | I50: =STDEV(H51:H54) -> 1.7274331 | J50: =INDEX(MarketCap2!$E$2:$AR$224,MATCH(A50,MarketCap2!$B$2:$B$224,0),MATCH(G50,MarketCap2!$E$1:$AR$1,0)) -> 29442402304 | K50: =LN(J50) -> 24.105702 | L50: =INDEX('PB2'!$D$2:$AQ$224,MATCH(A50,'PB2'!$B$2:$B$224,0),MATCH(G50,'PB2'!$D$1:$AQ$1,0)) -> 2.578748 | M50: =1/L50 -> 0.38778508 | N50: =INDEX('ROA2'!$D$2:$AQ$224,MATCH(A50,'ROA2'!$B$2:$B$224,0),MATCH(G50,'ROA2'!$D$1:$AQ$1,0)) -> 2.540138 | O50: 25264.001 | P50: -0.014203185
A51: ABX CN Equity | B51: =VLOOKUP(A51,Sheet3!L:L,1,FALSE) -> #N/A | C51: =VLOOKUP(A51,'ALL - prices'!B:C,2,FALSE) -> Barrick Mining Corp | D51: =VLOOKUP(A51,'ALL - prices'!B:I,8,FALSE) -> Materials | E51: 2017 | F51: Q2 | G51: =E51&"-"&F51 -> 2017-Q2 | H51: =INDEX('ALL - prices'!$J$3:$DY$219,MATCH('COMBINED DATA'!A51,'ALL - prices'!$B$3:$B$219,0),MATCH('COMBINED DATA'!G51,'ALL - prices'!$J$1:$DY$1,0)) -> 17.5321 | I51: =STDEV(H52:H55) -> 1.4125527 | J51: =INDEX(MarketCap2!$E$2:$AR$224,MATCH(A51,MarketCap2!$B$2:$B$224,0),MATCH(G51,MarketCap2!$E$1:$AR$1,0)) -> 24049934336 | K51: =LN(J51) -> 23.903398 | L51: =INDEX('PB2'!$D$2:$AQ$224,MATCH(A51,'PB2'!$B$2:$B$224,0),MATCH(G51,'PB2'!$D$1:$AQ$1,0)) -> 1.92039 | M51: =1/L51 -> 0.52072756 | N51: =INDEX('ROA2'!$D$2:$AQ$224,MATCH(A51,'ROA2'!$B$2:$B$224,0),MATCH(G51,'ROA2'!$D$1:$AQ$1,0)) -> 5.4734731 | O51: 26411 | P51: 0.04540052
A52: ABX CN Equity | B52: =VLOOKUP(A52,Sheet3!L:L,1,FALSE) -> #N/A | C52: =VLOOKUP(A52,'ALL - prices'!B:C,2,FALSE) -> Barrick Mining Corp | D52: =VLOOKUP(A52,'ALL - prices'!B:I,8,FALSE) -> Materials | E52: 2017 | F52: Q3 | G52: =E52&"-"&F52 -> 2017-Q3 | H52: =INDEX('ALL - prices'!$J$3:$DY$219,MATCH('COMBINED DATA'!A52,'ALL - prices'!$B$3:$B$219,0),MATCH('COMBINED DATA'!G52,'ALL - prices'!$J$1:$DY$1,0)) -> 17.0937 | I52: =STDEV(H53:H56) -> 1.4046691 | J52: =INDEX(MarketCap2!$E$2:$AR$224,MATCH(A52,MarketCap2!$B$2:$B$224,0),MATCH(G52,MarketCap2!$E$1:$AR$1,0)) -> 23413340160 | K52: =LN(J52) -> 23.876572 | L52: =INDEX('PB2'!$D$2:$AQ$224,MATCH(A52,'PB2'!$B$2:$B$224,0),MATCH(G52,'PB2'!$D$1:$AQ$1,0)) -> 1.951203 | M52: =1/L52 -> 0.51250434 | N52: =INDEX('ROA2'!$D$2:$AQ$224,MATCH(A52,'ROA2'!$B$2:$B$224,0),MATCH(G52,'ROA2'!$D$1:$AQ$1,0)) -> 9.192585 | O52: 25807 | P52: -0.022869269
A53: ABX CN Equity | B53: =VLOOKUP(A53,Sheet3!L:L,1,FALSE) -> #N/A | C53: =VLOOKUP(A53,'ALL - prices'!B:C,2,FALSE) -> Barrick Mining Corp | D53: =VLOOKUP(A53,'ALL - prices'!B:I,8,FALSE) -> Materials | E53: 2017 | F53: Q4 | G53: =E53&"-"&F53 -> 2017-Q4 | H53: =INDEX('ALL - prices'!$J$3:$DY$219,MATCH('COMBINED DATA'!A53,'ALL - prices'!$B$3:$B$219,0),MATCH('COMBINED DATA'!G53,'ALL - prices'!$J$1:$DY$1,0)) -> 15.5091 | I53: =STDEV(H54:H57) -> 1.5661405 | J53: =INDEX(MarketCap2!$E$2:$AR$224,MATCH(A53,MarketCap2!$B$2:$B$224,0),MATCH(G53,MarketCap2!$E$1:$AR$1,0)) -> 21202667520 | K53: =LN(J53) -> 23.777393 | L53: =INDEX('PB2'!$D$2:$AQ$224,MATCH(A53,'PB2'!$B$2:$B$224,0),MATCH(G53,'PB2'!$D$1:$AQ$1,0)) -> 1.8231879 | M53: =1/L53 -> 0.5484898 | N53: =INDEX('ROA2'!$D$2:$AQ$224,MATCH(A53,'ROA2'!$B$2:$B$224,0),MATCH(G53,'ROA2'!$D$1:$AQ$1,0)) -> 8.5877714 | O53: 25072.001 | P53: -0.028480588
... A77: ABX CN Equity | B77: =VLOOKUP(A77,Sheet3!L:L,1,FALSE) -> #N/A | C77: =VLOOKUP(A77,'ALL - prices'!B:C,2,FALSE) -> Barrick Mining Corp | D77: =VLOOKUP(A77,'ALL - prices'!B:I,8,FALSE) -> Materials | E77: 2023 | F77: Q4 | G77: =E77&"-"&F77 -> 2023-Q4 | H77: =INDEX('ALL - prices'!$J$3:$DY$219,MATCH('COMBINED DATA'!A77,'ALL - prices'!$B$3:$B$219,0),MATCH('COMBINED DATA'!G77,'ALL - prices'!$J$1:$DY$1,0)) -> 22.903 | I77: =STDEV(H78:H81) -> 2.1581346 | J77: =INDEX(MarketCap2!$E$2:$AR$224,MATCH(A77,MarketCap2!$B$2:$B$224,0),MATCH(G77,MarketCap2!$E$1:$AR$1,0)) -> 42027216896 | K77: =LN(J77) -> 24.461583 | L77: =INDEX('PB2'!$D$2:$AQ$224,MATCH(A77,'PB2'!$B$2:$B$224,0),MATCH(G77,'PB2'!$D$1:$AQ$1,0)) -> 1.363385 | M77: =1/L77 -> 0.73346856 | N77: =INDEX('ROA2'!$D$2:$AQ$224,MATCH(A77,'ROA2'!$B$2:$B$224,0),MATCH(G77,'ROA2'!$D$1:$AQ$1,0)) -> 0.126036 | O77: 45595.001 | P77: 0.0068233505
A78: ABX CN Equity | B78: =VLOOKUP(A78,Sheet3!L:L,1,FALSE) -> #N/A | C78: =VLOOKUP(A78,'ALL - prices'!B:C,2,FALSE) -> Barrick Mining Corp | D78: =VLOOKUP(A78,'ALL - prices'!B:I,8,FALSE) -> Materials | E78: 2024 | F78: Q1 | G78: =E78&"-"&F78 -> 2024-Q1 | H78: =INDEX('ALL - prices'!$J$3:$DY$219,MATCH('COMBINED DATA'!A78,'ALL - prices'!$B$3:$B$219,0),MATCH('COMBINED DATA'!G78,'ALL - prices'!$J$1:$DY$1,0)) -> 21.7035 | I78: N/A | J78: =INDEX(MarketCap2!$E$2:$AR$224,MATCH(A78,MarketCap2!$B$2:$B$224,0),MATCH(G78,MarketCap2!$E$1:$AR$1,0)) -> 39552983040 | K78: =LN(J78) -> 24.400907 | L78: =INDEX('PB2'!$D$2:$AQ$224,MATCH(A78,'PB2'!$B$2:$B$224,0),MATCH(G78,'PB2'!$D$1:$AQ$1,0)) -> 1.245345 | M78: =1/L78 -> 0.80299034 | N78: =INDEX('ROA2'!$D$2:$AQ$224,MATCH(A78,'ROA2'!$B$2:$B$224,0),MATCH(G78,'ROA2'!$D$1:$AQ$1,0)) -> 2.7719669 | O78: 45810.999 | P78: 0.0047373278
A79: ABX CN Equity | B79: =VLOOKUP(A79,Sheet3!L:L,1,FALSE) -> #N/A | C79: =VLOOKUP(A79,'ALL - prices'!B:C,2,FALSE) -> Barrick Mining Corp | D79: =VLOOKUP(A79,'ALL - prices'!B:I,8,FALSE) -> Materials | E79: 2024 | F79: Q2 | G79: =E79&"-"&F79 -> 2024-Q2 | H79: =INDEX('ALL - prices'!$J$3:$DY$219,MATCH('COMBINED DATA'!A79,'ALL - prices'!$B$3:$B$219,0),MATCH('COMBINED DATA'!G79,'ALL - prices'!$J$1:$DY$1,0)) -> 22.1118 | I79: N/A | J79: =INDEX(MarketCap2!$E$2:$AR$224,MATCH(A79,MarketCap2!$B$2:$B$224,0),MATCH(G79,MarketCap2!$E$1:$AR$1,0)) -> 40063614976 | K79: =LN(J79) -> 24.413734 | L79: =INDEX('PB2'!$D$2:$AQ$224,MATCH(A79,'PB2'!$B$2:$B$224,0),MATCH(G79,'PB2'!$D$1:$AQ$1,0)) -> 1.238506 | M79: =1/L79 -> 0.80742446 | N79: =INDEX('ROA2'!$D$2:$AQ$224,MATCH(A79,'ROA2'!$B$2:$B$224,0),MATCH(G79,'ROA2'!$D$1:$AQ$1,0)) -> 3.145823 | O79: 45843.001 | P79: 0.00069856691
A80: ABX CN Equity | B80: =VLOOKUP(A80,Sheet3!L:L,1,FALSE) -> #N/A | C80: =VLOOKUP(A80,'ALL - prices'!B:C,2,FALSE) -> Barrick Mining Corp | D80: =VLOOKUP(A80,'ALL - prices'!B:I,8,FALSE) -> Materials | E80: 2024 | F80: Q3 | G80: =E80&"-"&F80 -> 2024-Q3 | H80: =INDEX('ALL - prices'!$J$3:$DY$219,MATCH('COMBINED DATA'!A80,'ALL - prices'!$B$3:$B$219,0),MATCH('COMBINED DATA'!G80,'ALL - prices'!$J$1:$DY$1,0)) -> 26.1841 | I80: N/A | J80: =INDEX(MarketCap2!$E$2:$AR$224,MATCH(A80,MarketCap2!$B$2:$B$224,0),MATCH(G80,MarketCap2!$E$1:$AR$1,0)) -> 47092707328 | K80: =LN(J80) -> 24.575384 | L80: =INDEX('PB2'!$D$2:$AQ$224,MATCH(A80,'PB2'!$B$2:$B$224,0),MATCH(G80,'PB2'!$D$1:$AQ$1,0)) -> 1.460304 | M80: =1/L80 -> 0.68478891 | N80: =INDEX('ROA2'!$D$2:$AQ$224,MATCH(A80,'ROA2'!$B$2:$B$224,0),MATCH(G80,'ROA2'!$D$1:$AQ$1,0)) -> 3.3047371 | O80: 46219.002 | P80: 0.0082019174
A81: ABX CN Equity | B81: =VLOOKUP(A81,Sheet3!L:L,1,FALSE) -> #N/A | C81: =VLOOKUP(A81,'ALL - prices'!B:C,2,FALSE) -> Barrick Mining Corp | D81: =VLOOKUP(A81,'ALL - prices'!B:I,8,FALSE) -> Materials | E81: 2024 | F81: Q4 | G81: =E81&"-"&F81 -> 2024-Q4 | H81: =INDEX('ALL - prices'!$J$3:$DY$219,MATCH('COMBINED DATA'!A81,'ALL - prices'!$B$3:$B$219,0),MATCH('COMBINED DATA'!G81,'ALL - prices'!$J$1:$DY$1,0)) -> 21.8288 | I81: N/A | J81: =INDEX(MarketCap2!$E$2:$AR$224,MATCH(A81,MarketCap2!$B$2:$B$224,0),MATCH(G81,MarketCap2!$E$1:$AR$1,0)) -> 38807977984 | K81: =LN(J81) -> 24.381892 | L81: =INDEX('PB2'!$D$2:$AQ$224,MATCH(A81,'PB2'!$B$2:$B$224,0),MATCH(G81,'PB2'!$D$1:$AQ$1,0)) -> 1.1362153 | M81: =1/L81 -> 0.88011486 | N81: =INDEX('ROA2'!$D$2:$AQ$224,MATCH(A81,'ROA2'!$B$2:$B$224,0),MATCH(G81,'ROA2'!$D$1:$AQ$1,0)) -> 3.500845 | O81: 47353.999 | P81: 0.024556945
A82: AC CN Equity | B82: =VLOOKUP(A82,Sheet3!L:L,1,FALSE) -> #N/A | C82: =VLOOKUP(A82,'ALL - prices'!B:C,2,FALSE) -> Air Canada | D82: =VLOOKUP(A82,'ALL - prices'!B:I,8,FALSE) -> Industrials | E82: 2015 | F82: Q1 | G82: =E82&"-"&F82 -> 2015-Q1 | H82: =INDEX('ALL - prices'!$J$3:$DY$219,MATCH('COMBINED DATA'!A82,'ALL - prices'!$B$3:$B$219,0),MATCH('COMBINED DATA'!G82,'ALL - prices'!$J$1:$DY$1,0)) -> 12.39 | I82: =STDEV(H83:H86) -> 1.7836923 | J82: =INDEX(MarketCap2!$E$2:$AR$224,MATCH(A82,MarketCap2!$B$2:$B$224,0),MATCH(G82,MarketCap2!$E$1:$AR$1,0)) -> 3550374656 | K82: =LN(J82) -> 21.990319 | L82: =INDEX('PB2'!$D$2:$AQ$224,MATCH(A82,'PB2'!$B$2:$B$224,0),MATCH(G82,'PB2'!$D$1:$AQ$1,0)) -> -- | M82: =1/L82 -> #VALUE! | N82: =INDEX('ROA2'!$D$2:$AQ$224,MATCH(A82,'ROA2'!$B$2:$B$224,0),MATCH(G82,'ROA2'!$D$1:$AQ$1,0)) -> 0.99413502 | O82: 10648.001 | P82: 0.0097676681
A83: AC CN Equity | B83: =VLOOKUP(A83,Sheet3!L:L,1,FALSE) -> #N/A | C83: =VLOOKUP(A83,'ALL - prices'!B:C,2,FALSE) -> Air Canada | D83: =VLOOKUP(A83,'ALL - prices'!B:I,8,FALSE) -> Industrials | E83: 2015 | F83: Q2 | G83: =E83&"-"&F83 -> 2015-Q2 | H83: =INDEX('ALL - prices'!$J$3:$DY$219,MATCH('COMBINED DATA'!A83,'ALL - prices'!$B$3:$B$219,0),MATCH('COMBINED DATA'!G83,'ALL - prices'!$J$1:$DY$1,0)) -> 13.21 | I83: =STDEV(H84:H87) -> 0.91736489 | J83: =INDEX(MarketCap2!$E$2:$AR$224,MATCH(A83,MarketCap2!$B$2:$B$224,0),MATCH(G83,MarketCap2!$E$1:$AR$1,0)) -> 3789085440 | K83: =LN(J83) -> 22.055391 | L83: =INDEX('PB2'!$D$2:$AQ$224,MATCH(A83,'PB2'!$B$2:$B$224,0),MATCH(G83,'PB2'!$D$1:$AQ$1,0)) -> -- | M83: =1/L83 -> #VALUE! | N83: =INDEX('ROA2'!$D$2:$AQ$224,MATCH(A83,'ROA2'!$B$2:$B$224,0),MATCH(G83,'ROA2'!$D$1:$AQ$1,0)) -> 1.225342 | O83: 11581 | P83: 0.087622006
A84: AC CN Equity | B84: =VLOOKUP(A84,Sheet3!L:L,1,FALSE) -> #N/A | C84: =VLOOKUP(A84,'ALL - prices'!B:C,2,FALSE) -> Air Canada | D84: =VLOOKUP(A84,'ALL - prices'!B:I,8,FALSE) -> Industrials | E84: 2015 | F84: Q3 | G84: =E84&"-"&F84 -> 2015-Q3 | H84: =INDEX('ALL - prices'!$J$3:$DY$219,MATCH('COMBINED DATA'!A84,'ALL - prices'!$B$3:$B$219,0),MATCH('COMBINED DATA'!G84,'ALL - prices'!$J$1:$DY$1,0)) -> 10.73 | I84: =STDEV(H85:H88) -> 0.8696551 | J84: =INDEX(MarketCap2!$E$2:$AR$224,MATCH(A84,MarketCap2!$B$2:$B$224,0),MATCH(G84,MarketCap2!$E$1:$AR$1,0)) -> 3065968384 | K84: =LN(J84) -> 21.843629 | L84: =INDEX('PB2'!$D$2:$AQ$224,MATCH(A84,'PB2'!$B$2:$B$224,0),MATCH(G84,'PB2'!$D$1:$AQ$1,0)) -> -- | M84: =1/L84 -> #VALUE! | N84: =INDEX('ROA2'!$D$2:$AQ$224,MATCH(A84,'ROA2'!$B$2:$B$224,0),MATCH(G84,'ROA2'!$D$1:$AQ$1,0)) -> 1.790706 | O84: 12374 | P84: 0.068474221
A85: AC CN Equity | B85: =VLOOKUP(A85,Sheet3!L:L,1,FALSE) -> #N/A | C85: =VLOOKUP(A85,'ALL - prices'!B:C,2,FALSE) -> Air Canada | D85: =VLOOKUP(A85,'ALL - prices'!B:I,8,FALSE) -> Industrials | E85: 2015 | F85: Q4 | G85: =E85&"-"&F85 -> 2015-Q4 | H85: =INDEX('ALL - prices'!$J$3:$DY$219,MATCH('COMBINED DATA'!A85,'ALL - prices'!$B$3:$B$219,0),MATCH('COMBINED DATA'!G85,'ALL - prices'!$J$1:$DY$1,0)) -> 10.21 | I85: =STDEV(H86:H89) -> 2.2374837 | J85: =INDEX(MarketCap2!$E$2:$AR$224,MATCH(A85,MarketCap2!$B$2:$B$224,0),MATCH(G85,MarketCap2!$E$1:$AR$1,0)) -> 2894456832 | K85: =LN(J85) -> 21.786063 | L85: =INDEX('PB2'!$D$2:$AQ$224,MATCH(A85,'PB2'!$B$2:$B$224,0),MATCH(G85,'PB2'!$D$1:$AQ$1,0)) -> 222.09277 | M85: =1/L85 -> 0.0045026229 | N85: =INDEX('ROA2'!$D$2:$AQ$224,MATCH(A85,'ROA2'!$B$2:$B$224,0),MATCH(G85,'ROA2'!$D$1:$AQ$1,0)) -> 2.7381971 | O85: 12755 | P85: 0.030790425
A86: AC CN Equity | B86: =VLOOKUP(A86,Sheet3!L:L,1,FALSE) -> #N/A | C86: =VLOOKUP(A86,'ALL - prices'!B:C,2,FALSE) -> Air Canada | D86: =VLOOKUP(A86,'ALL - prices'!B:I,8,FALSE) -> Industrials | E86: 2016 | F86: Q1 | G86: =E86&"-"&F86 -> 2016-Q1 | H86: =INDEX('ALL - prices'!$J$3:$DY$219,MATCH('COMBINED DATA'!A86,'ALL - prices'!$B$3:$B$219,0),MATCH('COMBINED DATA'!G86,'ALL - prices'!$J$1:$DY$1,0)) -> 8.96 | I86: =STDEV(H87:H90) -> 2.4076683 | J86: =INDEX(MarketCap2!$E$2:$AR$224,MATCH(A86,MarketCap2!$B$2:$B$224,0),MATCH(G86,MarketCap2!$E$1:$AR$1,0)) -> 2523493376 | K86: =LN(J86) -> 21.64891 | L86: =INDEX('PB2'!$D$2:$AQ$224,MATCH(A86,'PB2'!$B$2:$B$224,0),MATCH(G86,'PB2'!$D$1:$AQ$1,0)) -> -- | M86: =1/L86 -> #VALUE! | N86: =INDEX('ROA2'!$D$2:$AQ$224,MATCH(A86,'ROA2'!$B$2:$B$224,0),MATCH(G86,'ROA2'!$D$1:$AQ$1,0)) -> 2.5488961 | O86: 13127 | P86: 0.029165013
...

Sheet RAW DATA -->
B2: Page intentionally left blank

Sheet securities
A1: Ticker
A2: AAUC CN Equity
A3: AAV CN Equity
A4: ABX CN Equity
A5: AC CN Equity
A6: ACO/X CN Equity
A7: AEM CN Equity
A8: AG CN Equity
A9: AGI CN Equity
A10: AIF CN Equity
A11: ALA CN Equity
A12: AP-U CN Equity
... A219: X CN Equity

Sheet ALL - prices
A1: Ticker | B1: Ticker | C1: Name | D1: Weight | E1: Shares | F1: Price | G1: Start | H1: End | I1: SECTOR | J1: 1/31/2015 | K1: 2/28/2015 | L1: 2015-Q1 | M1: 4/30/2015 | N1: 5/31/2015 | O1: 2015-Q2 | P1: 42216 | Q1: 42247 | R1: 2015-Q3 | S1: 42308 | T1: 42338 | U1: 2015-Q4 | V1: 42400 | W1: 42429 | X1: 2016-Q1 | Y1: 42490 | Z1: 42521 | AA1: 2016-Q2 | AB1: 42582 | AC1: 42613 | AD1: 2016-Q3 | AE1: 42674 | AF1: 42704 | AG1: 2016-Q4 | AH1: 42766 | AI1: 42794 | AJ1: 2017-Q1 | AK1: 42855 | AL1: 42886 | AM1: 2017-Q2 | AN1: 42947 | AO1: 42978 | AP1: 2017-Q3 | AQ1: 43039 | AR1: 43069 | AS1: 2017-Q4 | AT1: 43131 | AU1: 43159 | AV1: 2018-Q1 | AW1: 43220 | AX1: 43251 | AY1: 2018-Q2 | AZ1: 43312 | BA1: 43343 | BB1: 2018-Q3 | BC1: 43404 | BD1: 43434 | BE1: 2018-Q4 | BF1: 43496 | BG1: 43524 | BH1: 2019-Q1 | BI1: 43585 | BJ1: 43616 | BK1: 2019-Q2 | BL1: 43677 | BM1: 43708 | BN1: 2019-Q3 | BO1: 43769 | BP1: 43799 | BQ1: 2019-Q4 | BR1: 43861 | BS1: 43890 | BT1: 2020-Q1 | BU1: 43951 | BV1: 43982 | BW1: 2020-Q2 | BX1: 44043 | BY1: 44074 | BZ1: 2020-Q3 | CA1: 44135 | CB1: 44165 | CC1: 2020-Q4 | CD1: 44227 | CE1: 44255 | CF1: 2021-Q1 | CG1: 44316 | CH1: 44347 | CI1: 2021-Q2 | CJ1: 44408 | CK1: 44439 | CL1: 2021-Q3 | CM1: 44500 | CN1: 44530 | CO1: 2021-Q4 | CP1: 44592 | CQ1: 44620 | CR1: 2022-Q1 | CS1: 44681 | CT1: 44712 | CU1: 2022-Q2 | CV1: 44773 | CW1: 44804 | CX1: 2022-Q3 | CY1: 44865 | CZ1: 44895 | DA1: 2022-Q4 | DB1: 44957 | DC1: 44985 | DD1: 2023-Q1 | DE1: 45046 | DF1: 45077 | DG1: 2023-Q2 | DH1: 45138 | DI1: 45169 | DJ1: 2023-Q3 | DK1: 45230 | DL1: 45260 | DM1: 2023-Q4 | DN1: 45322 | DO1: 45351 | DP1: 2024-Q1 | DQ1: 45412 | DR1: 45443 | DS1: 2024-Q2 | DT1: 45504 | DU1: 45535 | DV1: 2024-Q3 | DW1: 45596 | DX1: 45626 | DY1: 2024-Q4
A2: AAUC | B2: =A2&" CN Equity" -> AAUC CN Equity | C2: Allied Gold Corp | D2: -- | E2: -- | F2: 42.97 | G2: 42005 | H2: 45657 | I2: Materials | DJ2: =_xll.BDH(B2, "PX_LAST", "2015-01-01", "2024-12-31", "Period=M", "Orientation=H", "CshAdjNormal = Y","CapChg = Y", "DTS=H","cols=16;rows=1") -> #N/A Requesting Data... | DK2: 13.2 | DL2: 11.25 | DM2: 10.53 | DN2: 9.48 | DO2: 8.88 | DP2: 10.2 | DQ2: 11.1 | DR2: 9.24 | DS2: 8.82 | DT2: 9.81 | DU2: 9.18 | DV2: 9.66 | DW2: 11.1 | DX2: 10.29 | DY2: 10.23
A3: AAV | B3: =A3&" CN Equity" -> AAV CN Equity | C3: Advantage Energy Ltd | D3: -- | E3: -- | F3: 11.01 | G3: 42005 | H3: 45657 | I3: Energy | J3: 5.82 | K3: 6.49 | L3: 6.82 | M3: 7.47 | N3: 7.54 | O3: 7.9 | P3: 7.14 | Q3: 7.33 | R3: 6.97 | S3: 7.27 | T3: 7.04 | U3: 7.03 | V3: 7.65 | W3: 6.88 | X3: 7.13 | Y3: 7.19 | Z3: 7.71 | AA3: 7.22 | AB3: 8.26 | AC3: 8.95 | AD3: 9.2 | AE3: 9.05 | AF3: 9.74 | AG3: 9.12 | AH3: 8.39 | AI3: 8 | AJ3: 8.78 | AK3: 8.59 | AL3: 8.51 | AM3: 8.77 | AN3: 8.57 | AO3: 7.96 | AP3: 7.82 | AQ3: 6.83 | AR3: 6.03 | AS3: 5.4 | AT3: 3.95 | AU3: 3.63 | AV3: 3.81 | AW3: 4.09 | AX3: 3.87 | AY3: 4.11 | AZ3: 4.5 | BA3: 3.88 | BB3: 3.6 | BC3: 2.95 | BD3: 2.38 | BE3: 1.98 | BF3: 2.05 | BG3: 2.24 | BH3: 2.2 | BI3: 2.22 | BJ3: 1.75 | BK3: 1.63 | BL3: 1.89 | BM3: 1.48 | BN3: 2.15 | BO3: 1.9 | BP3: 2.44 | BQ3: 2.75 | BR3: 2.21 | BS3: 2.02 | BT3: 1.43 | BU3: 2.26 | BV3: 2.1 | BW3: 1.66 | BX3: 1.6 | BY3: 2.17 | BZ3: 1.75 | CA3: 2.2 | CB3: 2.06 | CC3: 1.71 | CD3: 1.91 | CE3: 2.6 | CF3: 2.37 | CG3: 3.26 | CH3: 4.03 | CI3: 5.06 | CJ3: 4.69 | CK3: 5.25 | CL3: 6.4 | CM3: 7.01 | CN3: 7.09 | CO3: 7.41 | CP3: 6.88 | CQ3: 7.41 | CR3: 8.71 | CS3: 10.73 | CT3: 10.98 | CU3: 8 | CV3: 11.01 | CW3: 11.22 | CX3: 9.93 | CY3: 10.3 | CZ3: 11.56 | DA3: 9.47 | DB3: 8.3 | DC3: 7.98 | DD3: 7.81 | DE3: 7.62 | DF3: 7.31 | DG3: 8.65 | DH3: 9.3 | DI3: 9.63 | DJ3: 9.27 | DK3: 10.07 | DL3: 9.3 | DM3: 8.53 | DN3: 8.82 | DO3: 10.04 | DP3: 9.88 | DQ3: 10.74 | DR3: 11.59 | DS3: 10.38 | DT3: 9.63 | DU3: 9.72 | DV3: 9.45 | DW3: 8.71 | DX3: 9 | DY3: 9.86
A4: ABX | B4: =A4&" CN Equity" -> ABX CN Equity | C4: Barrick Mining Corp | D4: -- | E4: -- | F4: 62.24 | G4: 42005 | H4: 45657 | I4: Materials | J4: 13.5 | K4: 13.5648 | L4: 11.5543 | M4: 13.0809 | N4: 12.3327 | O4: 11.1849 | P4: 7.6996 | Q4: 7.6895 | R4: 7.1349 | S4: 8.5383 | T4: 8.2834 | U4: 8.6289 | V4: 11.7384 | W4: 15.8659 | X4: 14.8869 | Y4: 20.4991 | Z4: 18.5206 | AA4: 23.3029 | AB4: 24.0886 | AC4: 18.8539 | AD4: 19.649 | AE4: 19.962 | AF4: 17.0668 | AG4: 18.2018 | AH4: 20.3108 | AI4: 20.7913 | AJ4: 21.4276 | AK4: 19.3577 | AL4: 18.9853 | AM4: 17.5321 | AN4: 17.9145 | AO4: 19.1453 | AP4: 17.0937 | AQ4: 15.8679 | AR4: 15.2019 | AS4: 15.5091 | AT4: 15.091 | AU4: 12.6396 | AV4: 13.7257 | AW4: 14.7776 | AX4: 14.631 | AY4: 14.8024 | AZ4: 12.4967 | BA4: 11.4749 | BB4: 12.2829 | BC4: 14.1739 | BD4: 14.5856 | BE4: 15.9594 | BF4: 15.232 | BG4: 14.3747 | BH4: 15.8642 | BI4: 14.7471 | BJ4: 14.6063 | BK4: 17.9603 | BL4: 18.6381 | BM4: 22.4715 | BN4: 19.9553 | BO4: 19.9205 | BP4: 19.3687 | BQ4: 21.0628 | BR4: 21.4034 | BS4: 22.4297 | BT4: 22.6575 | BU4: 31.3928 | BV4: 29.0951 | BW4: 32.1004 | BX4: 34.016 | BY4: 34.05 | BZ4: 32.9573 | CA4: 31.3887 | CB4: 26.371 | CC4: 25.6545 | CD4: 25.2652 | CE4: 21.1075 | CF4: 22.1562 | CG4: 23.276 | CH4: 25.5469 | CI4: 22.8709 | CJ4: 24.2267 | CK4: 22.722 | CL4: 20.491 | CM4: 20.3477 | CN4: 21.8572 | CO4: 21.6501 | CP4: 21.9022 | CQ4: 25.8522 | CR4: 27.5974 | CS4: 25.9065 | CT4: 23.6523 | CU4: 20.7768 | CV4: 18.4216 | CW4: 18.0359 | CX4: 19.8024 | CY4: 19.0255 | CZ4: 20.4993 | DA4: 21.6761 | DB4: 24.3003 | DC4: 20.7225 | DD4: 23.5794 | DE4: 24.2091 | DF4: 21.6867 | DG4: 21.2046 | DH4: 21.5355 | DI4: 20.8312 | DJ4: 18.7671 | DK4: 21.069 | DL4: 22.8647 | DM4: 22.903 | DN4: 20.0903 | DO4: 19.064 | DP4: 21.7035 | DQ4: 22.0792 | DR4: 22.5963 | DS4: 22.1118 | DT4: 24.7862 | DU4: 26.4957 | DV4: 26.1841 | DW4: 26.2036 | DX4: 24.0126 | DY4: 21.8288
A5: AC | B5: =A5&" CN Equity" -> AC CN Equity | C5: Air Canada | D5: -- | E5: -- | F5: 18.85 | G5: 42005 | H5: 45657 | I5: Industrials | J5: 11.75 | K5: 12.34 | L5: 12.39 | M5: 11.52 | N5: 13.76 | O5: 13.21 | P5: 11.77 | Q5: 11.23 | R5: 10.73 | S5: 10.76 | T5: 10.43 | U5: 10.21 | V5: 7.83 | W5: 7.22 | X5: 8.96 | Y5: 9.33 | Z5: 9.63 | AA5: 8.89 | AB5: 8.99 | AC5: 8.96 | AD5: 10.6 | AE5: 12.65 | AF5: 13.5 | AG5: 13.67 | AH5: 13.37 | AI5: 13.38 | AJ5: 13.8 | AK5: 12.99 | AL5: 17.8 | AM5: 17.38 | AN5: 19.83 | AO5: 23.34 | AP5: 26.24 | AQ5: 25.56 | AR5: 24.59 | AS5: 25.88 | AT5: 23.91 | AU5: 27.06 | AV5: 26.77 | AW5: 25.25 | AX5: 22.97 | AY5: 21.25 | AZ5: 23.53 | BA5: 26.82 | BB5: 27.6 | BC5: 24.98 | BD5: 29 | BE5: 25.96 | BF5: 29.67 | BG5: 33.11 | BH5: 32.21 | BI5: 32.16 | BJ5: 39.9 | BK5: 39.69 | BL5: 45.41 | BM5: 44.75 | BN5: 43.21 | BO5: 46.9 | BP5: 50.05 | BQ5: 48.51 | BR5: 44.33 | BS5: 34.25 | BT5: 15.75 | BU5: 20.24 | BV5: 15.9 | BW5: 16.95 | BX5: 15.11 | BY5: 17.6 | BZ5: 15.69 | CA5: 15.1 | CB5: 24.7 | CC5: 22.77 | CD5: 20.02 | CE5: 25.1 | CF5: 26.15 | CG5: 24.77 | CH5: 27.36 | CI5: 25.5 | CJ5: 24.98 | CK5: 24.51 | CL5: 23.13 | CM5: 22.19 | CN5: 20.8 | CO5: 21.12 | CP5: 22.86 | CQ5: 23.95 | CR5: 24.25 | CS5: 22.5 | CT5: 22.19 | CU5: 16.04 | CV5: 17.39 | CW5: 17.69 | CX5: 16.6 | CY5: 19.61 | CZ5: 19.29 | DA5: 19.39 | DB5: 22.58 | DC5: 20.12 | DD5: 19.15 | DE5: 18.96 | DF5: 21.43 | DG5: 24.99 | DH5: 24.3 | DI5: 22.82 | DJ5: 19.38 | DK5: 16.73 | DL5: 17.63 | DM5: 18.69 | DN5: 18.22 | DO5: 18.12 | DP5: 19.61 | DQ5: 20.32 | DR5: 18.2 | DS5: 17.9 | DT5: 15.91 | DU5: 15.44 | DV5: 16.39 | DW5: 18.87 | DX5: 24.96 | DY5: 22.26
A6: ACO/X | B6: =A6&" CN Equity" -> ACO/X CN Equity | C6: Atco Ltd/Canada | D6: -- | E6: -- | F6: 59.12 | G6: 42005 | H6: 45657 | I6: Utilities | J6: 32.57 | K6: 31.9351 | L6: 30.0313 | M6: 30.4373 | N6: 28.9597 | O6: 26.4378 | P6: 26.2771 | Q6: 26.5784 | R6: 26.4174 | S6: 25.1706 | T6: 24.3148 | U6: 24.2275 | V6: 26.3517 | W6: 24.3429 | X6: 26.8634 | Y6: 28.0261 | Z6: 29.517 | AA6: 31.1943 | AB6: 33.8719 | AC6: 33.1147 | AD6: 32.2778 | AE6: 32.5548 | AF6: 29.633 | AG6: 31.1272 | AH6: 31.9357 | AI6: 31.6291 | AJ6: 36.2967 | AK6: 34.8647 | AL6: 35.7632 | AM6: 35.8231 | AN6: 32.7854 | AO6: 32.5029 | AP6: 32.5903 | AQ6: 33.2877 | AR6: 32.7896 | AS6: 32.2532 | AT6: 31.8805 | AU6: 30.275 | AV6: 29.9241 | AW6: 28.0945 | AX6: 28.4995 | AY6: 29.6328 | AZ6: 29.1289 | BA6: 28.4863 | BB6: 27.8395 | BC6: 28.3041 | BD6: 29.9634 | BE6: 28.7335 | BF6: 30.9214 | BG6: 32.9605 | BH6: 33.7935 | BI6: 34.5069 | BJ6: 34.9125 | BK6: 33.4396 | BL6: 33.3259 | BM6: 36.0456 | BN6: 37.0407 | BO6: 35.3751 | BP6: 38.5001 | BQ6: 38.3325 | BR6: 39.7573 | BS6: 38.5712 | BT6: 30.2715 | BU6: 30.3647 | BV6: 30.1472 | BW6: 31.6367 | BX6: 32.7444 | BY6: 31.2204 | BZ6: 30.5676 | CA6: 29.4558 | CB6: 31.0044 | CC6: 29.3054 | CD6: 29.4018 | CE6: 29.8114 | CF6: 33.9039 | CG6: 34.2858 | CH6: 35.4561 | CI6: 36.0949 | CJ6: 37.0145 | CK6: 34.8551 | CL6: 33.7168 | CM6: 34.8537 | CN6: 34.5467 | CO6: 35.8203 | CP6: 35.921 | CQ6: 34.9227 | CR6: 36.4159 | CS6: 38.825 | CT6: 38.9183 | CU6: 37.7886 | CV6: 40.5564 | CW6: 40.2381 | CX6: 36.7335 | CY6: 36.6037 | CZ6: 37.6763 | DA6: 37.0727 | DB6: 37.0377 | DC6: 37.0115 | DD6: 38.3258 | DE6: 39.6087 | DF6: 37.3364 | DG6: 35.2875 | DH6: 33.677 | DI6: 33.3728 | DJ6: 31.1757 | DK6: 32.218 | DL6: 33.5774 | DM6: 35.4947 | DN6: 34.5126 | DO6: 34.5691 | DP6: 35.0713 | DQ6: 34.9411 | DR6: 37.2136 | DS6: 36.6957 | DT6: 40.3305 | DU6: 42.8164 | DV6: 45.5895 | DW6: 45.9892 | DX6: 46.7696 | DY6: 45.7286
A7: AEM | B7: =A7&" CN Equity" -> AEM CN Equity | C7: Agnico Eagle Mines Ltd | D7: -- | E7: -- | F7: 258.84 | G7: 42005 | H7: 45657 | I7: Materials | J7: 35.38 | K7: 33.2588 | L7: 29.2018 | M7: 30.2367 | N7: 33.2195 | O7: 29.4344 | P7: 24.0223 | Q7: 26.8356 | R7: 28.1766 | S7: 30.7835 | T7: 29.639 | U7: 30.3825 | V7: 34.551 | W7: 39.8619 | X7: 39.3428 | Y7: 49.6578 | Z7: 49.37 | AA7: 57.9926 | AB7: 63.7298 | AC7: 55.8579 | AD7: 59.6227 | AE7: 57.2445 | AF7: 46.4972 | AG7: 47.5501 | AH7: 52.2841 | AI7: 47.1488 | AJ7: 47.63 | AK7: 55.0843 | AL7: 55.2318 | AM7: 49.4709 | AN7: 49.2425 | AO7: 54.2553 | AP7: 47.7965 | AQ7: 48.8221 | AR7: 48.0534 | AS7: 49.3196 | AT7: 49.447 | AU7: 41.6627 | AV7: 46.1878 | AW7: 46.0429 | AX7: 49.7083 | AY7: 51.4852 | AZ7: 46.5562 | BA7: 38.5428 | BB7: 37.8059 | BC7: 39.8453 | BD7: 40.1668 | BE7: 47.3613 | BF7: 49.1233 | BG7: 48.2509 | BH7: 50.0872 | BI7: 47.8285 | BJ7: 50.9743 | BK7: 58.0562 | BL7: 59.6213 | BM7: 72.1189 | BN7: 61.5142 | BO7: 70.1348 | BP7: 68.5825 | BQ7: 69.5037 | BR7: 71.0853 | BS7: 55.5647 | BT7: 49.0128 | BU7: 70.9543 | BV7: 77.0942 | BW7: 76.079 | BX7: 93.0924 | BY7: 94.3545 | BZ7: 92.8278 | CA7: 92.5383 | CB7: 75.0811 | CC7: 79.0332 | CD7: 78.7509 | CE7: 63.0431 | CF7: 64.4719 | CG7: 68.1724 | CH7: 76.255 | CI7: 66.8469 | CJ7: 71.9746 | CK7: 65.1403 | CL7: 58.9583 | CM7: 58.9403 | CN7: 57.535 | CO7: 60.7063 | CP7: 54.8516 | CQ7: 58.041 | CR7: 69.6458 | CS7: 68.0799 | CT7: 61.4833 | CU7: 54.0363 | CV7: 50.4963 | CW7: 50.1452 | CX7: 54.0338 | CY7: 55.4875 | CZ7: 63.2353 | DA7: 65.6714 | DB7: 70.1329 | DC7: 59.1488 | DD7: 64.8264 | DE7: 72.3683 | DF7: 65.5648 | DG7: 62.7839 | DH7: 65.6123 | DI7: 62.7825 | DJ7: 59.0601 | DK7: 62.237 | DL7: 70.2362 | DM7: 70.0433 | DN7: 63.7091 | DO7: 63.4178 | DP7: 78.5261 | DQ7: 84.758 | DR7: 90.9556 | DS7: 87.5036 | DT7: 104.177 | DU7: 107.8997 | DV7: 107.0644 | DW7: 118.1 | DX7: 116.5728 | DY7: 111.0433
A8: AG | B8: =A8&" CN Equity" -> AG CN Equity | C8: First Majestic Silver Corp | D8: -- | E8: -- | F8: 28.35 | G8: 42005 | H8: 45657 | I8: Materials | J8: 7.75 | K8: 7.6085 | L8: 6.7302 | M8: 5.8026 | N8: 6.0691 | O8: 5.9704 | P8: 3.9572 | Q8: 4.4803 | R8: 4.2138 | S8: 4.2631 | T8: 4.4013 | U8: 4.4506 | V8: 4.1447 | W8: 6.1974 | X8: 8.3092 | Y8: 13.1842 | Z8: 13.4605 | AA8: 17.319 | AB8: 22.342 | AC8: 15.6019 | AD8: 13.3519 | AE8: 10.6283 | AF8: 11.7533 | AG8: 10.125 | AH8: 12.3059 | AI8: 11.8815 | AJ8: 10.648 | AK8: 10.9539 | AL8: 11.1513 | AM8: 10.6184 | AN8: 10.125 | AO8: 8.7039 | AP8: 8.4079 | AQ8: 8.5756 | AR8: 8.5263 | AS8: 8.3684 | AT8: 7.421 | AU8: 6.7105 | AV8: 7.7862 | AW8: 8.2302 | AX8: 9.0691 | AY8: 9.898 | AZ8: 8.5164 | BA8: 7.1645 | BB8: 7.2335 | BC8: 7.2138 | BD8: 6.296 | BE8: 7.9145 | BF8: 7.9342 | BG8: 8.7631 | BH8: 8.6743 | BI8: 8.1217 | BJ8: 8.102 | BK8: 10.2039 | BL8: 12.2861 | BM8: 14.2894 | BN8: 11.8914 | BO8: 13.8947 | BP8: 14.0526 | BQ8: 15.7204 | BR8: 13.1644 | BS8: 9.9967 | BT8: 8.6052 | BU8: 11.0921 | BV8: 13.5789 | BW8: 13.3223 | BX8: 17.6447 | BY8: 15.9967 | BZ8: 12.4934 | CA8: 13.4506 | CB8: 13.3421 | CC8: 16.8552 | CD8: 22.7664 | CE8: 22.6381 | CF8: 19.3421 | CG8: 18.3749 | CH8: 21.3614 | CI8: 19.328 | CJ8: 16.8404 | CK8: 16.0485 | CL8: 14.1622 | CM8: 15.4855 | CN8: 15.0366 | CO8: 13.9005 | CP8: 12.7544 | CQ8: 14.0981 | CR8: 16.2412 | CS8: 13.1175 | CT8: 9.9714 | CU8: 9.1305 | CV8: 9.7043 | CW8: 9.4936 | CX8: 10.4538 | CY8: 11.3448 | CZ8: 12.3628 | DA8: 11.1741 | DB8: 10.4113 | DC8: 8.2518 | DD8: 9.6672 | DE8: 9.4888 | DF8: 7.8004 | DG8: 7.4332 | DH8: 8.7233 | DI8: 8.2339 | DJ8: 6.9129 | DK8: 7.0917 | DL8: 8.0632 | DM8: 8.0831 | DN8: 6.1642 | DO8: 6.0748 | DP8: 7.9112 | DQ8: 9.1352 | DR8: 9.7172 | DS8: 8.0645 | DT8: 8.5025 | DU8: 7.5232 | DV8: 8.0911 | DW8: 10.2534 | DX8: 8.5658 | DY8: 7.8777
A9: AGI | B9: =A9&" CN Equity" -> AGI CN Equity | C9: Alamos Gold Inc | D9: -- | E9: -- | F9: 50.46 | G9: 42005 | H9: 45657 | I9: Materials | J9: 6.29 | K9: 7.0124 | L9: 6.8826 | M9: 7.7359 | N9: 7.5815 | O9: 6.6129 | P9: 3.9584 | Q9: 5.0481 | R9: 4.6011 | S9: 4.6958 | T9: 3.7902 | U9: 4.2477 | V9: 4.2663 | W9: 5.788 | X9: 6.4228 | Y9: 8.4622 | Z9: 7.8451 | AA9: 10.3884 | AB9: 11.417 | AC9: 8.6305 | AD9: 10.0985 | AE9: 9.8504 | AF9: 8.0058 | AG9: 8.7361 | AH9: 9.1387 | AI9: 8.9983 | AJ9: 10.0002 | AK9: 9.1595 | AL9: 8.522 | AM9: 8.6157 | AN9: 8.2782 | AO9: 9.7501 | AP9: 7.9032 | AQ9: 7.6795 | AR9: 7.6983 | AS9: 7.6889 | AT9: 6.9191 | AU9: 6.1211 | AV9: 6.2901 | AW9: 6.5273 | AX9: 6.7436 | AY9: 7.0446 | AZ9: 6.6402 | BA9: 5.3987 | BB9: 5.5774 | BC9: 4.957 | BD9: 4.0241 | BE9: 4.6272 | BF9: 5.5131 | BG9: 5.9937 | BH9: 6.4015 | BI9: 5.8728 | BJ9: 6.2315 | BK9: 7.4734 | BL9: 8.1924 | BM9: 8.8735 | BN9: 7.2957 | BO9: 6.7935 | BP9: 7.1346 | BQ9: 7.4319 | BR9: 7.9255 | BS9: 7.4129 | BT9: 6.7364 | BU9: 10.681 | BV9: 10.6239 | BW9: 12.0859 | BX9: 13.5275 | BY9: 13.031 | BZ9: 11.2147 | CA9: 11.6353 | CB9: 10.2777 | CC9: 10.656 | CD9: 9.8318 | CE9: 8.6436 | CF9: 9.4396 | CG9: 9.4684 | CH9: 10.5354 | CI9: 9.1293 | CJ9: 9.7752 | CK9: 9.6016 | CL9: 8.8105 | CM9: 8.8782 | CN9: 9.4489 | CO9: 9.4424 | CP9: 8.4138 | CQ9: 9.064 | CR9: 10.221 | CS9: 9.7148 | CT9: 9.1891 | CU9: 8.8207 | CV9: 9.8855 | CW9: 9.231 | CX9: 10.0365 | CY9: 10.5364 | CZ9: 12.7808 | DA9: 13.4515 | DB9: 14.4243 | DC9: 13.6677 | DD9: 16.2504 | DE9: 17.2452 | DF9: 16.5065 | DG9: 15.5727 | DH9: 16.076 | DI9: 17.1517 | DJ9: 15.1505 | DK9: 16.9801 | DL9: 19.8876 | DM9: 17.6533 | DN9: 16.1277 | DO9: 15.8602 | DP9: 19.8196 | DQ9: 20.0975 | DR9: 22.6183 | DS9: 21.3317 | DT9: 23.3893 | DU9: 25.8247 | DV9: 26.8244 | DW9: 27.9989 | DX9: 26.486 | DY9: 26.4302
A10: AIF | B10: =A10&" CN Equity" -> AIF CN Equity | C10: Altus Group Ltd/Canada | D10: -- | E10: -- | F10: 46.2 | G10: 42005 | H10: 45657 | I10: Real Estate | J10: 15.61 | K10: 18.2763 | L10: 16.3731 | M10: 16.8921 | N10: 15.988 | O10: 15.0233 | P10: 14.0273 | Q10: 17.7747 | R10: 17.4114 | S10: 16.1956 | T10: 17.1648 | U10: 16.6173 | V10: 15.2889 | W10: 17.1829 | X10: 17.9326 | Y10: 19.0895 | Z10: 19.8147 | AA10: 19.3658 | AB10: 20.5224 | AC10: 24.2964 | AD10: 25.5673 | AE10: 25.2876 | AF10: 26.8698 | AG10: 27.1969 | AH10: 26.2218 | AI10: 26.6171 | AJ10: 25.695 | AK10: 27.1961 | AL10: 26.6751 | AM10: 24.8831 | AN10: 22.6904 | AO10: 27.6972 | AP10: 28.3376 | AQ10: 31.4238 | AR10: 32.1106 | AS10: 33.074 | AT10: 30.7007 | AU10: 28.1214 | AV10: 29.3512 | AW10: 29.0633 | AX10: 26.3189 | AY10: 26.5079 | AZ10: 25.3231 | BA10: 27.9911 | BB10: 27.8204 | BC10: 26.1845 | BD10: 23.9396 | BE10: 21.6561 | BF10: 22.5619 | BG10: 24.0898 | BH10: 23.9903 | BI10: 24.9014 | BJ10: 27.2111 | BK10: 29.6541 | BL10: 30.9856 | BM10: 36.0621 | BN10: 37.0832 | BO10: 33.8808 | BP10: 34.215 | BQ10: 35.3734 | BR10: 40.3961 | BS10: 41.8219 | BT10: 34.1518 | BU10: 39.326 | BV10: 40.3179 | BW10: 38.3056 | BX10: 40.0617 | BY10: 50.3448 | BZ10: 52.1077 | CA10: 51.3354 | CB10: 46.3535 | CC10: 46.4183 | CD10: 46.2388 | CE10: 52.7283 | CF10: 57.2328 | CG10: 58.8142 | CH10: 55.9071 | CI10: 54.5392 | CJ10: 55.7448 | CK10: 62.9882 | CL10: 58.8126 | CM10: 61.7722 | CN10: 62.2576 | CO10: 67.6833 | CP10: 58.1846 | CQ10: 46.8452 | CR10: 48.3054 | CS10: 46.0192 | CT10: 45.1392 | CU10: 42.7942 | CV10: 50.4528 | CW10: 49.234 | CX10: 43.118 | CY10: 46.6133 | CZ10: 51.2544 | DA10: 52.1801 | DB10: 54.9803 | DC10: 58.9006 | DD10: 55.5626 | DE10: 52.087 | DF10: 42.7636 | DG10: 42.6762 | DH10: 42.7733 | DI10: 50.5547 | DJ10: 45.8216 | DK10: 45.8995 | DL10: 38.9805 | DM10: 41.21 | DN10: 44.3198 | DO10: 48.9846 | DP10: 50.8802 | DQ10: 49.5464 | DR10: 46.0746 | DS10: 49.696 | DT10: 56.8179 | DU10: 53.4439 | DV10: 54.1419 | DW10: 51.962 | DX10: 58.7088 | DY10: 55.387
A11: ALA | B11: =A11&" CN Equity" -> ALA CN Equity | C11: AltaGas Ltd | D11: -- | E11: -- | F11: 41.07 | G11: 42005 | H11: 45657 | I11: Utilities | J11: 24.09 | K11: 25.3244 | L11: 23.8703 | M11: 23.2406 | N11: 22.5708 | O11: 21.738 | P11: 20.5484 | Q11: 20.8638 | R11: 19.0555 | S11: 19.6599 | T11: 18.3218 | U11: 18.1841 | V11: 19.4007 | W11: 19.1344 | X11: 19.9642 | Y11: 18.3263 | Z11: 18.3136 | AA11: 19.0735 | AB11: 20.2983 | AC11: 20.8301 | AD11: 20.8157 | AE11: 20.5794 | AF11: 20.3461 | AG11: 21.2408 | AH11: 19.4976 | AI11: 19.6393 | AJ11: 19.6241 | AK11: 19.6003 | AL11: 19.4023 | AM11: 19.2468 | AN11: 18.9242 | AO11: 18.1716 | AP11: 18.9767 | AQ11: 19.5356 | AR11: 19.6031 | AS11: 19.2511 | AT11: 18.6613 | AU11: 18.0067 | AV11: 16.371 | AW11: 17.1175 | AX11: 17.7271 | AY11: 19.0427 | AZ11: 18.6199 | BA11: 17.2474 | BB11: 14.7362 | BC11: 11.9683 | BD11: 10.5704 | BE11: 10.2322 | BF11: 9.9581 | BG11: 13.1566 | BH11: 13.148 | BI11: 13.3721 | BJ11: 14.7102 | BK11: 14.997 | BL11: 15.3597 | BM11: 13.8001 | BN11: 14.9062 | BO11: 14.7448 | BP11: 15.2211 | BQ11: 15.3443 | BR11: 16.5967 | BS11: 15.6869 | BT11: 10.0518 | BU11: 13.1906 | BV11: 11.7771 | BW11: 12.5317 | BX11: 13.5002 | BY11: 13.6341 | BZ11: 13.0593 | CA11: 13.7802 | CB11: 15.2746 | CC11: 15.4079 | CD11: 15.6957 | CE11: 16.0106 | CF11: 17.4504 | CG11: 19.2165 | CH11: 20.0638 | CI11: 21.9128 | CJ11: 22.3113 | CK11: 21.4179 | CL11: 21.2506 | CM11: 21.8546 | CN11: 20.7965 | CO11: 23.4455 | CP11: 22.4153 | CQ11: 23.9692 | CR11: 24.264 | CS11: 25.4599 | CT11: 26.4651 | CU11: 23.7635 | CV11: 24.9622 | CW11: 24.7785 | CX11: 23.3516 | CY11: 21.6918 | CZ11: 19.9261 | DA11: 20.8678 | DB11: 22.2066 | DC11: 20.9035 | DD11: 20.3609 | DE11: 21.4183 | DF11: 20.8037 | DG11: 21.7569 | DH11: 23.7955 | DI11: 24.152 | DJ11: 24.0663 | DK11: 23.7984 | DL11: 25.4983 | DM11: 25.9638 | DN11: 26.0851 | DO11: 27.149 | DP11: 28.2106 | DQ11: 28.4557 | DR11: 28.9932 | DS11: 29.429 | DT11: 31.3427 | DU11: 32.8661 | DV11: 32.1456 | DW11: 31.944 | DX11: 32.8753 | DY11: 32.4396
A12: AP-U | B12: =A12&" CN Equity" -> AP-U CN Equity | C12: Allied Properties Real Estate | D12: -- | E12: -- | F12: 14.05 | G12: 42005 | H12: 45657 | I12: Real Estate | J12: 21.61 | K12: 22.0001 | L12: 21.8995 | M12: 21.8126 | N12: 19.8491 | O12: 19.4554 | P12: 20.0618 | Q12: 19.2694 | R12: 19.3767 | S12: 19.9706 | T12: 18.2968 | U12: 17.7064 | V12: 18.7516 | W12: 17.8428 | X12: 19.8424 | Y12: 20.1313 | Z12: 20.7367 | AA12: 22.1754 | AB12: 22.7862 | AC12: 21.2516 | AD12: 21.8143 | AE12: 20.948 | AF12: 19.762 | AG12: 21.0392 | AH12: 19.9144 | AI12: 20.6461 | AJ12: 21.3516 | AK12: 21.7455 | AL12: 22.7843 | AM12: 23.2583 | AN12: 22.8742 | AO12: 23.2871 | AP12: 24.0444 | AQ12: 25.0263 | AR12: 25.1882 | AS12: 25.6324 | AT12: 25.2667 | AU12: 25.413 | AV12: 24.9437 | AW12: 25.5909 | AX12: 26.3059 | AY12: 25.9784 | AZ12: 26.4321 | BA12: 27.2235 | BB12: 26.9982 | BC12: 26.5802 | BD12: 28.4216 | BE12: 28.0139 | BF12: 29.9194 | BG12: 30.5176 | BH12: 31.4223 | BI12: 30.3151 | BJ12: 31.1547 | BK12: 30.4459 | BL12: 31.5339 | BM12: 33.921 | BN12: 34.6979 | BO12: 34.7915 | BP12: 34.7613 | BQ12: 33.9816 | BR12: 36.1271 | BS12: 35.7213 | BT12: 29.4307 | BU12: 29.4033 | BV12: 26.4852 | BW12: 27.2119 | BX12: 26.7348 | BY12: 24.6173 | BZ12: 24.074 | CA12: 21.7906 | CB12: 27.622 | CC12: 25.6903 | CD12: 24.7395 | CE12: 26.2469 | CF12: 27.9026 | CG12: 29.3803 | CH12: 30.6495 | CI12: 31.2309 | CJ12: 31.787 | CK12: 30.2023 | CL12: 28.1571 | CM12: 30.0398 | CN12: 29.0677 | CO12: 31.0705 | CP12: 31.727 | CQ12: 31.3707 | CR12: 33.2889 | CS12: 29.892 | CT12: 27.8837 | CU12: 23.9688 | CV12: 24.7863 | CW12: 22.8659 | CX12: 20.0458 | CY12: 19.4366 | CZ12: 19.448 | DA12: 19.0704 | DB12: 22.2218 | DC12: 21.5413 | DD12: 18.449 | DE12: 17.3614 | DF12: 17.0476 | DG12: 16.7807 | DH12: 17.0689 | DI12: 16.2742 | DJ12: 14.1673 | DK12: 12.6435 | DL12: 14.3751 | DM12: 16.3546 | DN12: 15.9353 | DO12: 13.9888 | DP12: 14.675 | DQ12: 14.1849 | DR12: 14.2792 | DS12: 13.0703 | DT12: 14.2504 | DU12: 15.1126 | DV12: 17.6954 | DW12: 16.2012 | DX12: 16.158 | DY12: 15.3866
A13: AQN | B13: =A13&" CN Equity" -> AQN CN Equity | C13: Algonquin Power & Utilities Co | D13: -- | E13: -- | F13: 8.94 | G13: 42005 | H13: 45657 | I13: Utilities | J13: 5.78 | K13: 5.8404 | L13: 5.4061 | M13: 5.6776 | N13: 5.6371 | O13: 5.473 | P13: 5.6017 | Q13: 5.7186 | R13: 5.5949 | S13: 5.9802 | T13: 6.1284 | U13: 6.5436 | V13: 6.8975 | W13: 6.2437 | X13: 6.5967 | Y13: 6.6514 | Z13: 7.0883 | AA13: 7.3003 | AB13: 7.4967 | AC13: 7.2696 | AD13: 7.2996 | AE13: 7.3617 | AF13: 6.9144 | AG13: 7.166 | AH13: 7.1283 | AI13: 7.5938 | AJ13: 8.0878 | AK13: 8.2343 | AL13: 8.8966 | AM13: 8.7884 | AN13: 8.5824 | AO13: 8.724 | AP13: 8.5859 | AQ13: 8.9895 | AR13: 9.2369 | AS13: 9.2486 | AT13: 8.7882 | AU13: 8.3475 | AV13: 8.4996 | AW13: 8.3199 | AX13: 8.4064 | AY13: 8.5668 | AZ13: 8.6207 | BA13: 9.1199 | BB13: 9.1243 | BC13: 8.974 | BD13: 9.6297 | BE13: 9.4981 | BF13: 10.0377 | BG13: 10.1 | BH13: 10.516 | BI13: 10.6979 | BJ13: 11.0337 | BK13: 11.2322 | BL13: 11.6357 | BM13: 12.3151 | BN13: 12.9714 | BO13: 12.9356 | BP13: 13.3218 | BQ13: 13.2668 | BR13: 14.6318 | BS13: 14.7329 | BT13: 13.8413 | BU13: 14.097 | BV13: 14.0824 | BW13: 12.9778 | BX13: 13.6655 | BY13: 13.3698 | BZ13: 14.4576 | CA13: 15.1005 | CB13: 15.2127 | CC13: 15.8088 | CD13: 16.0805 | CE13: 14.8731 | CF13: 15.1718 | CG13: 15.1109 | CH13: 14.1126 | CI13: 14.2323 | CJ13: 15.3573 | CK13: 15.0953 | CL13: 14.4719 | CM13: 13.903 | CN13: 13.4744 | CO13: 14.4083 | CP13: 14.3136 | CQ13: 14.4635 | CR13: 15.4614 | CS13: 14.8314 | CT13: 14.6719 | CU13: 13.9776 | CV13: 14.4705 | CW13: 14.5755 | CX13: 12.3837 | CY13: 12.3755 | CZ13: 8.3379 | DA13: 7.4844 | DB13: 8.1848 | DC13: 8.7923 | DD13: 9.6963 | DE13: 9.8502 | DF13: 9.7818 | DG13: 9.4875 | DH13: 9.4269 | DI13: 8.8637 | DJ13: 7.0824 | DK13: 6.1487 | DL13: 7.3731 | DM13: 7.4902 | DN13: 7.1408 | DO13: 7.087 | DP13: 7.81 | DQ13: 7.6732 | DR13: 7.8192 | DS13: 7.4711 | DT13: 8.01 | DU13: 6.7927 | DV13: 6.95 | DW13: 6.3293 | DX13: 6.5362 | DY13: 6.0888
